Workbook

Sheet JANUARI
A2: LAPORAN LABORATORIUM
A3: DI PUSKESMAS KABUPATEN ROTE NDAO
A4: JANUARI 2026
A6: No. | B6: ELEMEN DATA | D6: BAA | G6: BATUTUA | J6: BUSALANGGA | M6: DELHA | P6: EAHUN | S6: FEAPOPI
D7: L | E7: P | F7: TOTAL | G7: L | H7: P | I7: TOTAL | J7: L | K7: P | L7: TOTAL | M7: L | N7: P | O7: TOTAL | P7: L | Q7: P | R7: TOTAL | S7: L | T7: P | U7: TOTAL
A8: 1 | B8: Total Kunjungan Laboratorium | D8: =D9+D18 -> 163 | E8: =E9+E18 -> 778 | F8: =F9+F18 -> 941 | G8: =G9+G18 -> 276 | H8: =H9+H18 -> 622 | I8: =I9+I18 -> 898 | J8: =J9+J18 -> 174 | K8: =K9+K18 -> 630 | ... U8: =U9+U18 -> 237
A9: 2 | B9: Peminta Tes Laboratorium | D9: =SUM(D10:D17) -> 55 | E9: =SUM(E10:E17) -> 198 | F9: =SUM(F10:F17) -> 253 | G9: =SUM(G10:G17) -> 116 | H9: =SUM(H10:H17) -> 208 | I9: =SUM(I10:I17) -> 324 | J9: =SUM(J10:J17) -> 87 | K9: =SUM(K10:K17) -> 315 | ... U9: =SUM(U10:U17) -> 72
B10: a. | C10: Poli umum | D10: 51 | E10: 135 | F10: =SUM(D10:E10) -> 186 | G10: 98 | H10: 149 | I10: =SUM(G10:H10) -> 247 | J10: 87 | K10: 170 | L10: =SUM(J10:K10) -> 257 | M10: 33 | N10: 49 | O10: =SUM(M10:N10) -> 82 | P10: 45 | Q10: 67 | R10: =SUM(P10:Q10) -> 112 | S10: 27 | T10: 25 | U10: =SUM(S10:T10) -> 52
B11: b. | C11: KIA / KB | D11: 2 | E11: 62 | F11: =SUM(D11:E11) -> 64 | G11: 0 | H11: 41 | I11: =SUM(G11:H11) -> 41 | J11: 0 | K11: 144 | L11: =SUM(J11:K11) -> 144 | M11: 0 | N11: 39 | O11: =SUM(M11:N11) -> 39 | P11: 0 | Q11: 60 | R11: =SUM(P11:Q11) -> 60 | S11: 0 | T11: 20 | U11: =SUM(S11:T11) -> 20
B12: c. | C12: Rawat inap | D12: 0 | E12: 0 | F12: =SUM(D12:E12) -> 0 | G12: 0 | H12: 0 | I12: =SUM(G12:H12) -> 0 | L12: =SUM(J12:K12) -> 0 | M12: 1 | N12: 0 | O12: =SUM(M12:N12) -> 1 | P12: 0 | Q12: 6 | R12: =SUM(P12:Q12) -> 6 | S12: 0 | T12: 0 | U12: =SUM(S12:T12) -> 0
B13: d. | C13: Unit gawat darurat | D13: 0 | E13: 0 | F13: =SUM(D13:E13) -> 0 | G13: 0 | H13: 4 | I13: =SUM(G13:H13) -> 4 | L13: =SUM(J13:K13) -> 0 | M13: 3 | N13: 4 | O13: =SUM(M13:N13) -> 7 | P13: 1 | Q13: 4 | R13: =SUM(P13:Q13) -> 5 | S13: 0 | T13: 0 | U13: =SUM(S13:T13) -> 0
B14: e. | C14: MTBS | D14: 0 | E14: 0 | F14: =SUM(D14:E14) -> 0 | G14: 4 | H14: 4 | I14: =SUM(G14:H14) -> 8 | L14: =SUM(J14:K14) -> 0 | M14: 1 | N14: 2 | O14: =SUM(M14:N14) -> 3 | P14: 0 | Q14: 0 | R14: =SUM(P14:Q14) -> 0 | S14: 0 | T14: 0 | U14: =SUM(S14:T14) -> 0
B15: f. | C15: Poli Gigi | D15: 2 | E15: 1 | F15: =SUM(D15:E15) -> 3 | G15: 14 | H15: 8 | I15: =SUM(G15:H15) -> 22 | L15: =SUM(J15:K15) -> 0 | M15: 0 | N15: 0 | O15: =SUM(M15:N15) -> 0 | P15: 4 | Q15: 3 | R15: =SUM(P15:Q15) -> 7 | S15: 0 | T15: 0 | U15: =SUM(S15:T15) -> 0
B16: g. | C16: PONED | D16: 0 | E16: 0 | F16: =SUM(D16:E16) -> 0 | G16: 0 | H16: 2 | I16: =SUM(G16:H16) -> 2 | J16: 0 | K16: 1 | L16: =SUM(J16:K16) -> 1 | M16: 0 | N16: 3 | O16: =SUM(M16:N16) -> 3 | P16: 0 | Q16: 8 | R16: =SUM(P16:Q16) -> 8 | S16: 0 | T16: 0 | U16: =SUM(S16:T16) -> 0
B17: h. | C17: Pustu | D17: 0 | E17: 0 | F17: =SUM(D17:E17) -> 0 | G17: 0 | H17: 0 | I17: =SUM(G17:H17) -> 0 | L17: =SUM(J17:K17) -> 0 | M17: 0 | N17: 0 | O17: =SUM(M17:N17) -> 0 | P17: 0 | Q17: 0 | R17: =SUM(P17:Q17) -> 0 | S17: 0 | T17: 0 | U17: =SUM(S17:T17) -> 0
A18: 3 | B18: Jumlah Pemeriksaan Laboratorium | D18: =SUM(D19:D41) -> 108 | E18: =SUM(E19:E41) -> 580 | F18: =SUM(F19:F41) -> 688 | G18: =SUM(G19:G41) -> 160 | H18: =SUM(H19:H41) -> 414 | I18: =SUM(I19:I41) -> 574 | J18: =SUM(J19:J41) -> 87 | K18: =SUM(K19:K41) -> 315 | ... U18: =SUM(U19:U41) -> 165
B19: a. | C19: Golongan darah | D19: 3 | E19: 21 | F19: =SUM(D19:E19) -> 24 | G19: 0 | H19: 11 | I19: =SUM(G19:H19) -> 11 | J19: 2 | K19: 18 | L19: =SUM(J19:K19) -> 20 | M19: 0 | N19: 6 | O19: =SUM(M19:N19) -> 6 | P19: 0 | Q19: 33 | R19: =SUM(P19:Q19) -> 33 | S19: 0 | T19: 9 | U19: =SUM(S19:T19) -> 9
B20: b. | C20: Hb | E20: 59 | F20: =SUM(D20:E20) -> 59 | G20: 0 | H20: 34 | I20: =SUM(G20:H20) -> 34 | J20: 3 | K20: 45 | L20: =SUM(J20:K20) -> 48 | M20: 9 | N20: 55 | O20: =SUM(M20:N20) -> 64 | P20: 17 | Q20: 72 | R20: =SUM(P20:Q20) -> 89 | S20: 2 | T20: 11 | U20: =SUM(S20:T20) -> 13
B21: c. | C21: Leukosit | E21: 8 | F21: =SUM(D21:E21) -> 8 | G21: 0 | H21: 0 | I21: =SUM(G21:H21) -> 0 | L21: =SUM(J21:K21) -> 0 | M21: 0 | N21: 0 | O21: =SUM(M21:N21) -> 0 | P21: 7 | Q21: 9 | R21: =SUM(P21:Q21) -> 16 | S21: 0 | T21: 0 | U21: =SUM(S21:T21) -> 0
B22: d. | C22: Eritrosit | E22: 8 | F22: =SUM(D22:E22) -> 8 | G22: 0 | H22: 0 | I22: =SUM(G22:H22) -> 0 | L22: =SUM(J22:K22) -> 0 | M22: 0 | N22: 0 | O22: =SUM(M22:N22) -> 0 | P22: 7 | Q22: 9 | R22: =SUM(P22:Q22) -> 16 | S22: 0 | T22: 0 | U22: =SUM(S22:T22) -> 0
B23: e. | C23: Trombosit | F23: =SUM(D23:E23) -> 0 | G23: 0 | H23: 0 | I23: =SUM(G23:H23) -> 0 | L23: =SUM(J23:K23) -> 0 | M23: 0 | N23: 0 | O23: =SUM(M23:N23) -> 0 | P23: 7 | Q23: 9 | R23: =SUM(P23:Q23) -> 16 | S23: 0 | T23: 0 | U23: =SUM(S23:T23) -> 0
B24: f. | C24: Glukosa Post pandiel ( 2 jam PP ) | F24: =SUM(D24:E24) -> 0 | G24: 0 | H24: 0 | I24: =SUM(G24:H24) -> 0 | L24: =SUM(J24:K24) -> 0 | M24: 0 | N24: 0 | O24: =SUM(M24:N24) -> 0 | P24: 0 | Q24: 0 | R24: =SUM(P24:Q24) -> 0 | S24: 0 | T24: 0 | U24: =SUM(S24:T24) -> 0
B25: g. | C25: Gulukosa Urine | E25: 10 | F25: =SUM(D25:E25) -> 10 | G25: 0 | H25: 23 | I25: =SUM(G25:H25) -> 23 | L25: =SUM(J25:K25) -> 0 | M25: 0 | N25: 0 | O25: =SUM(M25:N25) -> 0 | P25: 0 | Q25: 0 | R25: =SUM(P25:Q25) -> 0 | S25: 0 | T25: 0 | U25: =SUM(S25:T25) -> 0
B26: h. | C26: Asam Urat | D26: 25 | E26: 72 | F26: =SUM(D26:E26) -> 97 | G26: 26 | H26: 30 | I26: =SUM(G26:H26) -> 56 | J26: 27 | K26: 57 | L26: =SUM(J26:K26) -> 84 | M26: 20 | N26: 28 | O26: =SUM(M26:N26) -> 48 | P26: 28 | Q26: 47 | R26: =SUM(P26:Q26) -> 75 | S26: 7 | T26: 9 | U26: =SUM(S26:T26) -> 16
B27: i. | C27: Gula darah sewaktu | D27: 27 | E27: 51 | F27: =SUM(D27:E27) -> 78 | G27: 69 | H27: 112 | I27: =SUM(G27:H27) -> 181 | J27: 8 | K27: 20 | L27: =SUM(J27:K27) -> 28 | M27: 30 | N27: 72 | O27: =SUM(M27:N27) -> 102 | P27: 25 | Q27: 92 | R27: =SUM(P27:Q27) -> 117 | S27: 15 | T27: =29-15 -> 14 | U27: =SUM(S27:T27) -> 29
B28: j. | C28: Gula darah puasa | D28: 21 | E28: 73 | F28: =SUM(D28:E28) -> 94 | G28: 44 | H28: 64 | I28: =SUM(G28:H28) -> 108 | J28: 19 | K28: 26 | L28: =SUM(J28:K28) -> 45 | M28: 2 | N28: 2 | O28: =SUM(M28:N28) -> 4 | P28: 10 | Q28: 24 | R28: =SUM(P28:Q28) -> 34 | S28: 7 | T28: 3 | U28: =SUM(S28:T28) -> 10
B29: k. | C29: Urin Acid | F29: =SUM(D29:E29) -> 0 | G29: 0 | H29: 0 | I29: =SUM(G29:H29) -> 0 | L29: =SUM(J29:K29) -> 0 | M29: 0 | N29: 0 | O29: =SUM(M29:N29) -> 0 | P29: 0 | Q29: 0 | R29: =SUM(P29:Q29) -> 0 | S29: 0 | T29: 0 | U29: =SUM(S29:T29) -> 0
B30: l. | C30: Cholestrol | D30: 25 | E30: 83 | F30: =SUM(D30:E30) -> 108 | G30: 21 | H30: 24 | I30: =SUM(G30:H30) -> 45 | J30: 24 | K30: 47 | L30: =SUM(J30:K30) -> 71 | M30: 22 | N30: 44 | O30: =SUM(M30:N30) -> 66 | P30: 27 | Q30: 43 | R30: =SUM(P30:Q30) -> 70 | S30: 10 | T30: 17 | U30: =SUM(S30:T30) -> 27
B31: m. | C31: Protein Urine | E31: 13 | F31: =SUM(D31:E31) -> 13 | G31: 0 | H31: 23 | I31: =SUM(G31:H31) -> 23 | L31: =SUM(J31:K31) -> 0 | M31: 0 | N31: 0 | O31: =SUM(M31:N31) -> 0 | P31: 0 | Q31: 47 | R31: =SUM(P31:Q31) -> 47 | S31: 0 | T31: 4 | U31: =SUM(S31:T31) -> 4
B32: n. | C32: HIV | D32: 1 | E32: 41 | F32: =SUM(D32:E32) -> 42 | G32: 0 | H32: 26 | I32: =SUM(G32:H32) -> 26 | J32: 1 | K32: 29 | L32: =SUM(J32:K32) -> 30 | M32: 0 | N32: 17 | O32: =SUM(M32:N32) -> 17 | P32: 2 | Q32: 38 | R32: =SUM(P32:Q32) -> 40 | S32: 0 | T32: 12 | U32: =SUM(S32:T32) -> 12
B33: o. | C33: SYPHILIS | E33: 41 | F33: =SUM(D33:E33) -> 41 | G33: 0 | H33: 26 | I33: =SUM(G33:H33) -> 26 | J33: 1 | K33: 12 | L33: =SUM(J33:K33) -> 13 | M33: 3 | N33: 17 | O33: =SUM(M33:N33) -> 20 | P33: 2 | Q33: 38 | R33: =SUM(P33:Q33) -> 40 | S33: 0 | T33: 12 | U33: =SUM(S33:T33) -> 12
B34: p. | C34: HBSAg | D34: 5 | E34: 43 | F34: =SUM(D34:E34) -> 48 | G34: 0 | H34: 27 | I34: =SUM(G34:H34) -> 27 | J34: 2 | K34: 31 | L34: =SUM(J34:K34) -> 33 | M34: 1 | N34: 17 | O34: =SUM(M34:N34) -> 18 | P34: 1 | Q34: 34 | R34: =SUM(P34:Q34) -> 35 | S34: 0 | T34: 12 | U34: =SUM(S34:T34) -> 12
B35: q. | C35: Malaria P.V (Jika positip isi jenis plasmodiumnya) | D35: 1 | E35: 39 | F35: =SUM(D35:E35) -> 40 | G35: 0 | H35: 0 | I35: =SUM(G35:H35) -> 0 | L35: =SUM(J35:K35) -> 0 | M35: 1 | N35: 15 | O35: =SUM(M35:N35) -> 16 | P35: 10 | Q35: 36 | R35: =SUM(P35:Q35) -> 46 | S35: 0 | T35: 9 | U35: =SUM(S35:T35) -> 9
B36: r. | C36: Widal | F36: =SUM(D36:E36) -> 0 | G36: 0 | H36: 0 | I36: =SUM(G36:H36) -> 0 | L36: =SUM(J36:K36) -> 0 | M36: 0 | N36: 0 | O36: =SUM(M36:N36) -> 0 | P36: 0 | Q36: 0 | R36: =SUM(P36:Q36) -> 0 | S36: 0 | T36: 0 | U36: =SUM(S36:T36) -> 0
B37: s. | C37: Sputum BTA | F37: =SUM(D37:E37) -> 0 | I37: =SUM(G37:H37) -> 0 | L37: =SUM(J37:K37) -> 0 | M37: 1 | N37: 5 | O37: =SUM(M37:N37) -> 6 | P37: 0 | Q37: 0 | R37: =SUM(P37:Q37) -> 0 | S37: 0 | T37: 0 | U37: =SUM(S37:T37) -> 0
B38: t. | C38: Test Kehamilan | E38: 18 | F38: =SUM(D38:E38) -> 18 | G38: 0 | H38: 14 | I38: =SUM(G38:H38) -> 14 | J38: 0 | K38: 29 | L38: =SUM(J38:K38) -> 29 | M38: 0 | N38: 15 | O38: =SUM(M38:N38) -> 15 | P38: 0 | Q38: 26 | R38: =SUM(P38:Q38) -> 26 | S38: 0 | T38: 12 | U38: =SUM(S38:T38) -> 12
B39: u. | C39: Tinja | F39: =SUM(D39:E39) -> 0 | G39: 0 | H39: 0 | I39: =SUM(G39:H39) -> 0 | L39: =SUM(J39:K39) -> 0 | M39: 0 | N39: 0 | O39: =SUM(M39:N39) -> 0 | P39: 0 | Q39: 0 | R39: =SUM(P39:Q39) -> 0 | S39: 0 | T39: 0 | U39: =SUM(S39:T39) -> 0
B40: v. | C40: Urine Lengkap | F40: =SUM(D40:E40) -> 0 | G40: 0 | H40: 0 | I40: =SUM(G40:H40) -> 0 | J40: 0 | K40: 1 | L40: =SUM(J40:K40) -> 1 | M40: 1 | N40: 13 | O40: =SUM(M40:N40) -> 14 | P40: 0 | Q40: 0 | R40: =SUM(P40:Q40) -> 0 | S40: 0 | T40: 0 | U40: =SUM(S40:T40) -> 0
B41: w. | C41: Urine Sedimen | F41: =SUM(D41:E41) -> 0 | G41: 0 | H41: 0 | I41: =SUM(G41:H41) -> 0 | L41: =SUM(J41:K41) -> 0 | M41: 0 | N41: 0 | O41: =SUM(M41:N41) -> 0 | P41: 0 | Q41: 0 | R41: =SUM(P41:Q41) -> 0 | S41: 0 | T41: 0 | U41: =SUM(S41:T41) -> 0
A44: No. | B44: ELEMEN DATA | D44: KORBAFO | G44: NDAO | J44: OELABA | M44: OELE | P44: SONIMANU | S44: SOTIMORI
...

Sheet FEBRUARI
A2: LAPORAN LABORATORIUM
A3: DI PUSKESMAS KABUPATEN ROTE NDAO
A4: FEBRUARI 2026
A6: No. | B6: ELEMEN DATA | D6: BAA | G6: BATUTUA | J6: BUSALANGGA | M6: DELHA | P6: EAHUN | S6: FEAPOPI
D7: L | E7: P | F7: TOTAL | G7: L | H7: P | I7: TOTAL | J7: L | K7: P | L7: TOTAL | M7: L | N7: P | O7: TOTAL | P7: L | Q7: P | R7: TOTAL | S7: L | T7: P | U7: TOTAL
A8: 1 | B8: Total Kunjungan Laboratorium | D8: =D9+D18 -> 249 | E8: =E9+E18 -> 991 | F8: =F9+F18 -> 1240 | G8: =G9+G18 -> 208 | H8: =H9+H18 -> 591 | I8: =I9+I18 -> 799 | J8: =J9+J18 -> 108 | K8: =K9+K18 -> 492 | ... U8: =U9+U18 -> 285
A9: 2 | B9: Peminta Tes Laboratorium | D9: =SUM(D10:D17) -> 39 | E9: =SUM(E10:E17) -> 202 | F9: =SUM(F10:F17) -> 241 | G9: =SUM(G10:G17) -> 93 | H9: =SUM(H10:H17) -> 169 | I9: =SUM(I10:I17) -> 262 | J9: =SUM(J10:J17) -> 54 | K9: =SUM(K10:K17) -> 246 | ... U9: =SUM(U10:U17) -> 143
B10: a. | C10: Poli umum | D10: 36 | E10: 101 | F10: =SUM(D10:E10) -> 137 | G10: 82 | H10: 103 | I10: =SUM(G10:H10) -> 185 | J10: 54 | K10: 121 | L10: =SUM(J10:K10) -> 175 | M10: 17 | N10: 48 | O10: =SUM(M10:N10) -> 65 | P10: 18 | Q10: 37 | R10: =SUM(P10:Q10) -> 55 | S10: 48 | T10: 30 | U10: =SUM(S10:T10) -> 78
B11: b. | C11: KIA / KB | D11: 3 | E11: 101 | F11: =SUM(D11:E11) -> 104 | G11: 0 | H11: 48 | I11: =SUM(G11:H11) -> 48 | K11: 125 | L11: =SUM(J11:K11) -> 125 | M11: 0 | N11: 35 | O11: =SUM(M11:N11) -> 35 | Q11: 43 | R11: =SUM(P11:Q11) -> 43 | S11: 0 | T11: 64 | U11: =SUM(S11:T11) -> 64
B12: c. | C12: Rawat inap | D12: 0 | E12: 0 | F12: =SUM(D12:E12) -> 0 | G12: 0 | H12: 0 | I12: =SUM(G12:H12) -> 0 | L12: =SUM(J12:K12) -> 0 | M12: 0 | N12: 0 | O12: =SUM(M12:N12) -> 0 | P12: 4 | Q12: 7 | R12: =SUM(P12:Q12) -> 11 | S12: 0 | T12: 0 | U12: =SUM(S12:T12) -> 0
B13: d. | C13: Unit gawat darurat | D13: 0 | E13: 0 | F13: =SUM(D13:E13) -> 0 | G13: 4 | H13: 4 | I13: =SUM(G13:H13) -> 8 | L13: =SUM(J13:K13) -> 0 | M13: 3 | N13: 3 | O13: =SUM(M13:N13) -> 6 | P13: 0 | Q13: 0 | R13: =SUM(P13:Q13) -> 0 | S13: 0 | T13: 0 | U13: =SUM(S13:T13) -> 0
B14: e. | C14: MTBS | D14: 0 | E14: 0 | F14: =SUM(D14:E14) -> 0 | G14: 1 | H14: 2 | I14: =SUM(G14:H14) -> 3 | L14: =SUM(J14:K14) -> 0 | M14: 0 | N14: 2 | O14: =SUM(M14:N14) -> 2 | P14: 0 | Q14: 0 | R14: =SUM(P14:Q14) -> 0 | S14: 0 | T14: 1 | U14: =SUM(S14:T14) -> 1
B15: f. | C15: Poli Gigi | D15: 0 | E15: 0 | F15: =SUM(D15:E15) -> 0 | G15: 6 | H15: 7 | I15: =SUM(G15:H15) -> 13 | L15: =SUM(J15:K15) -> 0 | M15: 0 | N15: 0 | O15: =SUM(M15:N15) -> 0 | P15: 0 | Q15: 1 | R15: =SUM(P15:Q15) -> 1 | S15: 0 | T15: 0 | U15: =SUM(S15:T15) -> 0
B16: g. | C16: PONED | D16: 0 | E16: 0 | F16: =SUM(D16:E16) -> 0 | G16: 0 | H16: 5 | I16: =SUM(G16:H16) -> 5 | L16: =SUM(J16:K16) -> 0 | M16: 0 | N16: 19 | O16: =SUM(M16:N16) -> 19 | P16: 0 | Q16: 7 | R16: =SUM(P16:Q16) -> 7 | S16: 0 | T16: 0 | U16: =SUM(S16:T16) -> 0
B17: h. | C17: Pustu | D17: 0 | E17: 0 | F17: =SUM(D17:E17) -> 0 | G17: 0 | H17: 0 | I17: =SUM(G17:H17) -> 0 | L17: =SUM(J17:K17) -> 0 | M17: 0 | N17: 0 | O17: =SUM(M17:N17) -> 0 | P17: 0 | Q17: 0 | R17: =SUM(P17:Q17) -> 0 | S17: 0 | T17: 0 | U17: =SUM(S17:T17) -> 0
A18: 3 | B18: Jumlah Pemeriksaan Laboratorium | D18: =SUM(D19:D41) -> 210 | E18: =SUM(E19:E41) -> 789 | F18: =SUM(F19:F41) -> 999 | G18: =SUM(G19:G41) -> 115 | H18: =SUM(H19:H41) -> 422 | I18: =SUM(I19:I41) -> 537 | J18: =SUM(J19:J41) -> 54 | K18: =SUM(K19:K41) -> 246 | ... U18: =SUM(U19:U41) -> 142
B19: a. | C19: Golongan darah | D19: 2 | E19: 21 | F19: =SUM(D19:E19) -> 23 | G19: 0 | H19: 20 | I19: =SUM(G19:H19) -> 20 | J19: 0 | K19: 12 | L19: =SUM(J19:K19) -> 12 | M19: 1 | N19: 4 | O19: =SUM(M19:N19) -> 5 | P19: 0 | Q19: 22 | R19: =SUM(P19:Q19) -> 22 | S19: 0 | T19: 9 | U19: =SUM(S19:T19) -> 9
B20: b. | C20: Hb | D20: 4 | E20: 82 | F20: =SUM(D20:E20) -> 86 | G20: 0 | H20: 53 | I20: =SUM(G20:H20) -> 53 | J20: 3 | K20: 30 | L20: =SUM(J20:K20) -> 33 | M20: 10 | N20: 70 | O20: =SUM(M20:N20) -> 80 | P20: 8 | Q20: 66 | R20: =SUM(P20:Q20) -> 74 | S20: 3 | T20: 15 | U20: =SUM(S20:T20) -> 18
B21: c. | C21: Leukosit | E21: 11 | F21: =SUM(D21:E21) -> 11 | G21: 0 | H21: 0 | I21: =SUM(G21:H21) -> 0 | L21: =SUM(J21:K21) -> 0 | M21: 0 | N21: 0 | O21: =SUM(M21:N21) -> 0 | P21: 3 | Q21: 6 | R21: =SUM(P21:Q21) -> 9 | S21: 0 | T21: 0 | U21: =SUM(S21:T21) -> 0
B22: d. | C22: Eritrosit | E22: 11 | F22: =SUM(D22:E22) -> 11 | G22: 0 | H22: 0 | I22: =SUM(G22:H22) -> 0 | L22: =SUM(J22:K22) -> 0 | M22: 0 | N22: 0 | O22: =SUM(M22:N22) -> 0 | P22: 3 | Q22: 6 | R22: =SUM(P22:Q22) -> 9 | S22: 0 | T22: 0 | U22: =SUM(S22:T22) -> 0
B23: e. | C23: Trombosit | F23: =SUM(D23:E23) -> 0 | G23: 0 | H23: 0 | I23: =SUM(G23:H23) -> 0 | L23: =SUM(J23:K23) -> 0 | M23: 0 | N23: 0 | O23: =SUM(M23:N23) -> 0 | P23: 3 | Q23: 6 | R23: =SUM(P23:Q23) -> 9 | S23: 0 | T23: 0 | U23: =SUM(S23:T23) -> 0
B24: f. | C24: Glukosa Post pandiel ( 2 jam PP ) | F24: =SUM(D24:E24) -> 0 | G24: 0 | H24: 0 | I24: =SUM(G24:H24) -> 0 | L24: =SUM(J24:K24) -> 0 | M24: 0 | N24: 0 | O24: =SUM(M24:N24) -> 0 | P24: 0 | Q24: 0 | R24: =SUM(P24:Q24) -> 0 | S24: 0 | T24: 1 | U24: =SUM(S24:T24) -> 1
B25: g. | C25: Gulukosa Urine | E25: 19 | F25: =SUM(D25:E25) -> 19 | G25: 0 | H25: 23 | I25: =SUM(G25:H25) -> 23 | L25: =SUM(J25:K25) -> 0 | M25: 0 | N25: 0 | O25: =SUM(M25:N25) -> 0 | P25: 0 | Q25: 0 | R25: =SUM(P25:Q25) -> 0 | S25: 0 | T25: 0 | U25: =SUM(S25:T25) -> 0
B26: h. | C26: Asam Urat | D26: 30 | E26: 58 | F26: =SUM(D26:E26) -> 88 | G26: 19 | H26: 32 | I26: =SUM(G26:H26) -> 51 | J26: 15 | K26: 40 | L26: =SUM(J26:K26) -> 55 | M26: 8 | N26: 28 | O26: =SUM(M26:N26) -> 36 | P26: 1 | Q26: 0 | R26: =SUM(P26:Q26) -> 1 | S26: 0 | T26: 0 | U26: =SUM(S26:T26) -> 0
B27: i. | C27: Gula darah sewaktu | D27: 67 | E27: 155 | F27: =SUM(D27:E27) -> 222 | G27: 55 | H27: 110 | I27: =SUM(G27:H27) -> 165 | J27: 8 | K27: 11 | L27: =SUM(J27:K27) -> 19 | M27: 19 | N27: 58 | O27: =SUM(M27:N27) -> 77 | P27: 4 | Q27: 54 | R27: =SUM(P27:Q27) -> 58 | S27: 11 | T27: 8 | U27: =SUM(S27:T27) -> 19
B28: j. | C28: Gula darah puasa | D28: 30 | E28: 71 | F28: =SUM(D28:E28) -> 101 | G28: 25 | H28: 39 | I28: =SUM(G28:H28) -> 64 | J28: 8 | K28: 18 | L28: =SUM(J28:K28) -> 26 | M28: 1 | N28: 5 | O28: =SUM(M28:N28) -> 6 | P28: 6 | Q28: 19 | R28: =SUM(P28:Q28) -> 25 | S28: 8 | T28: 6 | U28: =SUM(S28:T28) -> 14
B29: k. | C29: HCT | F29: =SUM(D29:E29) -> 0 | G29: 0 | H29: 0 | I29: =SUM(G29:H29) -> 0 | J29: 0 | K29: 2 | L29: =SUM(J29:K29) -> 2 | M29: 0 | N29: 0 | O29: =SUM(M29:N29) -> 0 | P29: 0 | Q29: 0 | R29: =SUM(P29:Q29) -> 0 | S29: 0 | T29: 0 | U29: =SUM(S29:T29) -> 0
B30: l. | C30: Cholestrol | D30: 34 | E30: 115 | F30: =SUM(D30:E30) -> 149 | G30: 16 | H30: 30 | I30: =SUM(G30:H30) -> 46 | J30: 19 | K30: 43 | L30: =SUM(J30:K30) -> 62 | M30: 13 | N30: 35 | O30: =SUM(M30:N30) -> 48 | P30: 7 | Q30: 13 | R30: =SUM(P30:Q30) -> 20 | S30: =25-T30 -> 18 | T30: 7 | U30: =SUM(S30:T30) -> 25
B31: m. | C31: Protein Urine | E31: 24 | F31: =SUM(D31:E31) -> 24 | G31: 0 | H31: 23 | I31: =SUM(G31:H31) -> 23 | J31: 0 | K31: 1 | L31: =SUM(J31:K31) -> 1 | M31: 0 | N31: 0 | O31: =SUM(M31:N31) -> 0 | P31: 0 | Q31: 35 | R31: =SUM(P31:Q31) -> 35 | S31: 0 | T31: 5 | U31: =SUM(S31:T31) -> 5
B32: n. | C32: HIV | D32: 9 | E32: 40 | F32: =SUM(D32:E32) -> 49 | G32: 0 | H32: 27 | I32: =SUM(G32:H32) -> 27 | J32: 0 | K32: 21 | L32: =SUM(J32:K32) -> 21 | M32: 1 | N32: 13 | O32: =SUM(M32:N32) -> 14 | P32: 0 | Q32: 23 | R32: =SUM(P32:Q32) -> 23 | S32: 0 | T32: 14 | U32: =SUM(S32:T32) -> 14
B33: o. | C33: SYPHILIS | D33: 8 | E33: 40 | F33: =SUM(D33:E33) -> 48 | G33: 0 | H33: 27 | I33: =SUM(G33:H33) -> 27 | J33: 0 | K33: 19 | L33: =SUM(J33:K33) -> 19 | M33: 1 | N33: 12 | O33: =SUM(M33:N33) -> 13 | P33: 0 | Q33: 23 | R33: =SUM(P33:Q33) -> 23 | S33: 0 | T33: 14 | U33: =SUM(S33:T33) -> 14
B34: p. | C34: HBSAg | D34: 24 | E34: 70 | F34: =SUM(D34:E34) -> 94 | G34: 0 | H34: 30 | I34: =SUM(G34:H34) -> 30 | J34: 1 | K34: 24 | L34: =SUM(J34:K34) -> 25 | M34: 3 | N34: 12 | O34: =SUM(M34:N34) -> 15 | P34: 0 | Q34: 23 | R34: =SUM(P34:Q34) -> 23 | S34: 0 | T34: 14 | U34: =SUM(S34:T34) -> 14
B35: q. | C35: Malaria P.V (Jika positip isi jenis plasmodiumnya) | D35: 2 | E35: 37 | F35: =SUM(D35:E35) -> 39 | G35: 0 | H35: 0 | I35: =SUM(G35:H35) -> 0 | L35: =SUM(J35:K35) -> 0 | M35: 2 | N35: 12 | O35: =SUM(M35:N35) -> 14 | P35: 12 | Q35: 27 | R35: =SUM(P35:Q35) -> 39 | S35: 0 | T35: 2 | U35: =SUM(S35:T35) -> 2
B36: r. | C36: Widal | F36: =SUM(D36:E36) -> 0 | G36: 0 | H36: 0 | I36: =SUM(G36:H36) -> 0 | L36: =SUM(J36:K36) -> 0 | M36: 0 | N36: 0 | O36: =SUM(M36:N36) -> 0 | P36: 0 | Q36: 0 | R36: =SUM(P36:Q36) -> 0 | S36: 0 | T36: 0 | U36: =SUM(S36:T36) -> 0
B37: s. | C37: Sputum BTA | F37: =SUM(D37:E37) -> 0 | G37: 0 | H37: 0 | I37: =SUM(G37:H37) -> 0 | L37: =SUM(J37:K37) -> 0 | M37: 2 | N37: 1 | O37: =SUM(M37:N37) -> 3 | P37: 0 | Q37: 0 | R37: =SUM(P37:Q37) -> 0 | S37: 0 | T37: 0 | U37: =SUM(S37:T37) -> 0
B38: t. | C38: Test Kehamilan | E38: 35 | F38: =SUM(D38:E38) -> 35 | G38: 0 | H38: 8 | I38: =SUM(G38:H38) -> 8 | J38: 0 | K38: 23 | L38: =SUM(J38:K38) -> 23 | M38: 0 | N38: 3 | O38: =SUM(M38:N38) -> 3 | P38: 0 | Q38: 13 | R38: =SUM(P38:Q38) -> 13 | S38: 0 | T38: 7 | U38: =SUM(S38:T38) -> 7
B39: u. | C39: Tinja | F39: =SUM(D39:E39) -> 0 | G39: 0 | H39: 0 | I39: =SUM(G39:H39) -> 0 | L39: =SUM(J39:K39) -> 0 | M39: 0 | N39: 0 | O39: =SUM(M39:N39) -> 0 | P39: 0 | Q39: 0 | R39: =SUM(P39:Q39) -> 0 | S39: 0 | T39: 0 | U39: =SUM(S39:T39) -> 0
B40: v. | C40: Urine Lengkap | F40: =SUM(D40:E40) -> 0 | G40: 0 | H40: 0 | I40: =SUM(G40:H40) -> 0 | J40: 0 | K40: 2 | L40: =SUM(J40:K40) -> 2 | M40: 0 | N40: 8 | O40: =SUM(M40:N40) -> 8 | P40: 0 | Q40: 2 | R40: =SUM(P40:Q40) -> 2 | S40: 0 | T40: 0 | U40: =SUM(S40:T40) -> 0
B41: w. | C41: Urine Sedimen | F41: =SUM(D41:E41) -> 0 | G41: 0 | H41: 0 | I41: =SUM(G41:H41) -> 0 | L41: =SUM(J41:K41) -> 0 | M41: 0 | N41: 0 | O41: =SUM(M41:N41) -> 0 | P41: 0 | Q41: 0 | R41: =SUM(P41:Q41) -> 0 | S41: 0 | T41: 0 | U41: =SUM(S41:T41) -> 0
A44: No. | B44: ELEMEN DATA | D44: KORBAFO | G44: NDAO | J44: OELABA | M44: OELE | P44: SONIMANU | S44: SOTIMORI
...

Sheet MARET
A2: LAPORAN LABORATORIUM
A3: DI PUSKESMAS KABUPATEN ROTE NDAO
A4: MARET 2026
A6: No. | B6: ELEMEN DATA | D6: BAA | G6: BATUTUA | J6: BUSALANGGA | M6: DELHA | P6: EAHUN | S6: FEAPOPI
D7: L | E7: P | F7: TOTAL | G7: L | H7: P | I7: TOTAL | J7: L | K7: P | L7: TOTAL | M7: L | N7: P | O7: TOTAL | P7: L | Q7: P | R7: TOTAL | S7: L | T7: P | U7: TOTAL
A8: 1 | B8: Total Kunjungan Laboratorium | D8: =D9+D18 -> 631 | E8: =E9+E18 -> 1615 | F8: =F9+F18 -> 2246 | G8: =G9+G18 -> 211 | H8: =H9+H18 -> 806 | I8: =I9+I18 -> 1017 | J8: =J9+J18 -> 242 | K8: =K9+K18 -> 826 | ... U8: =U9+U18 -> 267
A9: 2 | B9: Peminta Tes Laboratorium | D9: =SUM(D10:D17) -> 76 | E9: =SUM(E10:E17) -> 230 | F9: =SUM(F10:F17) -> 306 | G9: =SUM(G10:G17) -> 59 | H9: =SUM(H10:H17) -> 156 | I9: =SUM(I10:I17) -> 215 | J9: =SUM(J10:J17) -> 121 | K9: =SUM(K10:K17) -> 413 | ... U9: =SUM(U10:U17) -> 81
B10: a. | C10: Poli umum | D10: 55 | E10: 121 | F10: =SUM(D10:E10) -> 176 | G10: 40 | H10: 80 | I10: =SUM(G10:H10) -> 120 | J10: 121 | K10: 300 | L10: =SUM(J10:K10) -> 421 | M10: 27 | N10: 94 | O10: =SUM(M10:N10) -> 121 | P10: 85 | Q10: 142 | R10: =SUM(P10:Q10) -> 227 | S10: 20 | T10: 40 | U10: =SUM(S10:T10) -> 60
B11: b. | C11: KIA / KB | D11: 7 | E11: 74 | F11: =SUM(D11:E11) -> 81 | G11: 0 | H11: 63 | I11: =SUM(G11:H11) -> 63 | J11: 0 | K11: 107 | L11: =SUM(J11:K11) -> 107 | M11: 0 | N11: 34 | O11: =SUM(M11:N11) -> 34 | P11: 0 | Q11: 36 | R11: =SUM(P11:Q11) -> 36 | S11: 0 | T11: 20 | U11: =SUM(S11:T11) -> 20
B12: c. | C12: Rawat inap | D12: 0 | E12: 0 | F12: =SUM(D12:E12) -> 0 | G12: 0 | H12: 0 | I12: =SUM(G12:H12) -> 0 | L12: =SUM(J12:K12) -> 0 | M12: 0 | N12: 0 | O12: =SUM(M12:N12) -> 0 | P12: 0 | Q12: 0 | R12: =SUM(P12:Q12) -> 0 | S12: 0 | T12: 0 | U12: =SUM(S12:T12) -> 0
B13: d. | C13: Unit gawat darurat | D13: 0 | E13: 0 | F13: =SUM(D13:E13) -> 0 | G13: 1 | H13: 3 | I13: =SUM(G13:H13) -> 4 | L13: =SUM(J13:K13) -> 0 | M13: 5 | N13: 2 | O13: =SUM(M13:N13) -> 7 | P13: 2 | Q13: 2 | R13: =SUM(P13:Q13) -> 4 | S13: 0 | T13: 0 | U13: =SUM(S13:T13) -> 0
B14: e. | C14: MTBS | D14: 0 | E14: 0 | F14: =SUM(D14:E14) -> 0 | G14: 4 | H14: 1 | I14: =SUM(G14:H14) -> 5 | J14: 0 | K14: 3 | L14: =SUM(J14:K14) -> 3 | M14: 1 | N14: 2 | O14: =SUM(M14:N14) -> 3 | P14: 0 | Q14: 0 | R14: =SUM(P14:Q14) -> 0 | S14: 1 | T14: 0 | U14: =SUM(S14:T14) -> 1
B15: f. | C15: Poli Gigi | D15: 3 | E15: 2 | F15: =SUM(D15:E15) -> 5 | G15: 14 | H15: 4 | I15: =SUM(G15:H15) -> 18 | L15: =SUM(J15:K15) -> 0 | M15: 0 | N15: 0 | O15: =SUM(M15:N15) -> 0 | P15: 3 | Q15: 2 | R15: =SUM(P15:Q15) -> 5 | S15: 0 | T15: 0 | U15: =SUM(S15:T15) -> 0
B16: g. | C16: PONED | D16: 0 | E16: 0 | F16: =SUM(D16:E16) -> 0 | G16: 0 | H16: 5 | I16: =SUM(G16:H16) -> 5 | J16: 0 | K16: 3 | L16: =SUM(J16:K16) -> 3 | M16: 0 | N16: 34 | O16: =SUM(M16:N16) -> 34 | P16: 0 | Q16: 2 | R16: =SUM(P16:Q16) -> 2 | S16: 0 | T16: 0 | U16: =SUM(S16:T16) -> 0
B17: h. | C17: Pustu | D17: 11 | E17: 33 | F17: =SUM(D17:E17) -> 44 | G17: 0 | H17: 0 | I17: =SUM(G17:H17) -> 0 | L17: =SUM(J17:K17) -> 0 | M17: 10 | N17: 25 | O17: =SUM(M17:N17) -> 35 | P17: 0 | Q17: 0 | R17: =SUM(P17:Q17) -> 0 | S17: 0 | T17: 0 | U17: =SUM(S17:T17) -> 0
A18: 3 | B18: Jumlah Pemeriksaan Laboratorium | D18: =SUM(D19:D41) -> 555 | E18: =SUM(E19:E41) -> 1385 | F18: =SUM(F19:F41) -> 1940 | G18: =SUM(G19:G41) -> 152 | H18: =SUM(H19:H41) -> 650 | I18: =SUM(I19:I41) -> 802 | J18: =SUM(J19:J41) -> 121 | K18: =SUM(K19:K41) -> 413 | ... U18: =SUM(U19:U41) -> 186
B19: a. | C19: Golongan darah | D19: 5 | E19: 27 | F19: =SUM(D19:E19) -> 32 | G19: 1 | H19: 33 | I19: =SUM(G19:H19) -> 34 | J19: 5 | K19: 11 | L19: =SUM(J19:K19) -> 16 | M19: 3 | N19: 1 | O19: =SUM(M19:N19) -> 4 | P19: 2 | Q19: 17 | R19: =SUM(P19:Q19) -> 19 | S19: 0 | T19: 10 | U19: =SUM(S19:T19) -> 10
B20: b. | C20: Hb | D20: 11 | E20: 123 | F20: =SUM(D20:E20) -> 134 | G20: 0 | H20: 65 | I20: =SUM(G20:H20) -> 65 | J20: 5 | K20: 32 | L20: =SUM(J20:K20) -> 37 | M20: 2 | N20: 61 | O20: =SUM(M20:N20) -> 63 | P20: 10 | Q20: 34 | R20: =SUM(P20:Q20) -> 44 | S20: 0 | T20: 23 | U20: =SUM(S20:T20) -> 23
B21: c. | C21: Leukosit | D21: 5 | E21: 8 | F21: =SUM(D21:E21) -> 13 | G21: 0 | H21: 0 | I21: =SUM(G21:H21) -> 0 | L21: =SUM(J21:K21) -> 0 | M21: 0 | N21: 0 | O21: =SUM(M21:N21) -> 0 | P21: 5 | Q21: 1 | R21: =SUM(P21:Q21) -> 6 | S21: 0 | T21: 0 | U21: =SUM(S21:T21) -> 0
B22: d. | C22: Eritrosit | D22: 5 | E22: 8 | F22: =SUM(D22:E22) -> 13 | G22: 0 | H22: 0 | I22: =SUM(G22:H22) -> 0 | L22: =SUM(J22:K22) -> 0 | M22: 0 | N22: 0 | O22: =SUM(M22:N22) -> 0 | P22: 5 | Q22: 1 | R22: =SUM(P22:Q22) -> 6 | S22: 0 | T22: 0 | U22: =SUM(S22:T22) -> 0
B23: e. | C23: Trombosit | F23: =SUM(D23:E23) -> 0 | G23: 0 | H23: 0 | I23: =SUM(G23:H23) -> 0 | L23: =SUM(J23:K23) -> 0 | M23: 0 | N23: 0 | O23: =SUM(M23:N23) -> 0 | P23: 5 | Q23: 1 | R23: =SUM(P23:Q23) -> 6 | S23: 0 | T23: 0 | U23: =SUM(S23:T23) -> 0
B24: f. | C24: Glukosa Post pandiel ( 2 jam PP ) | F24: =SUM(D24:E24) -> 0 | G24: 0 | H24: 0 | I24: =SUM(G24:H24) -> 0 | L24: =SUM(J24:K24) -> 0 | M24: 0 | N24: 0 | O24: =SUM(M24:N24) -> 0 | P24: 0 | Q24: 0 | R24: =SUM(P24:Q24) -> 0 | S24: 0 | T24: 0 | U24: =SUM(S24:T24) -> 0
B25: g. | C25: Gulukosa Urine | D25: 5 | E25: 14 | F25: =SUM(D25:E25) -> 19 | G25: 0 | H25: 36 | I25: =SUM(G25:H25) -> 36 | L25: =SUM(J25:K25) -> 0 | M25: 0 | N25: 0 | O25: =SUM(M25:N25) -> 0 | P25: 0 | Q25: 0 | R25: =SUM(P25:Q25) -> 0 | S25: 0 | T25: 0 | U25: =SUM(S25:T25) -> 0
B26: h. | C26: Asam Urat | D26: 106 | E26: 243 | F26: =SUM(D26:E26) -> 349 | G26: 34 | H26: 63 | I26: =SUM(G26:H26) -> 97 | J26: 22 | K26: 83 | L26: =SUM(J26:K26) -> 105 | M26: 28 | N26: 75 | O26: =SUM(M26:N26) -> 103 | P26: 6 | Q26: 9 | R26: =SUM(P26:Q26) -> 15 | S26: 13 | T26: =23-S26 -> 10 | U26: =SUM(S26:T26) -> 23
B27: i. | C27: Gula darah sewaktu | D27: 239 | E27: 428 | F27: =SUM(D27:E27) -> 667 | G27: 50 | H27: 140 | I27: =SUM(G27:H27) -> 190 | J27: 43 | K27: 97 | L27: =SUM(J27:K27) -> 140 | M27: 46 | N27: 134 | O27: =SUM(M27:N27) -> 180 | P27: 71 | Q27: 124 | R27: =SUM(P27:Q27) -> 195 | S27: =19-T27 -> 10 | T27: 9 | U27: =SUM(S27:T27) -> 19
B28: j. | C28: Gula darah puasa | D28: 42 | E28: 99 | F28: =SUM(D28:E28) -> 141 | G28: 31 | H28: 59 | I28: =SUM(G28:H28) -> 90 | J28: 13 | K28: 36 | L28: =SUM(J28:K28) -> 49 | M28: 0 | N28: 2 | O28: =SUM(M28:N28) -> 2 | P28: 14 | Q28: 55 | R28: =SUM(P28:Q28) -> 69 | S28: 9 | T28: 7 | U28: =SUM(S28:T28) -> 16
B29: k. | C29: Urin Acid | F29: =SUM(D29:E29) -> 0 | G29: 0 | H29: 0 | I29: =SUM(G29:H29) -> 0 | L29: =SUM(J29:K29) -> 0 | M29: 0 | N29: 0 | O29: =SUM(M29:N29) -> 0 | P29: 0 | Q29: 0 | R29: =SUM(P29:Q29) -> 0 | S29: 0 | T29: 0 | U29: =SUM(S29:T29) -> 0
B30: l. | C30: Cholestrol | D30: 81 | E30: 216 | F30: =SUM(D30:E30) -> 297 | G30: 30 | H30: 68 | I30: =SUM(G30:H30) -> 98 | J30: 30 | K30: 79 | L30: =SUM(J30:K30) -> 109 | M30: 15 | N30: 48 | O30: =SUM(M30:N30) -> 63 | P30: 17 | Q30: 49 | R30: =SUM(P30:Q30) -> 66 | S30: 21 | T30: =42-S30 -> 21 | U30: =SUM(S30:T30) -> 42
B31: m. | C31: Protein Urine | D31: 7 | E31: 19 | F31: =SUM(D31:E31) -> 26 | G31: 0 | H31: 36 | I31: =SUM(G31:H31) -> 36 | L31: =SUM(J31:K31) -> 0 | M31: 0 | N31: 0 | O31: =SUM(M31:N31) -> 0 | P31: 1 | Q31: 28 | R31: =SUM(P31:Q31) -> 29 | S31: 0 | T31: 10 | U31: =SUM(S31:T31) -> 10
B32: n. | C32: HIV | D32: 3 | E32: 33 | F32: =SUM(D32:E32) -> 36 | G32: 0 | H32: 45 | I32: =SUM(G32:H32) -> 45 | J32: 1 | K32: 15 | L32: =SUM(J32:K32) -> 16 | M32: 1 | N32: 4 | O32: =SUM(M32:N32) -> 5 | P32: 51 | Q32: 88 | R32: =SUM(P32:Q32) -> 139 | S32: 0 | T32: 10 | U32: =SUM(S32:T32) -> 10
B33: o. | C33: SYPHILIS | D33: 3 | E33: 33 | F33: =SUM(D33:E33) -> 36 | G33: 0 | H33: 44 | I33: =SUM(G33:H33) -> 44 | J33: 0 | K33: 14 | L33: =SUM(J33:K33) -> 14 | M33: 1 | N33: 4 | O33: =SUM(M33:N33) -> 5 | P33: 51 | Q33: 88 | R33: =SUM(P33:Q33) -> 139 | S33: 0 | T33: 10 | U33: =SUM(S33:T33) -> 10
B34: p. | C34: HBSAg | D34: 40 | E34: 69 | F34: =SUM(D34:E34) -> 109 | G34: 0 | H34: 43 | I34: =SUM(G34:H34) -> 43 | J34: 2 | K34: 16 | L34: =SUM(J34:K34) -> 18 | M34: 1 | N34: 4 | O34: =SUM(M34:N34) -> 5 | P34: 51 | Q34: 90 | R34: =SUM(P34:Q34) -> 141 | S34: 0 | T34: 11 | U34: =SUM(S34:T34) -> 11
B35: q. | C35: Malaria P.V (Jika positip isi jenis plasmodiumnya) | D35: 3 | E35: 28 | F35: =SUM(D35:E35) -> 31 | G35: 0 | H35: 0 | I35: =SUM(G35:H35) -> 0 | L35: =SUM(J35:K35) -> 0 | M35: 0 | N35: 6 | O35: =SUM(M35:N35) -> 6 | P35: 3 | Q35: 20 | R35: =SUM(P35:Q35) -> 23 | S35: 2 | T35: 7 | U35: =SUM(S35:T35) -> 9
B36: r. | C36: Widal | F36: =SUM(D36:E36) -> 0 | G36: 0 | H36: 0 | I36: =SUM(G36:H36) -> 0 | L36: =SUM(J36:K36) -> 0 | M36: 0 | N36: 0 | O36: =SUM(M36:N36) -> 0 | P36: 0 | Q36: 0 | R36: =SUM(P36:Q36) -> 0 | S36: 0 | T36: 0 | U36: =SUM(S36:T36) -> 0
B37: s. | C37: Sputum BTA | F37: =SUM(D37:E37) -> 0 | G37: 4 | H37: 3 | I37: =SUM(G37:H37) -> 7 | L37: =SUM(J37:K37) -> 0 | M37: 3 | N37: 1 | O37: =SUM(M37:N37) -> 4 | P37: 0 | Q37: 0 | R37: =SUM(P37:Q37) -> 0 | S37: 0 | T37: 0 | U37: =SUM(S37:T37) -> 0
B38: t. | C38: Test Kehamilan | E38: 37 | F38: =SUM(D38:E38) -> 37 | G38: 0 | H38: 11 | I38: =SUM(G38:H38) -> 11 | J38: 0 | K38: 29 | L38: =SUM(J38:K38) -> 29 | M38: 0 | N38: 3 | O38: =SUM(M38:N38) -> 3 | P38: 0 | Q38: 17 | R38: =SUM(P38:Q38) -> 17 | S38: 0 | T38: 3 | U38: =SUM(S38:T38) -> 3
B39: u. | C39: Tinja | F39: =SUM(D39:E39) -> 0 | G39: 0 | H39: 0 | I39: =SUM(G39:H39) -> 0 | L39: =SUM(J39:K39) -> 0 | M39: 0 | N39: 0 | O39: =SUM(M39:N39) -> 0 | P39: 0 | Q39: 0 | R39: =SUM(P39:Q39) -> 0 | S39: 0 | T39: 0 | U39: =SUM(S39:T39) -> 0
B40: v. | C40: Urine Lengkap | F40: =SUM(D40:E40) -> 0 | G40: 2 | H40: 4 | I40: =SUM(G40:H40) -> 6 | J40: 0 | K40: 1 | L40: =SUM(J40:K40) -> 1 | M40: 1 | N40: 20 | O40: =SUM(M40:N40) -> 21 | P40: 2 | Q40: 1 | R40: =SUM(P40:Q40) -> 3 | S40: 0 | T40: 0 | U40: =SUM(S40:T40) -> 0
B41: w. | C41: Urine Sedimen | F41: =SUM(D41:E41) -> 0 | G41: 0 | H41: 0 | I41: =SUM(G41:H41) -> 0 | L41: =SUM(J41:K41) -> 0 | M41: 0 | N41: 0 | O41: =SUM(M41:N41) -> 0 | P41: 0 | Q41: 0 | R41: =SUM(P41:Q41) -> 0 | S41: 0 | T41: 0 | U41: =SUM(S41:T41) -> 0
A44: No. | B44: ELEMEN DATA | D44: KORBAFO | G44: NDAO | J44: OELABA | M44: OELE | P44: SONIMANU | S44: SOTIMORI
...

Sheet APRIL
A2: LAPORAN LABORATORIUM
A3: DI PUSKESMAS KABUPATEN ROTE NDAO
A4: APRIL 2026
A6: No. | B6: ELEMEN DATA | D6: BAA | G6: BATUTUA | J6: BUSALANGGA | M6: DELHA | P6: EAHUN | S6: FEAPOPI
D7: L | E7: P | F7: TOTAL | G7: L | H7: P | I7: TOTAL | J7: L | K7: P | L7: TOTAL | M7: L | N7: P | O7: TOTAL | P7: L | Q7: P | R7: TOTAL | S7: L | T7: P | U7: TOTAL
A8: 1 | B8: Total Kunjungan Laboratorium | D8: =D9+D18 -> 493 | E8: =E9+E18 -> 1396 | F8: =F9+F18 -> 1889 | G8: =G9+G18 -> 252 | H8: =H9+H18 -> 615 | I8: =I9+I18 -> 867 | J8: =J9+J18 -> 172 | K8: =K9+K18 -> 622 | ... U8: =U9+U18 -> 296
A9: 2 | B9: Peminta Tes Laboratorium | D9: =SUM(D10:D17) -> 73 | E9: =SUM(E10:E17) -> 257 | F9: =SUM(F10:F17) -> 330 | G9: =SUM(G10:G17) -> 73 | H9: =SUM(H10:H17) -> 159 | I9: =SUM(I10:I17) -> 232 | J9: =SUM(J10:J17) -> 86 | K9: =SUM(K10:K17) -> 311 | ... U9: =SUM(U10:U17) -> 101
B10: a. | C10: Poli umum | D10: 34 | E10: 81 | F10: =SUM(D10:E10) -> 115 | G10: 71 | H10: 106 | I10: =SUM(G10:H10) -> 177 | J10: 83 | K10: 146 | L10: =SUM(J10:K10) -> 229 | M10: 23 | N10: 65 | O10: =SUM(M10:N10) -> 88 | P10: 38 | Q10: 70 | R10: =SUM(P10:Q10) -> 108 | S10: 27 | T10: =82-S10 -> 55 | U10: =SUM(S10:T10) -> 82
B11: b. | C11: KIA / KB | D11: 4 | E11: 59 | F11: =SUM(D11:E11) -> 63 | G11: 0 | H11: 34 | I11: =SUM(G11:H11) -> 34 | J11: 0 | K11: 150 | L11: =SUM(J11:K11) -> 150 | M11: 0 | N11: 38 | O11: =SUM(M11:N11) -> 38 | P11: 0 | Q11: 39 | R11: =SUM(P11:Q11) -> 39 | S11: 0 | T11: 19 | U11: =SUM(S11:T11) -> 19
B12: c. | C12: Rawat inap | F12: =SUM(D12:E12) -> 0 | G12: 0 | H12: 0 | I12: =SUM(G12:H12) -> 0 | L12: =SUM(J12:K12) -> 0 | M12: 0 | N12: 1 | O12: =SUM(M12:N12) -> 1 | P12: 0 | Q12: 0 | R12: =SUM(P12:Q12) -> 0 | S12: 0 | T12: 0 | U12: =SUM(S12:T12) -> 0
B13: d. | C13: Unit gawat darurat | F13: =SUM(D13:E13) -> 0 | G13: 0 | H13: 1 | I13: =SUM(G13:H13) -> 1 | L13: =SUM(J13:K13) -> 0 | M13: 3 | N13: 6 | O13: =SUM(M13:N13) -> 9 | P13: 1 | Q13: 3 | R13: =SUM(P13:Q13) -> 4 | S13: 0 | T13: 0 | U13: =SUM(S13:T13) -> 0
B14: e. | C14: MTBS | F14: =SUM(D14:E14) -> 0 | G14: 0 | H14: 2 | I14: =SUM(G14:H14) -> 2 | J14: 2 | K14: 1 | L14: =SUM(J14:K14) -> 3 | M14: 0 | N14: 1 | O14: =SUM(M14:N14) -> 1 | P14: 0 | Q14: 0 | R14: =SUM(P14:Q14) -> 0 | S14: 0 | T14: 0 | U14: =SUM(S14:T14) -> 0
B15: f. | C15: Poli Gigi | D15: 6 | E15: 5 | F15: =SUM(D15:E15) -> 11 | G15: 0 | H15: 7 | I15: =SUM(G15:H15) -> 7 | J15: 1 | K15: 10 | L15: =SUM(J15:K15) -> 11 | M15: 1 | N15: 0 | O15: =SUM(M15:N15) -> 1 | P15: 0 | Q15: 0 | R15: =SUM(P15:Q15) -> 0 | S15: 0 | T15: 0 | U15: =SUM(S15:T15) -> 0
B16: g. | C16: PONED | F16: =SUM(D16:E16) -> 0 | G16: 2 | H16: 9 | I16: =SUM(G16:H16) -> 11 | J16: 0 | K16: 4 | L16: =SUM(J16:K16) -> 4 | M16: 4 | N16: 20 | O16: =SUM(M16:N16) -> 24 | P16: 0 | Q16: 3 | R16: =SUM(P16:Q16) -> 3 | S16: 0 | T16: 0 | U16: =SUM(S16:T16) -> 0
B17: h. | C17: Pustu | D17: 29 | E17: 112 | F17: =SUM(D17:E17) -> 141 | G17: 0 | H17: 0 | I17: =SUM(G17:H17) -> 0 | L17: =SUM(J17:K17) -> 0 | M17: 13 | N17: 50 | O17: =SUM(M17:N17) -> 63 | P17: 0 | Q17: 0 | R17: =SUM(P17:Q17) -> 0 | S17: 0 | T17: 0 | U17: =SUM(S17:T17) -> 0
A18: 3 | B18: Jumlah Pemeriksaan Laboratorium | D18: =SUM(D19:D41) -> 420 | E18: =SUM(E19:E41) -> 1139 | F18: =SUM(F19:F41) -> 1559 | G18: =SUM(G19:G41) -> 179 | H18: =SUM(H19:H41) -> 456 | I18: =SUM(I19:I41) -> 635 | J18: =SUM(J19:J41) -> 86 | K18: =SUM(K19:K41) -> 311 | ... U18: =SUM(U19:U41) -> 195
B19: a. | C19: Golongan darah | D19: 7 | E19: 16 | F19: =SUM(D19:E19) -> 23 | G19: 14 | H19: 22 | I19: =SUM(G19:H19) -> 36 | J19: 7 | K19: 11 | L19: =SUM(J19:K19) -> 18 | M19: 0 | N19: 6 | O19: =SUM(M19:N19) -> 6 | P19: 5 | Q19: 22 | R19: =SUM(P19:Q19) -> 27 | S19: 0 | T19: 6 | U19: =SUM(S19:T19) -> 6
B20: b. | C20: Hb | D20: 1 | E20: 51 | F20: =SUM(D20:E20) -> 52 | G20: 2 | H20: 41 | I20: =SUM(G20:H20) -> 43 | J20: 2 | K20: 32 | L20: =SUM(J20:K20) -> 34 | M20: 3 | N20: 53 | O20: =SUM(M20:N20) -> 56 | P20: 7 | Q20: 50 | R20: =SUM(P20:Q20) -> 57 | S20: 0 | T20: 15 | U20: =SUM(S20:T20) -> 15
B21: c. | C21: Leukosit | D21: 1 | E21: 5 | F21: =SUM(D21:E21) -> 6 | G21: 0 | H21: 0 | I21: =SUM(G21:H21) -> 0 | L21: =SUM(J21:K21) -> 0 | M21: 0 | N21: 0 | O21: =SUM(M21:N21) -> 0 | P21: 0 | Q21: 0 | R21: =SUM(P21:Q21) -> 0 | S21: 0 | T21: 2 | U21: =SUM(S21:T21) -> 2
B22: d. | C22: Eritrosit | D22: 1 | E22: 5 | F22: =SUM(D22:E22) -> 6 | G22: 0 | H22: 0 | I22: =SUM(G22:H22) -> 0 | L22: =SUM(J22:K22) -> 0 | M22: 0 | N22: 0 | O22: =SUM(M22:N22) -> 0 | P22: 0 | Q22: 0 | R22: =SUM(P22:Q22) -> 0 | S22: 0 | T22: 0 | U22: =SUM(S22:T22) -> 0
B23: e. | C23: HCT | F23: =SUM(D23:E23) -> 0 | G23: 0 | H23: 0 | I23: =SUM(G23:H23) -> 0 | J23: 1 | K23: 32 | L23: =SUM(J23:K23) -> 33 | M23: 0 | N23: 0 | O23: =SUM(M23:N23) -> 0 | P23: 0 | Q23: 0 | R23: =SUM(P23:Q23) -> 0 | S23: 0 | T23: 0 | U23: =SUM(S23:T23) -> 0
B24: f. | C24: Glukosa Post pandiel ( 2 jam PP ) | F24: =SUM(D24:E24) -> 0 | G24: 0 | H24: 0 | I24: =SUM(G24:H24) -> 0 | L24: =SUM(J24:K24) -> 0 | M24: 0 | N24: 0 | O24: =SUM(M24:N24) -> 0 | P24: 0 | Q24: 0 | R24: =SUM(P24:Q24) -> 0 | S24: 0 | T24: 0 | U24: =SUM(S24:T24) -> 0
B25: g. | C25: Gulukosa Urine | F25: =SUM(D25:E25) -> 0 | G25: 0 | H25: 19 | I25: =SUM(G25:H25) -> 19 | L25: =SUM(J25:K25) -> 0 | M25: 0 | N25: 0 | O25: =SUM(M25:N25) -> 0 | P25: 0 | Q25: 0 | R25: =SUM(P25:Q25) -> 0 | S25: 0 | T25: 0 | U25: =SUM(S25:T25) -> 0
B26: h. | C26: Asam Urat | D26: 90 | E26: 184 | F26: =SUM(D26:E26) -> 274 | G26: 36 | H26: 56 | I26: =SUM(G26:H26) -> 92 | J26: 24 | K26: 40 | L26: =SUM(J26:K26) -> 64 | M26: 18 | N26: 77 | O26: =SUM(M26:N26) -> 95 | P26: 19 | Q26: 46 | R26: =SUM(P26:Q26) -> 65 | S26: =33-T26 -> 17 | T26: 16 | U26: =SUM(S26:T26) -> 33
B27: i. | C27: Gula darah sewaktu | D27: 183 | E27: 411 | F27: =SUM(D27:E27) -> 594 | G27: 41 | H27: 88 | I27: =SUM(G27:H27) -> 129 | J27: 31 | K27: 66 | L27: =SUM(J27:K27) -> 97 | M27: 22 | N27: 98 | O27: =SUM(M27:N27) -> 120 | P27: 21 | Q27: 91 | R27: =SUM(P27:Q27) -> 112 | S27: =32-T27 -> 17 | T27: 15 | U27: =SUM(S27:T27) -> 32
B28: j. | C28: Gula darah puasa | D28: 29 | E28: 69 | F28: =SUM(D28:E28) -> 98 | G28: 32 | H28: 43 | I28: =SUM(G28:H28) -> 75 | J28: 6 | K28: 15 | L28: =SUM(J28:K28) -> 21 | M28: 1 | N28: 3 | O28: =SUM(M28:N28) -> 4 | P28: 12 | Q28: 23 | R28: =SUM(P28:Q28) -> 35 | S28: =19-T28 -> 7 | T28: 12 | U28: =SUM(S28:T28) -> 19
B29: k. | C29: Urin Acid | F29: =SUM(D29:E29) -> 0 | G29: 0 | H29: 0 | I29: =SUM(G29:H29) -> 0 | L29: =SUM(J29:K29) -> 0 | M29: 0 | N29: 0 | O29: =SUM(M29:N29) -> 0 | P29: 0 | Q29: 0 | R29: =SUM(P29:Q29) -> 0 | S29: 0 | T29: 0 | U29: =SUM(S29:T29) -> 0
B30: l. | C30: Cholestrol | D30: 94 | E30: 240 | F30: =SUM(D30:E30) -> 334 | G30: 43 | H30: 66 | I30: =SUM(G30:H30) -> 109 | J30: 11 | K30: 15 | L30: =SUM(J30:K30) -> 26 | M30: 18 | N30: 100 | O30: =SUM(M30:N30) -> 118 | P30: 15 | Q30: 44 | R30: =SUM(P30:Q30) -> 59 | S30: =44-T30 -> 27 | T30: 17 | U30: =SUM(S30:T30) -> 44
B31: m. | C31: Protein Urine | D31: 2 | E31: 23 | F31: =SUM(D31:E31) -> 25 | G31: 0 | H31: 19 | I31: =SUM(G31:H31) -> 19 | J31: 0 | K31: 1 | L31: =SUM(J31:K31) -> 1 | M31: 0 | N31: 0 | O31: =SUM(M31:N31) -> 0 | P31: 0 | Q31: 31 | R31: =SUM(P31:Q31) -> 31 | S31: 0 | T31: 10 | U31: =SUM(S31:T31) -> 10
B32: n. | C32: HIV | D32: 1 | E32: 30 | F32: =SUM(D32:E32) -> 31 | G32: 2 | H32: 27 | I32: =SUM(G32:H32) -> 29 | J32: 2 | K32: 27 | L32: =SUM(J32:K32) -> 29 | M32: 1 | N32: 18 | O32: =SUM(M32:N32) -> 19 | P32: 4 | Q32: 27 | R32: =SUM(P32:Q32) -> 31 | S32: 0 | T32: 7 | U32: =SUM(S32:T32) -> 7
B33: o. | C33: SYPHILIS | D33: 1 | E33: 30 | F33: =SUM(D33:E33) -> 31 | G33: 2 | H33: 28 | I33: =SUM(G33:H33) -> 30 | J33: 0 | K33: 27 | L33: =SUM(J33:K33) -> 27 | M33: 1 | N33: 16 | O33: =SUM(M33:N33) -> 17 | P33: 4 | Q33: 27 | R33: =SUM(P33:Q33) -> 31 | S33: 0 | T33: 7 | U33: =SUM(S33:T33) -> 7
B34: p. | C34: HBSAg | D34: 9 | E34: 34 | F34: =SUM(D34:E34) -> 43 | G34: 2 | H34: 29 | I34: =SUM(G34:H34) -> 31 | J34: 2 | K34: 28 | L34: =SUM(J34:K34) -> 30 | M34: 0 | N34: 17 | O34: =SUM(M34:N34) -> 17 | P34: 8 | Q34: 29 | R34: =SUM(P34:Q34) -> 37 | S34: 0 | T34: 9 | U34: =SUM(S34:T34) -> 9
B35: q. | C35: Malaria P.V (Jika positip isi jenis plasmodiumnya) | D35: 1 | E35: 27 | F35: =SUM(D35:E35) -> 28 | G35: 0 | H35: 0 | I35: =SUM(G35:H35) -> 0 | L35: =SUM(J35:K35) -> 0 | M35: 1 | N35: 24 | O35: =SUM(M35:N35) -> 25 | P35: 3 | Q35: 19 | R35: =SUM(P35:Q35) -> 22 | S35: 0 | T35: 4 | U35: =SUM(S35:T35) -> 4
B36: r. | C36: Widal | F36: =SUM(D36:E36) -> 0 | G36: 0 | H36: 0 | I36: =SUM(G36:H36) -> 0 | L36: =SUM(J36:K36) -> 0 | M36: 0 | N36: 0 | O36: =SUM(M36:N36) -> 0 | P36: 0 | Q36: 0 | R36: =SUM(P36:Q36) -> 0 | S36: 0 | T36: 0 | U36: =SUM(S36:T36) -> 0
B37: s. | C37: Sputum BTA | F37: =SUM(D37:E37) -> 0 | G37: 4 | H37: 5 | I37: =SUM(G37:H37) -> 9 | L37: =SUM(J37:K37) -> 0 | M37: 2 | N37: 1 | O37: =SUM(M37:N37) -> 3 | P37: 0 | Q37: 0 | R37: =SUM(P37:Q37) -> 0 | S37: 0 | T37: 0 | U37: =SUM(S37:T37) -> 0
B38: t. | C38: Test Kehamilan | E38: 14 | F38: =SUM(D38:E38) -> 14 | G38: 0 | H38: 10 | I38: =SUM(G38:H38) -> 10 | J38: 0 | K38: 15 | L38: =SUM(J38:K38) -> 15 | M38: 0 | N38: 17 | O38: =SUM(M38:N38) -> 17 | P38: 0 | Q38: 13 | R38: =SUM(P38:Q38) -> 13 | S38: 0 | T38: 7 | U38: =SUM(S38:T38) -> 7
B39: u. | C39: Tinja | F39: =SUM(D39:E39) -> 0 | G39: 0 | H39: 0 | I39: =SUM(G39:H39) -> 0 | L39: =SUM(J39:K39) -> 0 | M39: 0 | N39: 0 | O39: =SUM(M39:N39) -> 0 | P39: 0 | Q39: 0 | R39: =SUM(P39:Q39) -> 0 | S39: 0 | T39: 0 | U39: =SUM(S39:T39) -> 0
B40: v. | C40: Urine Lengkap | F40: =SUM(D40:E40) -> 0 | G40: 1 | H40: 3 | I40: =SUM(G40:H40) -> 4 | J40: 0 | K40: 2 | L40: =SUM(J40:K40) -> 2 | M40: 3 | N40: 11 | O40: =SUM(M40:N40) -> 14 | P40: 2 | Q40: 1 | R40: =SUM(P40:Q40) -> 3 | S40: 0 | T40: 0 | U40: =SUM(S40:T40) -> 0
B41: w. | C41: Urine Sedimen | F41: =SUM(D41:E41) -> 0 | G41: 0 | H41: 0 | I41: =SUM(G41:H41) -> 0 | L41: =SUM(J41:K41) -> 0 | M41: 0 | N41: 0 | O41: =SUM(M41:N41) -> 0 | P41: 0 | Q41: 0 | R41: =SUM(P41:Q41) -> 0 | S41: 0 | T41: 0 | U41: =SUM(S41:T41) -> 0
A44: No. | B44: ELEMEN DATA | D44: KORBAFO | G44: NDAO | J44: OELABA | M44: OELE | P44: SONIMANU | S44: SOTIMORI
...

Sheet MEI
A2: LAPORAN LABORATORIUM
A3: DI PUSKESMAS KABUPATEN ROTE NDAO
A4: MEI 2026
A6: No. | B6: ELEMEN DATA | D6: BAA | G6: BATUTUA | J6: BUSALANGGA | M6: DELHA | P6: EAHUN | S6: FEAPOPI
D7: L | E7: P | F7: TOTAL | G7: L | H7: P | I7: TOTAL | J7: L | K7: P | L7: TOTAL | M7: L | N7: P | O7: TOTAL | P7: L | Q7: P | R7: TOTAL | S7: L | T7: P | U7: TOTAL
A8: 1 | B8: Total Kunjungan Laboratorium | D8: =D9+D18 -> 0 | E8: =E9+E18 -> 0 | F8: =F9+F18 -> 0 | G8: =G9+G18 -> 188 | H8: =H9+H18 -> 468 | I8: =I9+I18 -> 656 | J8: =J9+J18 -> 268 | K8: =K9+K18 -> 650 | ... U8: =U9+U18 -> 499
A9: 2 | B9: Peminta Tes Laboratorium | D9: =SUM(D10:D17) -> 0 | E9: =SUM(E10:E17) -> 0 | F9: =SUM(F10:F17) -> 0 | G9: =SUM(G10:G17) -> 57 | H9: =SUM(H10:H17) -> 116 | I9: =SUM(I10:I17) -> 173 | J9: =SUM(J10:J17) -> 134 | K9: =SUM(K10:K17) -> 325 | ... U9: =SUM(U10:U17) -> 236
B10: a. | C10: Poli umum | F10: =SUM(D10:E10) -> 0 | G10: 49 | H10: 74 | I10: =SUM(G10:H10) -> 123 | J10: 133 | K10: 215 | L10: =SUM(J10:K10) -> 348 | M10: 51 | N10: 79 | O10: =SUM(M10:N10) -> 130 | P10: 37 | Q10: 60 | R10: =SUM(P10:Q10) -> 97 | S10: 76 | T10: =197-S10 -> 121 | U10: =SUM(S10:T10) -> 197
B11: b. | C11: KIA / KB | F11: =SUM(D11:E11) -> 0 | G11: 0 | H11: 30 | I11: =SUM(G11:H11) -> 30 | J11: 0 | K11: 109 | L11: =SUM(J11:K11) -> 109 | M11: 0 | N11: 32 | O11: =SUM(M11:N11) -> 32 | P11: 0 | Q11: 31 | R11: =SUM(P11:Q11) -> 31 | S11: 0 | T11: 39 | U11: =SUM(S11:T11) -> 39
B12: c. | C12: Rawat inap | F12: =SUM(D12:E12) -> 0 | G12: 0 | H12: 0 | I12: =SUM(G12:H12) -> 0 | L12: =SUM(J12:K12) -> 0 | M12: 0 | N12: 0 | O12: =SUM(M12:N12) -> 0 | P12: 0 | Q12: 1 | R12: =SUM(P12:Q12) -> 1 | S12: 0 | T12: 0 | U12: =SUM(S12:T12) -> 0
B13: d. | C13: Unit gawat darurat | F13: =SUM(D13:E13) -> 0 | G13: 0 | H13: 3 | I13: =SUM(G13:H13) -> 3 | L13: =SUM(J13:K13) -> 0 | M13: 3 | N13: 14 | O13: =SUM(M13:N13) -> 17 | P13: 5 | Q13: 0 | R13: =SUM(P13:Q13) -> 5 | S13: 0 | T13: 0 | U13: =SUM(S13:T13) -> 0
B14: e. | C14: MTBS | F14: =SUM(D14:E14) -> 0 | G14: 3 | H14: 3 | I14: =SUM(G14:H14) -> 6 | L14: =SUM(J14:K14) -> 0 | M14: 0 | N14: 0 | O14: =SUM(M14:N14) -> 0 | P14: 0 | Q14: 0 | R14: =SUM(P14:Q14) -> 0 | S14: 0 | T14: 0 | U14: =SUM(S14:T14) -> 0
B15: f. | C15: Poli Gigi | F15: =SUM(D15:E15) -> 0 | G15: 5 | H15: 3 | I15: =SUM(G15:H15) -> 8 | J15: 1 | K15: 1 | L15: =SUM(J15:K15) -> 2 | M15: 0 | O15: =SUM(M15:N15) -> 0 | P15: 0 | Q15: 0 | R15: =SUM(P15:Q15) -> 0 | S15: 0 | T15: 0 | U15: =SUM(S15:T15) -> 0
B16: g. | C16: PONED | F16: =SUM(D16:E16) -> 0 | G16: 0 | H16: 3 | I16: =SUM(G16:H16) -> 3 | L16: =SUM(J16:K16) -> 0 | M16: 5 | N16: 21 | O16: =SUM(M16:N16) -> 26 | P16: 0 | Q16: 3 | R16: =SUM(P16:Q16) -> 3 | S16: 0 | T16: 0 | U16: =SUM(S16:T16) -> 0
B17: h. | C17: Pustu | F17: =SUM(D17:E17) -> 0 | G17: 0 | H17: 0 | I17: =SUM(G17:H17) -> 0 | L17: =SUM(J17:K17) -> 0 | M17: 12 | N17: 45 | O17: =SUM(M17:N17) -> 57 | P17: 0 | Q17: 0 | R17: =SUM(P17:Q17) -> 0 | S17: 0 | T17: 0 | U17: =SUM(S17:T17) -> 0
A18: 3 | B18: Jumlah Pemeriksaan Laboratorium | D18: =SUM(D19:D41) -> 0 | E18: =SUM(E19:E41) -> 0 | F18: =SUM(F19:F41) -> 0 | G18: =SUM(G19:G41) -> 131 | H18: =SUM(H19:H41) -> 352 | I18: =SUM(I19:I41) -> 483 | J18: =SUM(J19:J41) -> 134 | K18: =SUM(K19:K41) -> 325 | ... U18: =SUM(U19:U41) -> 263
B19: a. | C19: Golongan darah | F19: =SUM(D19:E19) -> 0 | G19: 6 | H19: 25 | I19: =SUM(G19:H19) -> 31 | J19: 1 | K19: 9 | L19: =SUM(J19:K19) -> 10 | M19: 2 | N19: 7 | O19: =SUM(M19:N19) -> 9 | P19: 0 | Q19: 16 | R19: =SUM(P19:Q19) -> 16 | S19: 0 | T19: 5 | U19: =SUM(S19:T19) -> 5
B20: b. | C20: Hb | F20: =SUM(D20:E20) -> 0 | G20: 0 | H20: 36 | I20: =SUM(G20:H20) -> 36 | J20: 2 | K20: 17 | L20: =SUM(J20:K20) -> 19 | M20: 7 | N20: 60 | O20: =SUM(M20:N20) -> 67 | P20: 7 | Q20: 36 | R20: =SUM(P20:Q20) -> 43 | S20: 0 | T20: 12 | U20: =SUM(S20:T20) -> 12
B21: c. | C21: Leukosit | F21: =SUM(D21:E21) -> 0 | G21: 0 | H21: 0 | I21: =SUM(G21:H21) -> 0 | L21: =SUM(J21:K21) -> 0 | M21: 0 | N21: 0 | O21: =SUM(M21:N21) -> 0 | P21: 0 | Q21: 0 | R21: =SUM(P21:Q21) -> 0 | S21: 0 | T21: 0 | U21: =SUM(S21:T21) -> 0
B22: d. | C22: Eritrosit | F22: =SUM(D22:E22) -> 0 | G22: 0 | H22: 0 | I22: =SUM(G22:H22) -> 0 | L22: =SUM(J22:K22) -> 0 | M22: 0 | N22: 0 | O22: =SUM(M22:N22) -> 0 | P22: 0 | Q22: 0 | R22: =SUM(P22:Q22) -> 0 | S22: 0 | T22: 0 | U22: =SUM(S22:T22) -> 0
B23: e. | C23: HCT | F23: =SUM(D23:E23) -> 0 | G23: 0 | H23: 0 | I23: =SUM(G23:H23) -> 0 | J23: 2 | K23: 17 | L23: =SUM(J23:K23) -> 19 | M23: 0 | N23: 0 | O23: =SUM(M23:N23) -> 0 | P23: 0 | Q23: 0 | R23: =SUM(P23:Q23) -> 0 | S23: 0 | T23: 0 | U23: =SUM(S23:T23) -> 0
B24: f. | C24: Glukosa Post pandiel ( 2 jam PP ) | F24: =SUM(D24:E24) -> 0 | G24: 0 | H24: 0 | I24: =SUM(G24:H24) -> 0 | L24: =SUM(J24:K24) -> 0 | M24: 3 | N24: 0 | O24: =SUM(M24:N24) -> 3 | P24: 0 | Q24: 0 | R24: =SUM(P24:Q24) -> 0 | S24: 0 | T24: 0 | U24: =SUM(S24:T24) -> 0
B25: g. | C25: Gulukosa Urine | F25: =SUM(D25:E25) -> 0 | G25: 0 | H25: 21 | I25: =SUM(G25:H25) -> 21 | L25: =SUM(J25:K25) -> 0 | M25: 0 | N25: 0 | O25: =SUM(M25:N25) -> 0 | P25: 0 | Q25: 0 | R25: =SUM(P25:Q25) -> 0 | S25: 0 | T25: 0 | U25: =SUM(S25:T25) -> 0
B26: h. | C26: Asam Urat | F26: =SUM(D26:E26) -> 0 | G26: 28 | H26: 28 | I26: =SUM(G26:H26) -> 56 | J26: 44 | K26: 67 | L26: =SUM(J26:K26) -> 111 | M26: 24 | N26: 45 | O26: =SUM(M26:N26) -> 69 | P26: 15 | Q26: 37 | R26: =SUM(P26:Q26) -> 52 | S26: 12 | T26: =34-S26 -> 22 | U26: =SUM(S26:T26) -> 34
B27: i. | C27: Gula darah sewaktu | F27: =SUM(D27:E27) -> 0 | G27: 29 | H27: 67 | I27: =SUM(G27:H27) -> 96 | J27: 56 | K27: 95 | L27: =SUM(J27:K27) -> 151 | M27: 42 | N27: 104 | O27: =SUM(M27:N27) -> 146 | P27: 21 | Q27: 52 | R27: =SUM(P27:Q27) -> 73 | S27: 32 | T27: =70-S27 -> 38 | U27: =SUM(S27:T27) -> 70
B28: j. | C28: Gula darah puasa | F28: =SUM(D28:E28) -> 0 | G28: 17 | H28: 21 | I28: =SUM(G28:H28) -> 38 | J28: 19 | K28: 39 | L28: =SUM(J28:K28) -> 58 | M28: 5 | N28: 1 | O28: =SUM(M28:N28) -> 6 | P28: 10 | Q28: 25 | R28: =SUM(P28:Q28) -> 35 | S28: 4 | T28: =17-S28 -> 13 | U28: =SUM(S28:T28) -> 17
B29: k. | C29: Urin Acid | F29: =SUM(D29:E29) -> 0 | G29: 0 | H29: 0 | I29: =SUM(G29:H29) -> 0 | L29: =SUM(J29:K29) -> 0 | M29: 0 | N29: 0 | O29: =SUM(M29:N29) -> 0 | P29: 0 | Q29: 0 | R29: =SUM(P29:Q29) -> 0 | S29: 0 | T29: 0 | U29: =SUM(S29:T29) -> 0
B30: l. | C30: Cholestrol | F30: =SUM(D30:E30) -> 0 | G30: 32 | H30: 32 | I30: =SUM(G30:H30) -> 64 | J30: 6 | K30: 22 | L30: =SUM(J30:K30) -> 28 | M30: 27 | N30: 46 | O30: =SUM(M30:N30) -> 73 | P30: 19 | Q30: 37 | R30: =SUM(P30:Q30) -> 56 | S30: 32 | T30: =73-S30 -> 41 | U30: =SUM(S30:T30) -> 73
B31: m. | C31: Protein Urine | F31: =SUM(D31:E31) -> 0 | G31: 0 | H31: 21 | I31: =SUM(G31:H31) -> 21 | L31: =SUM(J31:K31) -> 0 | M31: 0 | N31: 0 | O31: =SUM(M31:N31) -> 0 | P31: 0 | Q31: 22 | R31: =SUM(P31:Q31) -> 22 | S31: 0 | T31: 9 | U31: =SUM(S31:T31) -> 9
B32: n. | C32: HIV | F32: =SUM(D32:E32) -> 0 | G32: 5 | H32: 27 | I32: =SUM(G32:H32) -> 32 | J32: 3 | K32: 16 | L32: =SUM(J32:K32) -> 19 | M32: 1 | N32: 14 | O32: =SUM(M32:N32) -> 15 | P32: 3 | Q32: 17 | R32: =SUM(P32:Q32) -> 20 | S32: 0 | T32: 9 | U32: =SUM(S32:T32) -> 9
B33: o. | C33: SYPHILIS | F33: =SUM(D33:E33) -> 0 | G33: 5 | H33: 27 | I33: =SUM(G33:H33) -> 32 | J33: 0 | K33: 15 | L33: =SUM(J33:K33) -> 15 | M33: 1 | N33: 13 | O33: =SUM(M33:N33) -> 14 | P33: 3 | Q33: 17 | R33: =SUM(P33:Q33) -> 20 | S33: 0 | T33: 9 | U33: =SUM(S33:T33) -> 9
B34: p. | C34: HBSAg | F34: =SUM(D34:E34) -> 0 | G34: 5 | H34: 30 | I34: =SUM(G34:H34) -> 35 | J34: 1 | K34: 15 | L34: =SUM(J34:K34) -> 16 | M34: 1 | N34: 12 | O34: =SUM(M34:N34) -> 13 | P34: 6 | Q34: 17 | R34: =SUM(P34:Q34) -> 23 | S34: 0 | T34: 9 | U34: =SUM(S34:T34) -> 9
B35: q. | C35: Malaria P.V (Jika positip isi jenis plasmodiumnya) | F35: =SUM(D35:E35) -> 0 | G35: 0 | H35: 0 | I35: =SUM(G35:H35) -> 0 | L35: =SUM(J35:K35) -> 0 | M35: 1 | N35: 11 | O35: =SUM(M35:N35) -> 12 | P35: 14 | Q35: 17 | R35: =SUM(P35:Q35) -> 31 | S35: 1 | T35: 9 | U35: =SUM(S35:T35) -> 10
B36: r. | C36: Widal | F36: =SUM(D36:E36) -> 0 | G36: 0 | H36: 0 | I36: =SUM(G36:H36) -> 0 | L36: =SUM(J36:K36) -> 0 | M36: 0 | N36: 0 | O36: =SUM(M36:N36) -> 0 | P36: 0 | Q36: 0 | R36: =SUM(P36:Q36) -> 0 | S36: 0 | T36: 0 | U36: =SUM(S36:T36) -> 0
B37: s. | C37: Sputum BTA | F37: =SUM(D37:E37) -> 0 | G37: 0 | H37: 0 | I37: =SUM(G37:H37) -> 0 | L37: =SUM(J37:K37) -> 0 | M37: 1 | N37: 2 | O37: =SUM(M37:N37) -> 3 | P37: 0 | Q37: 0 | R37: =SUM(P37:Q37) -> 0 | S37: 0 | T37: 0 | U37: =SUM(S37:T37) -> 0
B38: t. | C38: Test Kehamilan | F38: =SUM(D38:E38) -> 0 | G38: 0 | H38: 9 | I38: =SUM(G38:H38) -> 9 | J38: 0 | K38: 13 | L38: =SUM(J38:K38) -> 13 | M38: 0 | N38: 17 | O38: =SUM(M38:N38) -> 17 | P38: 0 | Q38: 8 | R38: =SUM(P38:Q38) -> 8 | S38: 0 | T38: 6 | U38: =SUM(S38:T38) -> 6
B39: u. | C39: Tinja | F39: =SUM(D39:E39) -> 0 | G39: 0 | H39: 0 | I39: =SUM(G39:H39) -> 0 | L39: =SUM(J39:K39) -> 0 | M39: 0 | N39: 0 | O39: =SUM(M39:N39) -> 0 | P39: 0 | Q39: 0 | R39: =SUM(P39:Q39) -> 0 | S39: 0 | T39: 0 | U39: =SUM(S39:T39) -> 0
B40: v. | C40: Urine Lengkap | F40: =SUM(D40:E40) -> 0 | G40: 4 | H40: 8 | I40: =SUM(G40:H40) -> 12 | L40: =SUM(J40:K40) -> 0 | M40: 5 | N40: 28 | O40: =SUM(M40:N40) -> 33 | P40: 0 | Q40: 0 | R40: =SUM(P40:Q40) -> 0 | S40: 0 | T40: 0 | U40: =SUM(S40:T40) -> 0
B41: w. | C41: Urine Sedimen | F41: =SUM(D41:E41) -> 0 | G41: 0 | H41: 0 | I41: =SUM(G41:H41) -> 0 | L41: =SUM(J41:K41) -> 0 | M41: 0 | N41: 0 | O41: =SUM(M41:N41) -> 0 | P41: 0 | Q41: 0 | R41: =SUM(P41:Q41) -> 0 | S41: 0 | T41: 0 | U41: =SUM(S41:T41) -> 0
A44: No. | B44: ELEMEN DATA | D44: KORBAFO | G44: NDAO | J44: OELABA | M44: OELE | P44: SONIMANU | S44: SOTIMORI
...

Sheet JUNI
A2: LAPORAN LABORATORIUM
A3: DI PUSKESMAS KABUPATEN ROTE NDAO
A4: JUNI 2026
A6: No. | B6: ELEMEN DATA | D6: BAA | G6: BATUTUA | J6: BUSALANGGA | M6: DELHA | P6: EAHUN | S6: FEAPOPI
D7: L | E7: P | F7: TOTAL | G7: L | H7: P | I7: TOTAL | J7: L | K7: P | L7: TOTAL | M7: L | N7: P | O7: TOTAL | P7: L | Q7: P | R7: TOTAL | S7: L | T7: P | U7: TOTAL
A8: 1 | B8: Total Kunjungan Laboratorium | D8: =D9+D18 -> 0 | E8: =E9+E18 -> 0 | F8: =F9+F18 -> 0 | G8: =G9+G18 -> 124 | H8: =H9+H18 -> 491 | I8: =I9+I18 -> 615 | J8: =J9+J18 -> 49 | K8: =K9+K18 -> 368 | ... U8: =U9+U18 -> 0
A9: 2 | B9: Peminta Tes Laboratorium | D9: =SUM(D10:D17) -> 0 | E9: =SUM(E10:E17) -> 0 | F9: =SUM(F10:F17) -> 0 | G9: =SUM(G10:G17) -> 51 | H9: =SUM(H10:H17) -> 115 | I9: =SUM(I10:I17) -> 166 | J9: =SUM(J10:J17) -> 0 | K9: =SUM(K10:K17) -> 0 | ... U9: =SUM(U10:U17) -> 0
B10: a. | C10: Poli umum | F10: =SUM(D10:E10) -> 0 | G10: 46 | H10: 61 | I10: =SUM(G10:H10) -> 107 | L10: =SUM(J10:K10) -> 0 | M10: 37 | N10: 72 | O10: =SUM(M10:N10) -> 109 | R10: =SUM(P10:Q10) -> 0 | U10: =SUM(S10:T10) -> 0
B11: b. | C11: KIA / KB | F11: =SUM(D11:E11) -> 0 | G11: 0 | H11: 46 | I11: =SUM(G11:H11) -> 46 | J11: 0 | L11: =SUM(J11:K11) -> 0 | M11: 0 | N11: 27 | O11: =SUM(M11:N11) -> 27 | R11: =SUM(P11:Q11) -> 0 | U11: =SUM(S11:T11) -> 0
B12: c. | C12: Rawat inap | F12: =SUM(D12:E12) -> 0 | G12: 0 | H12: 0 | I12: =SUM(G12:H12) -> 0 | L12: =SUM(J12:K12) -> 0 | M12: 0 | N12: 0 | O12: =SUM(M12:N12) -> 0 | R12: =SUM(P12:Q12) -> 0 | U12: =SUM(S12:T12) -> 0
B13: d. | C13: Unit gawat darurat | F13: =SUM(D13:E13) -> 0 | G13: 5 | H13: 0 | I13: =SUM(G13:H13) -> 5 | L13: =SUM(J13:K13) -> 0 | M13: 2 | N13: 11 | O13: =SUM(M13:N13) -> 13 | R13: =SUM(P13:Q13) -> 0 | U13: =SUM(S13:T13) -> 0
B14: e. | C14: MTBS | F14: =SUM(D14:E14) -> 0 | G14: 0 | H14: 3 | I14: =SUM(G14:H14) -> 3 | L14: =SUM(J14:K14) -> 0 | M14: 4 | N14: 4 | O14: =SUM(M14:N14) -> 8 | R14: =SUM(P14:Q14) -> 0 | U14: =SUM(S14:T14) -> 0
B15: f. | C15: Poli Gigi | F15: =SUM(D15:E15) -> 0 | G15: 0 | H15: 0 | I15: =SUM(G15:H15) -> 0 | L15: =SUM(J15:K15) -> 0 | M15: 0 | N15: 0 | O15: =SUM(M15:N15) -> 0 | R15: =SUM(P15:Q15) -> 0 | U15: =SUM(S15:T15) -> 0
B16: g. | C16: PONED | F16: =SUM(D16:E16) -> 0 | G16: 0 | H16: 5 | I16: =SUM(G16:H16) -> 5 | L16: =SUM(J16:K16) -> 0 | M16: 6 | N16: 20 | O16: =SUM(M16:N16) -> 26 | R16: =SUM(P16:Q16) -> 0 | U16: =SUM(S16:T16) -> 0
B17: h. | C17: Pustu | F17: =SUM(D17:E17) -> 0 | G17: 0 | H17: 0 | I17: =SUM(G17:H17) -> 0 | L17: =SUM(J17:K17) -> 0 | M17: 2 | N17: 8 | O17: =SUM(M17:N17) -> 10 | R17: =SUM(P17:Q17) -> 0 | U17: =SUM(S17:T17) -> 0
A18: 3 | B18: Jumlah Pemeriksaan Laboratorium | D18: =SUM(D19:D41) -> 0 | E18: =SUM(E19:E41) -> 0 | F18: =SUM(F19:F41) -> 0 | G18: =SUM(G19:G41) -> 73 | H18: =SUM(H19:H41) -> 376 | I18: =SUM(I19:I41) -> 449 | J18: =SUM(J19:J41) -> 49 | K18: =SUM(K19:K41) -> 368 | ... U18: =SUM(U19:U41) -> 0
B19: a. | C19: Golongan darah | F19: =SUM(D19:E19) -> 0 | G19: 1 | H19: 39 | I19: =SUM(G19:H19) -> 40 | J19: 1 | K19: 13 | L19: =SUM(J19:K19) -> 14 | M19: 3 | N19: 11 | O19: =SUM(M19:N19) -> 14 | R19: =SUM(P19:Q19) -> 0 | U19: =SUM(S19:T19) -> 0
B20: b. | C20: Hb | F20: =SUM(D20:E20) -> 0 | G20: 1 | H20: 45 | I20: =SUM(G20:H20) -> 46 | J20: 0 | K20: 38 | L20: =SUM(J20:K20) -> 38 | M20: 5 | N20: 56 | O20: =SUM(M20:N20) -> 61 | R20: =SUM(P20:Q20) -> 0 | U20: =SUM(S20:T20) -> 0
B21: c. | C21: Leukosit | F21: =SUM(D21:E21) -> 0 | G21: 0 | H21: 0 | I21: =SUM(G21:H21) -> 0 | L21: =SUM(J21:K21) -> 0 | M21: 0 | N21: 0 | O21: =SUM(M21:N21) -> 0 | R21: =SUM(P21:Q21) -> 0 | U21: =SUM(S21:T21) -> 0
B22: d. | C22: Eritrosit | F22: =SUM(D22:E22) -> 0 | G22: 0 | H22: 0 | I22: =SUM(G22:H22) -> 0 | L22: =SUM(J22:K22) -> 0 | M22: 0 | N22: 0 | O22: =SUM(M22:N22) -> 0 | R22: =SUM(P22:Q22) -> 0 | U22: =SUM(S22:T22) -> 0
B23: e. | C23: HCT | F23: =SUM(D23:E23) -> 0 | G23: 0 | H23: 0 | I23: =SUM(G23:H23) -> 0 | J23: 0 | K23: 38 | L23: =SUM(J23:K23) -> 38 | M23: 0 | N23: 0 | O23: =SUM(M23:N23) -> 0 | R23: =SUM(P23:Q23) -> 0 | U23: =SUM(S23:T23) -> 0
B24: f. | C24: Glukosa Post pandiel ( 2 jam PP ) | F24: =SUM(D24:E24) -> 0 | G24: 0 | H24: 1 | I24: =SUM(G24:H24) -> 1 | L24: =SUM(J24:K24) -> 0 | M24: 2 | N24: 0 | O24: =SUM(M24:N24) -> 2 | R24: =SUM(P24:Q24) -> 0 | U24: =SUM(S24:T24) -> 0
B25: g. | C25: Gulukosa Urine | F25: =SUM(D25:E25) -> 0 | G25: 0 | H25: 18 | I25: =SUM(G25:H25) -> 18 | L25: =SUM(J25:K25) -> 0 | M25: 0 | N25: 0 | O25: =SUM(M25:N25) -> 0 | R25: =SUM(P25:Q25) -> 0 | U25: =SUM(S25:T25) -> 0
B26: h. | C26: Asam Urat | F26: =SUM(D26:E26) -> 0 | G26: 16 | H26: 24 | I26: =SUM(G26:H26) -> 40 | J26: 0 | K26: 38 | L26: =SUM(J26:K26) -> 38 | M26: 18 | N26: 27 | O26: =SUM(M26:N26) -> 45 | R26: =SUM(P26:Q26) -> 0 | U26: =SUM(S26:T26) -> 0
B27: i. | C27: Gula darah sewaktu | F27: =SUM(D27:E27) -> 0 | G27: 16 | H27: 54 | I27: =SUM(G27:H27) -> 70 | J27: 15 | K27: 56 | L27: =SUM(J27:K27) -> 71 | M27: 33 | N27: 102 | O27: =SUM(M27:N27) -> 135 | R27: =SUM(P27:Q27) -> 0 | U27: =SUM(S27:T27) -> 0
B28: j. | C28: Gula darah puasa | F28: =SUM(D28:E28) -> 0 | G28: 13 | H28: 29 | I28: =SUM(G28:H28) -> 42 | J28: 8 | K28: 29 | L28: =SUM(J28:K28) -> 37 | M28: 2 | N28: 2 | O28: =SUM(M28:N28) -> 4 | R28: =SUM(P28:Q28) -> 0 | U28: =SUM(S28:T28) -> 0
B29: k. | C29: Urin Acid | F29: =SUM(D29:E29) -> 0 | G29: 0 | H29: 0 | I29: =SUM(G29:H29) -> 0 | L29: =SUM(J29:K29) -> 0 | M29: 0 | N29: 0 | O29: =SUM(M29:N29) -> 0 | R29: =SUM(P29:Q29) -> 0 | U29: =SUM(S29:T29) -> 0
B30: l. | C30: Cholestrol | F30: =SUM(D30:E30) -> 0 | G30: 20 | H30: 37 | I30: =SUM(G30:H30) -> 57 | J30: 5 | K30: 13 | L30: =SUM(J30:K30) -> 18 | M30: 16 | N30: 22 | O30: =SUM(M30:N30) -> 38 | R30: =SUM(P30:Q30) -> 0 | U30: =SUM(S30:T30) -> 0
B31: m. | C31: Protein Urine | F31: =SUM(D31:E31) -> 0 | G31: 0 | H31: 18 | I31: =SUM(G31:H31) -> 18 | L31: =SUM(J31:K31) -> 0 | M31: 0 | N31: 0 | O31: =SUM(M31:N31) -> 0 | R31: =SUM(P31:Q31) -> 0 | U31: =SUM(S31:T31) -> 0
B32: n. | C32: HIV | F32: =SUM(D32:E32) -> 0 | G32: 2 | H32: 30 | I32: =SUM(G32:H32) -> 32 | J32: 18 | K32: 57 | L32: =SUM(J32:K32) -> 75 | M32: 0 | N32: 14 | O32: =SUM(M32:N32) -> 14 | R32: =SUM(P32:Q32) -> 0 | U32: =SUM(S32:T32) -> 0
B33: o. | C33: SYPHILIS | F33: =SUM(D33:E33) -> 0 | G33: 1 | H33: 30 | I33: =SUM(G33:H33) -> 31 | J33: 1 | K33: 56 | L33: =SUM(J33:K33) -> 57 | M33: 0 | N33: 13 | O33: =SUM(M33:N33) -> 13 | R33: =SUM(P33:Q33) -> 0 | U33: =SUM(S33:T33) -> 0
B34: p. | C34: HBSAg | F34: =SUM(D34:E34) -> 0 | G34: 3 | H34: 30 | I34: =SUM(G34:H34) -> 33 | J34: 1 | K34: 30 | L34: =SUM(J34:K34) -> 31 | M34: 3 | N34: 16 | O34: =SUM(M34:N34) -> 19 | R34: =SUM(P34:Q34) -> 0 | U34: =SUM(S34:T34) -> 0
B35: q. | C35: Malaria P.V (Jika positip isi jenis plasmodiumnya) | F35: =SUM(D35:E35) -> 0 | G35: 0 | H35: 0 | I35: =SUM(G35:H35) -> 0 | L35: =SUM(J35:K35) -> 0 | M35: 2 | N35: 21 | O35: =SUM(M35:N35) -> 23 | R35: =SUM(P35:Q35) -> 0 | U35: =SUM(S35:T35) -> 0
B36: r. | C36: Widal | F36: =SUM(D36:E36) -> 0 | G36: 0 | H36: 0 | I36: =SUM(G36:H36) -> 0 | L36: =SUM(J36:K36) -> 0 | M36: 0 | N36: 0 | O36: =SUM(M36:N36) -> 0 | R36: =SUM(P36:Q36) -> 0 | U36: =SUM(S36:T36) -> 0
B37: s. | C37: Sputum BTA | F37: =SUM(D37:E37) -> 0 | G37: 0 | H37: 0 | I37: =SUM(G37:H37) -> 0 | L37: =SUM(J37:K37) -> 0 | M37: 0 | N37: 0 | O37: =SUM(M37:N37) -> 0 | R37: =SUM(P37:Q37) -> 0 | U37: =SUM(S37:T37) -> 0
B38: t. | C38: Test Kehamilan | F38: =SUM(D38:E38) -> 0 | G38: 0 | H38: 21 | I38: =SUM(G38:H38) -> 21 | L38: =SUM(J38:K38) -> 0 | M38: 0 | N38: 13 | O38: =SUM(M38:N38) -> 13 | R38: =SUM(P38:Q38) -> 0 | U38: =SUM(S38:T38) -> 0
B39: u. | C39: Tinja | F39: =SUM(D39:E39) -> 0 | G39: 0 | H39: 0 | I39: =SUM(G39:H39) -> 0 | L39: =SUM(J39:K39) -> 0 | M39: 0 | N39: 0 | O39: =SUM(M39:N39) -> 0 | R39: =SUM(P39:Q39) -> 0 | U39: =SUM(S39:T39) -> 0
B40: v. | C40: Urine Lengkap | F40: =SUM(D40:E40) -> 0 | G40: 0 | H40: 0 | I40: =SUM(G40:H40) -> 0 | L40: =SUM(J40:K40) -> 0 | M40: 4 | N40: 19 | O40: =SUM(M40:N40) -> 23 | R40: =SUM(P40:Q40) -> 0 | U40: =SUM(S40:T40) -> 0
B41: w. | C41: Urine Sedimen | F41: =SUM(D41:E41) -> 0 | G41: 0 | H41: 0 | I41: =SUM(G41:H41) -> 0 | L41: =SUM(J41:K41) -> 0 | M41: 0 | N41: 0 | O41: =SUM(M41:N41) -> 0 | R41: =SUM(P41:Q41) -> 0 | U41: =SUM(S41:T41) -> 0
A44: No. | B44: ELEMEN DATA | D44: KORBAFO | G44: NDAO | J44: OELABA | M44: OELE | P44: SONIMANU | S44: SOTIMORI
...

Sheet JULI
A2: LAPORAN LABORATORIUM
A3: DI PUSKESMAS KABUPATEN ROTE NDAO
A4: JULI 2026
A6: No. | B6: ELEMEN DATA | D6: BAA | G6: BATUTUA | J6: BUSALANGGA | M6: DELHA | P6: EAHUN | S6: FEAPOPI
D7: L | E7: P | F7: TOTAL | G7: L | H7: P | I7: TOTAL | J7: L | K7: P | L7: TOTAL | M7: L | N7: P | O7: TOTAL | P7: L | Q7: P | R7: TOTAL | S7: L | T7: P | U7: TOTAL
A8: 1 | B8: Total Kunjungan Laboratorium | D8: =D9+D18 -> 0 | E8: =E9+E18 -> 0 | F8: =F9+F18 -> 0 | G8: =G9+G18 -> 0 | H8: =H9+H18 -> 0 | I8: =I9+I18 -> 0 | J8: =J9+J18 -> 0 | K8: =K9+K18 -> 0 | ... U8: =U9+U18 -> 0
A9: 2 | B9: Peminta Tes Laboratorium | D9: =SUM(D10:D17) -> 0 | E9: =SUM(E10:E17) -> 0 | F9: =SUM(F10:F17) -> 0 | G9: =SUM(G10:G17) -> 0 | H9: =SUM(H10:H17) -> 0 | I9: =SUM(I10:I17) -> 0 | J9: =SUM(J10:J17) -> 0 | K9: =SUM(K10:K17) -> 0 | ... U9: =SUM(U10:U17) -> 0
B10: a. | C10: Poli umum | F10: =SUM(D10:E10) -> 0 | I10: =SUM(G10:H10) -> 0 | L10: =SUM(J10:K10) -> 0 | O10: =SUM(M10:N10) -> 0 | R10: =SUM(P10:Q10) -> 0 | U10: =SUM(S10:T10) -> 0
B11: b. | C11: KIA / KB | F11: =SUM(D11:E11) -> 0 | I11: =SUM(G11:H11) -> 0 | L11: =SUM(J11:K11) -> 0 | O11: =SUM(M11:N11) -> 0 | R11: =SUM(P11:Q11) -> 0 | U11: =SUM(S11:T11) -> 0
B12: c. | C12: Rawat inap | F12: =SUM(D12:E12) -> 0 | I12: =SUM(G12:H12) -> 0 | L12: =SUM(J12:K12) -> 0 | O12: =SUM(M12:N12) -> 0 | R12: =SUM(P12:Q12) -> 0 | U12: =SUM(S12:T12) -> 0
B13: d. | C13: Unit gawat darurat | F13: =SUM(D13:E13) -> 0 | I13: =SUM(G13:H13) -> 0 | L13: =SUM(J13:K13) -> 0 | O13: =SUM(M13:N13) -> 0 | R13: =SUM(P13:Q13) -> 0 | U13: =SUM(S13:T13) -> 0
