Workbook

Sheet BAA
A2: LAPORAN RUJUKAN
A3: DI PUSKESMAS BAA
A4: TAHUN 2026
A6: No. | B6: NAMA FASKES | C6: JANUARI | J6: FEBRUARI | Q6: MARET | X6: APRIL
C7: UMUM | E7: BPJS/KIS | G7: SKTM | I7: TOTAL | J7: UMUM | L7: BPJS/KIS | N7: SKTM | P7: TOTAL | Q7: UMUM | S7: BPJS/KIS | U7: SKTM | W7: TOTAL | X7: UMUM | Z7: BPJS/KIS | AB7: SKTM | AD7: TOTAL
C8: L | D8: P | E8: L | F8: P | G8: L | H8: P | J8: L | K8: P | L8: L | M8: P | N8: L | O8: P | Q8: L | R8: P | S8: L | T8: P | U8: L | V8: P | X8: L | Y8: P | Z8: L | AA8: P | AB8: L | AC8: P
A9: 1 | B9: RSUD KAB. ROTE NDAO | D9: 3 | E9: 37 | F9: 56 | I9: =SUM(C9:H9) -> 96 | J9: 2 | K9: 4 | L9: 18 | M9: 15 | P9: =SUM(J9:O9) -> 39 | Q9: 2 | R9: 4 | S9: 36 | T9: 34 | W9: =SUM(Q9:V9) -> 76 | X9: 2 | Y9: 2 | Z9: 30 | AA9: 39 | AD9: =SUM(X9:AC9) -> 73
A10: 2 | B10: RSUD PROF DR WZ JOHANNES | E10: 2 | F10: 3 | I10: =SUM(C10:H10) -> 5 | M10: 1 | P10: =SUM(J10:O10) -> 1 | S10: 1 | T10: 2 | W10: =SUM(Q10:V10) -> 3 | Z10: 1 | AA10: 5 | AD10: =SUM(X10:AC10) -> 6
A11: 3 | B11: RS BHAYANGKARA KUPANG | E11: 2 | I11: =SUM(C11:H11) -> 2 | L11: 1 | M11: 2 | P11: =SUM(J11:O11) -> 3 | S11: 1 | T11: 3 | W11: =SUM(Q11:V11) -> 4 | Z11: 2 | AA11: 1 | AD11: =SUM(X11:AC11) -> 3
A12: 4 | B12: RS KARTINI KUPANG | E12: 3 | F12: 5 | I12: =SUM(C12:H12) -> 8 | L12: 6 | M12: 6 | P12: =SUM(J12:O12) -> 12 | S12: 4 | T12: 12 | W12: =SUM(Q12:V12) -> 16 | Z12: 8 | AA12: 8 | AD12: =SUM(X12:AC12) -> 16
A13: 5 | B13: RS ST. CAROLUS BORROMEUS | F13: 3 | I13: =SUM(C13:H13) -> 3 | M13: 2 | P13: =SUM(J13:O13) -> 2 | T13: 1 | W13: =SUM(Q13:V13) -> 1 | AA13: 2 | AD13: =SUM(X13:AC13) -> 2
A14: 6 | B14: RSU LEONA KUPANG | E14: 9 | F14: 3 | I14: =SUM(C14:H14) -> 12 | L14: 6 | M14: 9 | P14: =SUM(J14:O14) -> 15 | S14: 4 | T14: 8 | W14: =SUM(Q14:V14) -> 12 | Z14: 6 | AA14: 9 | AD14: =SUM(X14:AC14) -> 15
A15: 7 | B15: RSU SILOAM KUPANG | E15: 4 | F15: 6 | I15: =SUM(C15:H15) -> 10 | L15: 10 | M15: 5 | P15: =SUM(J15:O15) -> 15 | S15: 6 | T15: 7 | W15: =SUM(Q15:V15) -> 13 | Z15: 5 | AA15: 2 | AD15: =SUM(X15:AC15) -> 7
A16: 8 | B16: RUMAH SAKIT TK. III WIRASAKTI | F16: 2 | I16: =SUM(C16:H16) -> 2 | L16: 1 | M16: 4 | P16: =SUM(J16:O16) -> 5 | T16: 3 | W16: =SUM(Q16:V16) -> 3 | AD16: =SUM(X16:AC16) -> 0
A17: 9 | B17: RSJ NAIMATA | I17: =SUM(C17:H17) -> 0 | L17: 2 | M17: 1 | P17: =SUM(J17:O17) -> 3 | S17: 1 | W17: =SUM(Q17:V17) -> 1 | Z17: 2 | AD17: =SUM(X17:AC17) -> 2
A18: 10 | B18: RS MAMAMI | F18: 2 | I18: =SUM(C18:H18) -> 2 | M18: 1 | P18: =SUM(J18:O18) -> 1 | S18: 2 | T18: 1 | W18: =SUM(Q18:V18) -> 3 | Z18: 1 | AA18: 2 | AD18: =SUM(X18:AC18) -> 3
A19: 11 | B19: RSUD S.K. LERIK | E19: 1 | I19: =SUM(C19:H19) -> 1 | L19: 1 | P19: =SUM(J19:O19) -> 1 | T19: 2 | W19: =SUM(Q19:V19) -> 2 | Z19: 2 | AA19: 1 | AD19: =SUM(X19:AC19) -> 3
A20: 12 | B20: KU DEWANTA MENTAL JIWA HEALTH CARE | F20: 1 | I20: =SUM(C20:H20) -> 1 | P20: =SUM(J20:O20) -> 0 | W20: =SUM(Q20:V20) -> 0 | AA20: 2 | AD20: =SUM(X20:AC20) -> 2
A21: 13 | B21: RSIA DEDARI | I21: =SUM(C21:H21) -> 0 | M21: 9 | P21: =SUM(J21:O21) -> 9 | T21: 9 | W21: =SUM(Q21:V21) -> 9 | Z21: 2 | AA21: 8 | AD21: =SUM(X21:AC21) -> 10
A22: 14 | B22: RSAL SAMUEL J MOEDA | I22: =SUM(C22:H22) -> 0 | M22: 2 | P22: =SUM(J22:O22) -> 2 | W22: =SUM(Q22:V22) -> 0 | AD22: =SUM(X22:AC22) -> 0
A23: 15 | B23: RSUP Dr. BEN MBOI KUPANG | F23: 2 | I23: =SUM(C23:H23) -> 2 | L23: 6 | M23: 2 | P23: =SUM(J23:O23) -> 8 | S23: 1 | T23: 2 | W23: =SUM(Q23:V23) -> 3 | Z23: 5 | AA23: 5 | AD23: =SUM(X23:AC23) -> 10
A24: TOTAL | C24: =SUM(C9:C23) -> 0 | D24: =SUM(D9:D23) -> 3 | E24: =SUM(E9:E23) -> 58 | F24: =SUM(F9:F23) -> 83 | G24: =SUM(G9:G23) -> 0 | H24: =SUM(H9:H23) -> 0 | I24: =SUM(C24:H24) -> 144 | J24: =SUM(J9:J23) -> 2 | K24: =SUM(K9:K23) -> 4 | L24: =SUM(L9:L23) -> 51 | M24: =SUM(M9:M23) -> 59 | N24: =SUM(N9:N23) -> 0 | O24: =SUM(O9:O23) -> 0 | P24: =SUM(J24:O24) -> 116 | Q24: =SUM(Q9:Q23) -> 2 | R24: =SUM(R9:R23) -> 4 | S24: =SUM(S9:S23) -> 56 | T24: =SUM(T9:T23) -> 84 | U24: =SUM(U9:U23) -> 0 | V24: =SUM(V9:V23) -> 0 | W24: =SUM(Q24:V24) -> 146 | X24: =SUM(X9:X23) -> 2 | Y24: =SUM(Y9:Y23) -> 2 | Z24: =SUM(Z9:Z23) -> 64 | AA24: =SUM(AA9:AA23) -> 84 | AB24: =SUM(AB9:AB23) -> 0 | AC24: =SUM(AC9:AC23) -> 0 | AD24: =SUM(X24:AC24) -> 152
A29: No. | B29: NAMA FASKES | C29: MEI | J29: JUNI | Q29: JULI | X29: AGUSTUS
C30: UMUM | E30: BPJS/KIS | G30: SKTM | I30: TOTAL | J30: UMUM | L30: BPJS/KIS | N30: SKTM | P30: TOTAL | Q30: UMUM | S30: BPJS/KIS | U30: SKTM | W30: TOTAL | X30: UMUM | Z30: BPJS/KIS | AB30: SKTM | AD30: TOTAL
C31: L | D31: P | E31: L | F31: P | G31: L | H31: P | J31: L | K31: P | L31: L | M31: P | N31: L | O31: P | Q31: L | R31: P | S31: L | T31: P | U31: L | V31: P | X31: L | Y31: P | Z31: L | AA31: P | AB31: L | AC31: P
A32: 1 | B32: RSUD KAB. ROTE NDAO | I32: =SUM(C32:H32) -> 0 | P32: =SUM(J32:O32) -> 0 | W32: =SUM(Q32:V32) -> 0 | AD32: =SUM(X32:AC32) -> 0
A33: 2 | B33: RSUD PROF DR WZ JOHANNES | I33: =SUM(C33:H33) -> 0 | P33: =SUM(J33:O33) -> 0 | W33: =SUM(Q33:V33) -> 0 | AD33: =SUM(X33:AC33) -> 0
A34: 3 | B34: RS BHAYANGKARA KUPANG | I34: =SUM(C34:H34) -> 0 | P34: =SUM(J34:O34) -> 0 | W34: =SUM(Q34:V34) -> 0 | AD34: =SUM(X34:AC34) -> 0
A35: 4 | B35: RS KARTINI KUPANG | I35: =SUM(C35:H35) -> 0 | P35: =SUM(J35:O35) -> 0 | W35: =SUM(Q35:V35) -> 0 | AD35: =SUM(X35:AC35) -> 0
A36: 5 | B36: RS ST. CAROLUS BORROMEUS | I36: =SUM(C36:H36) -> 0 | P36: =SUM(J36:O36) -> 0 | W36: =SUM(Q36:V36) -> 0 | AD36: =SUM(X36:AC36) -> 0
A37: 6 | B37: RSU LEONA KUPANG | I37: =SUM(C37:H37) -> 0 | P37: =SUM(J37:O37) -> 0 | W37: =SUM(Q37:V37) -> 0 | AD37: =SUM(X37:AC37) -> 0
A38: 7 | B38: RSU SILOAM KUPANG | I38: =SUM(C38:H38) -> 0 | P38: =SUM(J38:O38) -> 0 | W38: =SUM(Q38:V38) -> 0 | AD38: =SUM(X38:AC38) -> 0
A39: 8 | B39: RUMAH SAKIT TK. III WIRASAKTI | I39: =SUM(C39:H39) -> 0 | P39: =SUM(J39:O39) -> 0 | W39: =SUM(Q39:V39) -> 0 | AD39: =SUM(X39:AC39) -> 0
A40: 9 | B40: RSJ NAIMATA | I40: =SUM(C40:H40) -> 0 | P40: =SUM(J40:O40) -> 0 | W40: =SUM(Q40:V40) -> 0 | AD40: =SUM(X40:AC40) -> 0
A41: 10 | B41: RS MAMAMI | I41: =SUM(C41:H41) -> 0 | P41: =SUM(J41:O41) -> 0 | W41: =SUM(Q41:V41) -> 0 | AD41: =SUM(X41:AC41) -> 0
A42: 11 | B42: RSUD S.K. LERIK | I42: =SUM(C42:H42) -> 0 | P42: =SUM(J42:O42) -> 0 | W42: =SUM(Q42:V42) -> 0 | AD42: =SUM(X42:AC42) -> 0
A43: 12 | B43: KU DEWANTA MENTAL JIWA HEALTH CARE | I43: =SUM(C43:H43) -> 0 | P43: =SUM(J43:O43) -> 0 | W43: =SUM(Q43:V43) -> 0 | AD43: =SUM(X43:AC43) -> 0
... A46: 15 | B46: RSUP Dr. BEN MBOI KUPANG | I46: =SUM(C46:H46) -> 0 | P46: =SUM(J46:O46) -> 0 | W46: =SUM(Q46:V46) -> 0 | AD46: =SUM(X46:AC46) -> 0
A47: TOTAL | C47: =SUM(C32:C46) -> 0 | D47: =SUM(D32:D46) -> 0 | E47: =SUM(E32:E46) -> 0 | F47: =SUM(F32:F46) -> 0 | G47: =SUM(G32:G46) -> 0 | H47: =SUM(H32:H46) -> 0 | I47: =SUM(C47:H47) -> 0 | J47: =SUM(J32:J46) -> 0 | K47: =SUM(K32:K46) -> 0 | L47: =SUM(L32:L46) -> 0 | M47: =SUM(M32:M46) -> 0 | N47: =SUM(N32:N46) -> 0 | O47: =SUM(O32:O46) -> 0 | P47: =SUM(J47:O47) -> 0 | Q47: =SUM(Q32:Q46) -> 0 | R47: =SUM(R32:R46) -> 0 | S47: =SUM(S32:S46) -> 0 | T47: =SUM(T32:T46) -> 0 | U47: =SUM(U32:U46) -> 0 | V47: =SUM(V32:V46) -> 0 | W47: =SUM(Q47:V47) -> 0 | X47: =SUM(X32:X46) -> 0 | Y47: =SUM(Y32:Y46) -> 0 | Z47: =SUM(Z32:Z46) -> 0 | AA47: =SUM(AA32:AA46) -> 0 | AB47: =SUM(AB32:AB46) -> 0 | AC47: =SUM(AC32:AC46) -> 0 | AD47: =SUM(X47:AC47) -> 0
A50: No. | B50: NAMA FASKES | C50: SEPTEMBER | J50: OKTOBER | Q50: NOVEMBER | X50: DESEMBER
...

Sheet BATUTUA
A2: LAPORAN RUJUKAN
A3: DI PUSKESMAS BATUTUA
A4: TAHUN 2026
A6: No. | B6: NAMA FASKES | C6: JANUARI | J6: FEBRUARI | Q6: MARET | X6: APRIL
C7: UMUM | E7: BPJS/KIS | G7: SKTM | I7: TOTAL | J7: UMUM | L7: BPJS/KIS | N7: SKTM | P7: TOTAL | Q7: UMUM | S7: BPJS/KIS | U7: SKTM | W7: TOTAL | X7: UMUM | Z7: BPJS/KIS | AB7: SKTM | AD7: TOTAL
C8: L | D8: P | E8: L | F8: P | G8: L | H8: P | J8: L | K8: P | L8: L | M8: P | N8: L | O8: P | Q8: L | R8: P | S8: L | T8: P | U8: L | V8: P | X8: L | Y8: P | Z8: L | AA8: P | AB8: L | AC8: P
A9: 1 | B9: RSUD KAB. ROTE NDAO | C9: 3 | D9: 3 | E9: 20 | F9: 25 | I9: =SUM(C9:H9) -> 51 | J9: 1 | K9: 4 | L9: 16 | M9: 17 | P9: =SUM(J9:O9) -> 38 | S9: 14 | T9: 23 | U9: 1 | W9: =SUM(Q9:V9) -> 38 | Z9: 10 | AA9: 18 | AD9: =SUM(X9:AC9) -> 28
A10: 2 | B10: RSUD PROF DR WZ JOHANNES | F10: 3 | I10: =SUM(C10:H10) -> 3 | L10: 2 | M10: 1 | P10: =SUM(J10:O10) -> 3 | S10: 1 | T10: 3 | W10: =SUM(Q10:V10) -> 4 | AA10: 2 | AD10: =SUM(X10:AC10) -> 2
A11: 3 | B11: RS BHAYANGKARA KUPANG | F11: 1 | I11: =SUM(C11:H11) -> 1 | M11: 1 | P11: =SUM(J11:O11) -> 1 | T11: 1 | W11: =SUM(Q11:V11) -> 1 | Z11: 1 | AD11: =SUM(X11:AC11) -> 1
A12: 4 | B12: RS KARTINI KUPANG | E12: 5 | F12: 6 | I12: =SUM(C12:H12) -> 11 | L12: 3 | M12: 2 | P12: =SUM(J12:O12) -> 5 | S12: 10 | T12: 9 | W12: =SUM(Q12:V12) -> 19 | Z12: 8 | AA12: 3 | AD12: =SUM(X12:AC12) -> 11
A13: 5 | B13: RS ST. CAROLUS BORROMEUS | E13: 1 | F13: 1 | I13: =SUM(C13:H13) -> 2 | P13: =SUM(J13:O13) -> 0 | W13: =SUM(Q13:V13) -> 0 | AA13: 1 | AD13: =SUM(X13:AC13) -> 1
A14: 6 | B14: RSU LEONA KUPANG | E14: 5 | F14: 5 | I14: =SUM(C14:H14) -> 10 | L14: 2 | M14: 16 | P14: =SUM(J14:O14) -> 18 | S14: 7 | T14: 21 | W14: =SUM(Q14:V14) -> 28 | Z14: 10 | AA14: 15 | AD14: =SUM(X14:AC14) -> 25
A15: 7 | B15: RSU SILOAM KUPANG | E15: 3 | F15: 3 | I15: =SUM(C15:H15) -> 6 | L15: 2 | M15: 3 | P15: =SUM(J15:O15) -> 5 | S15: 1 | T15: 2 | W15: =SUM(Q15:V15) -> 3 | Z15: 4 | AA15: 3 | AD15: =SUM(X15:AC15) -> 7
A16: 8 | B16: RUMAH SAKIT TK. III WIRASAKTI | E16: 1 | F16: 1 | I16: =SUM(C16:H16) -> 2 | M16: 1 | P16: =SUM(J16:O16) -> 1 | S16: 1 | T16: 1 | W16: =SUM(Q16:V16) -> 2 | Z16: 1 | AA16: 4 | AD16: =SUM(X16:AC16) -> 5
A17: 9 | B17: RSJ NAIMATA | I17: =SUM(C17:H17) -> 0 | M17: 1 | P17: =SUM(J17:O17) -> 1 | S17: 1 | T17: 1 | W17: =SUM(Q17:V17) -> 2 | AA17: 1 | AD17: =SUM(X17:AC17) -> 1
A18: 10 | B18: RS MAMAMI | I18: =SUM(C18:H18) -> 0 | P18: =SUM(J18:O18) -> 0 | W18: =SUM(Q18:V18) -> 0 | Z18: 1 | AD18: =SUM(X18:AC18) -> 1
A19: 11 | B19: RSUD S.K. LERIK | E19: 1 | F19: 1 | I19: =SUM(C19:H19) -> 2 | L19: 1 | P19: =SUM(J19:O19) -> 1 | S19: 2 | W19: =SUM(Q19:V19) -> 2 | AD19: =SUM(X19:AC19) -> 0
A20: 12 | B20: KU DEWANTA MENTAL JIWA HEALTH CARE | I20: =SUM(C20:H20) -> 0 | P20: =SUM(J20:O20) -> 0 | W20: =SUM(Q20:V20) -> 0 | AD20: =SUM(X20:AC20) -> 0
A21: 13 | B21: RSIA DEDARI | I21: =SUM(C21:H21) -> 0 | M21: 6 | P21: =SUM(J21:O21) -> 6 | T21: 5 | W21: =SUM(Q21:V21) -> 5 | AA21: 5 | AD21: =SUM(X21:AC21) -> 5
A22: 14 | B22: RSAL SAMUEL J MOEDA | I22: =SUM(C22:H22) -> 0 | P22: =SUM(J22:O22) -> 0 | W22: =SUM(Q22:V22) -> 0 | AD22: =SUM(X22:AC22) -> 0
A23: 15 | B23: RSUP Dr. BEN MBOI KUPANG | E23: 2 | I23: =SUM(C23:H23) -> 2 | M23: 1 | P23: =SUM(J23:O23) -> 1 | T23: 1 | U23: 1 | W23: =SUM(Q23:V23) -> 2 | Z23: 2 | AD23: =SUM(X23:AC23) -> 2
A24: TOTAL | C24: =SUM(C9:C23) -> 3 | D24: =SUM(D9:D23) -> 3 | E24: =SUM(E9:E23) -> 38 | F24: =SUM(F9:F23) -> 46 | G24: =SUM(G9:G23) -> 0 | H24: =SUM(H9:H23) -> 0 | I24: =SUM(C24:H24) -> 90 | J24: =SUM(J9:J23) -> 1 | K24: =SUM(K9:K23) -> 4 | L24: =SUM(L9:L23) -> 26 | M24: =SUM(M9:M23) -> 49 | N24: =SUM(N9:N23) -> 0 | O24: =SUM(O9:O23) -> 0 | P24: =SUM(J24:O24) -> 80 | Q24: =SUM(Q9:Q23) -> 0 | R24: =SUM(R9:R23) -> 0 | S24: =SUM(S9:S23) -> 37 | T24: =SUM(T9:T23) -> 67 | U24: =SUM(U9:U23) -> 2 | V24: =SUM(V9:V23) -> 0 | W24: =SUM(Q24:V24) -> 106 | X24: =SUM(X9:X23) -> 0 | Y24: =SUM(Y9:Y23) -> 0 | Z24: =SUM(Z9:Z23) -> 37 | AA24: =SUM(AA9:AA23) -> 52 | AB24: =SUM(AB9:AB23) -> 0 | AC24: =SUM(AC9:AC23) -> 0 | AD24: =SUM(X24:AC24) -> 89
A27: No. | B27: NAMA FASKES | C27: MEI | J27: JUNI | Q27: JULI | X27: AGUSTUS
C28: UMUM | E28: BPJS/KIS | G28: SKTM | I28: TOTAL | J28: UMUM | L28: BPJS/KIS | N28: SKTM | P28: TOTAL | Q28: UMUM | S28: BPJS/KIS | U28: SKTM | W28: TOTAL | X28: UMUM | Z28: BPJS/KIS | AB28: SKTM | AD28: TOTAL
C29: L | D29: P | E29: L | F29: P | G29: L | H29: P | J29: L | K29: P | L29: L | M29: P | N29: L | O29: P | Q29: L | R29: P | S29: L | T29: P | U29: L | V29: P | X29: L | Y29: P | Z29: L | AA29: P | AB29: L | AC29: P
A30: 1 | B30: RSUD KAB. ROTE NDAO | D30: 1 | E30: 13 | F30: 11 | I30: =SUM(C30:H30) -> 25 | L30: 22 | M30: 41 | O30: 1 | P30: =SUM(J30:O30) -> 64 | W30: =SUM(Q30:V30) -> 0 | AD30: =SUM(X30:AC30) -> 0
A31: 2 | B31: RSUD PROF DR WZ JOHANNES | E31: 4 | I31: =SUM(C31:H31) -> 4 | L31: 2 | M31: 3 | P31: =SUM(J31:O31) -> 5 | W31: =SUM(Q31:V31) -> 0 | AD31: =SUM(X31:AC31) -> 0
A32: 3 | B32: RS BHAYANGKARA KUPANG | F32: 1 | I32: =SUM(C32:H32) -> 1 | L32: 1 | P32: =SUM(J32:O32) -> 1 | W32: =SUM(Q32:V32) -> 0 | AD32: =SUM(X32:AC32) -> 0
A33: 4 | B33: RS KARTINI KUPANG | E33: 1 | F33: 6 | I33: =SUM(C33:H33) -> 7 | L33: 5 | M33: 6 | P33: =SUM(J33:O33) -> 11 | W33: =SUM(Q33:V33) -> 0 | AD33: =SUM(X33:AC33) -> 0
A34: 5 | B34: RS ST. CAROLUS BORROMEUS | F34: 1 | I34: =SUM(C34:H34) -> 1 | M34: 1 | P34: =SUM(J34:O34) -> 1 | W34: =SUM(Q34:V34) -> 0 | AD34: =SUM(X34:AC34) -> 0
A35: 6 | B35: RSU LEONA KUPANG | E35: 6 | F35: 7 | I35: =SUM(C35:H35) -> 13 | L35: 4 | M35: 4 | P35: =SUM(J35:O35) -> 8 | W35: =SUM(Q35:V35) -> 0 | AD35: =SUM(X35:AC35) -> 0
A36: 7 | B36: RSU SILOAM KUPANG | E36: 3 | F36: 3 | I36: =SUM(C36:H36) -> 6 | L36: 3 | M36: 3 | P36: =SUM(J36:O36) -> 6 | W36: =SUM(Q36:V36) -> 0 | AD36: =SUM(X36:AC36) -> 0
A37: 8 | B37: RUMAH SAKIT TK. III WIRASAKTI | I37: =SUM(C37:H37) -> 0 | M37: 1 | P37: =SUM(J37:O37) -> 1 | W37: =SUM(Q37:V37) -> 0 | AD37: =SUM(X37:AC37) -> 0
A38: 9 | B38: RSJ NAIMATA | F38: 1 | I38: =SUM(C38:H38) -> 1 | L38: 2 | P38: =SUM(J38:O38) -> 2 | W38: =SUM(Q38:V38) -> 0 | AD38: =SUM(X38:AC38) -> 0
A39: 10 | B39: RS MAMAMI | F39: 1 | I39: =SUM(C39:H39) -> 1 | M39: 1 | P39: =SUM(J39:O39) -> 1 | W39: =SUM(Q39:V39) -> 0 | AD39: =SUM(X39:AC39) -> 0
A40: 11 | B40: RSUD S.K. LERIK | F40: 1 | I40: =SUM(C40:H40) -> 1 | L40: 1 | P40: =SUM(J40:O40) -> 1 | W40: =SUM(Q40:V40) -> 0 | AD40: =SUM(X40:AC40) -> 0
A41: 12 | B41: KU DEWANTA MENTAL JIWA HEALTH CARE | I41: =SUM(C41:H41) -> 0 | M41: 1 | P41: =SUM(J41:O41) -> 1 | W41: =SUM(Q41:V41) -> 0 | AD41: =SUM(X41:AC41) -> 0
A42: 13 | B42: RSIA DEDARI | E42: 1 | F42: 3 | I42: =SUM(C42:H42) -> 4 | M42: 2 | P42: =SUM(J42:O42) -> 2 | W42: =SUM(Q42:V42) -> 0 | AD42: =SUM(X42:AC42) -> 0
A43: 14 | B43: RSAL SAMUEL J MOEDA | I43: =SUM(C43:H43) -> 0 | P43: =SUM(J43:O43) -> 0 | W43: =SUM(Q43:V43) -> 0 | AD43: =SUM(X43:AC43) -> 0
A44: 15 | B44: RSUP Dr. BEN MBOI KUPANG | E44: 2 | F44: 3 | I44: =SUM(C44:H44) -> 5 | L44: 1 | M44: 1 | P44: =SUM(J44:O44) -> 2 | W44: =SUM(Q44:V44) -> 0 | AD44: =SUM(X44:AC44) -> 0
...

Sheet BUSALANGGA
A2: LAPORAN RUJUKAN
A3: DI PUSKESMAS BUSALANGGA
A4: TAHUN 2026
A6: No. | B6: NAMA FASKES | C6: JANUARI | J6: FEBRUARI | Q6: MARET | X6: APRIL
C7: UMUM | E7: BPJS/KIS | G7: SKTM | I7: TOTAL | J7: UMUM | L7: BPJS/KIS | N7: SKTM | P7: TOTAL | Q7: UMUM | S7: BPJS/KIS | U7: SKTM | W7: TOTAL | X7: UMUM | Z7: BPJS/KIS | AB7: SKTM | AD7: TOTAL
C8: L | D8: P | E8: L | F8: P | G8: L | H8: P | J8: L | K8: P | L8: L | M8: P | N8: L | O8: P | Q8: L | R8: P | S8: L | T8: P | U8: L | V8: P | X8: L | Y8: P | Z8: L | AA8: P | AB8: L | AC8: P
A9: 1 | B9: RSUD KAB. ROTE NDAO | C9: 0 | D9: 6 | E9: 19 | F9: 38 | G9: 0 | H9: 0 | I9: =SUM(C9:H9) -> 63 | J9: 1 | K9: 1 | L9: 7 | M9: 7 | N9: 0 | O9: 0 | P9: =SUM(J9:O9) -> 16 | Q9: 1 | R9: 2 | S9: 13 | T9: 11 | U9: 0 | V9: 0 | W9: =SUM(Q9:V9) -> 27 | X9: 0 | Y9: 4 | Z9: 18 | AA9: 13 | AB9: 0 | AC9: 0 | AD9: =SUM(X9:AC9) -> 35
A10: 2 | B10: RSUD PROF DR WZ JOHANNES | C10: 0 | D10: 0 | E10: 1 | F10: 0 | G10: 0 | H10: 0 | I10: =SUM(C10:H10) -> 1 | J10: 0 | K10: 0 | L10: 0 | M10: 2 | N10: 0 | O10: 0 | P10: =SUM(J10:O10) -> 2 | Q10: 0 | R10: 0 | S10: 1 | T10: 0 | U10: 0 | V10: 0 | W10: =SUM(Q10:V10) -> 1 | X10: 0 | Y10: 0 | Z10: 0 | AA10: 3 | AB10: 0 | AC10: 0 | AD10: =SUM(X10:AC10) -> 3
A11: 3 | B11: RS BHAYANGKARA KUPANG | C11: 0 | D11: 0 | E11: 0 | F11: 0 | G11: 0 | H11: 0 | I11: =SUM(C11:H11) -> 0 | J11: 0 | K11: 0 | L11: 0 | M11: 0 | N11: 0 | O11: 0 | P11: =SUM(J11:O11) -> 0 | Q11: 0 | R11: 0 | S11: 0 | T11: 0 | U11: 0 | V11: 0 | W11: =SUM(Q11:V11) -> 0 | X11: 0 | Y11: 0 | Z11: 0 | AA11: 0 | AB11: 0 | AC11: 0 | AD11: =SUM(X11:AC11) -> 0
A12: 4 | B12: RS KARTINI KUPANG | C12: 0 | D12: 0 | E12: 1 | F12: 2 | G12: 0 | H12: 0 | I12: =SUM(C12:H12) -> 3 | J12: 0 | K12: 0 | L12: 2 | M12: 2 | N12: 0 | O12: 0 | P12: =SUM(J12:O12) -> 4 | Q12: 0 | R12: 0 | S12: 3 | T12: 6 | U12: 0 | V12: 0 | W12: =SUM(Q12:V12) -> 9 | X12: 0 | Y12: 0 | Z12: 3 | AA12: 7 | AB12: 0 | AC12: 0 | AD12: =SUM(X12:AC12) -> 10
A13: 5 | B13: RS ST. CAROLUS BORROMEUS | C13: 0 | D13: 0 | E13: 0 | F13: 0 | G13: 0 | H13: 0 | I13: =SUM(C13:H13) -> 0 | J13: 0 | K13: 0 | L13: 3 | M13: 0 | N13: 0 | O13: 0 | P13: =SUM(J13:O13) -> 3 | Q13: 0 | R13: 0 | S13: 1 | T13: 1 | U13: 0 | V13: 0 | W13: =SUM(Q13:V13) -> 2 | X13: 0 | Y13: 0 | Z13: 1 | AA13: 0 | AB13: 0 | AC13: 0 | AD13: =SUM(X13:AC13) -> 1
A14: 6 | B14: RSU LEONA KUPANG | C14: 0 | D14: 0 | E14: 2 | F14: 3 | G14: 0 | H14: 0 | I14: =SUM(C14:H14) -> 5 | J14: 0 | K14: 0 | L14: 4 | M14: 9 | N14: 0 | O14: 0 | P14: =SUM(J14:O14) -> 13 | Q14: 0 | R14: 0 | S14: 3 | T14: 5 | U14: 0 | V14: 0 | W14: =SUM(Q14:V14) -> 8 | X14: 0 | Y14: 0 | Z14: 4 | AA14: 6 | AB14: 0 | AC14: 0 | AD14: =SUM(X14:AC14) -> 10
A15: 7 | B15: RSU SILOAM KUPANG | C15: 0 | D15: 0 | E15: 1 | F15: 0 | G15: 0 | H15: 0 | I15: =SUM(C15:H15) -> 1 | J15: 0 | K15: 0 | L15: 1 | M15: 1 | N15: 0 | O15: 0 | P15: =SUM(J15:O15) -> 2 | Q15: 0 | R15: 0 | S15: 1 | T15: 0 | U15: 0 | V15: 0 | W15: =SUM(Q15:V15) -> 1 | X15: 0 | Y15: 0 | Z15: 1 | AA15: 6 | AB15: 0 | AC15: 0 | AD15: =SUM(X15:AC15) -> 7
A16: 8 | B16: RUMAH SAKIT TK. III WIRASAKTI | C16: 0 | D16: 0 | E16: 0 | F16: 0 | G16: 0 | H16: 0 | I16: =SUM(C16:H16) -> 0 | J16: 0 | K16: 0 | L16: 0 | M16: 0 | N16: 0 | O16: 0 | P16: =SUM(J16:O16) -> 0 | Q16: 0 | R16: 0 | S16: 0 | T16: 0 | U16: 0 | V16: 0 | W16: =SUM(Q16:V16) -> 0 | X16: 0 | Y16: 0 | Z16: 0 | AA16: 0 | AB16: 0 | AC16: 0 | AD16: =SUM(X16:AC16) -> 0
A17: 9 | B17: RSJ NAIMATA | C17: 0 | D17: 0 | E17: 0 | F17: 0 | G17: 0 | H17: 0 | I17: =SUM(C17:H17) -> 0 | J17: 0 | K17: 0 | L17: 0 | M17: 0 | N17: 0 | O17: 0 | P17: =SUM(J17:O17) -> 0 | Q17: 0 | R17: 0 | S17: 0 | T17: 0 | U17: 0 | V17: 0 | W17: =SUM(Q17:V17) -> 0 | X17: 0 | Y17: 0 | Z17: 0 | AA17: 0 | AB17: 0 | AC17: 0 | AD17: =SUM(X17:AC17) -> 0
A18: 10 | B18: RS MAMAMI | C18: 0 | D18: 0 | E18: 0 | F18: 0 | G18: 0 | H18: 0 | I18: =SUM(C18:H18) -> 0 | J18: 0 | K18: 0 | L18: 2 | M18: 1 | N18: 0 | O18: 0 | P18: =SUM(J18:O18) -> 3 | Q18: 0 | R18: 0 | S18: 2 | T18: 2 | U18: 0 | V18: 0 | W18: =SUM(Q18:V18) -> 4 | X18: 0 | Y18: 0 | Z18: 0 | AA18: 0 | AB18: 0 | AC18: 0 | AD18: =SUM(X18:AC18) -> 0
A19: 11 | B19: RSUD S.K. LERIK | C19: 0 | D19: 0 | E19: 0 | F19: 1 | G19: 0 | H19: 0 | I19: =SUM(C19:H19) -> 1 | J19: 0 | K19: 0 | L19: 0 | M19: 0 | N19: 0 | O19: 0 | P19: =SUM(J19:O19) -> 0 | Q19: 0 | R19: 0 | S19: 0 | T19: 1 | U19: 0 | V19: 0 | W19: =SUM(Q19:V19) -> 1 | X19: 0 | Y19: 0 | Z19: 0 | AA19: 0 | AB19: 0 | AC19: 0 | AD19: =SUM(X19:AC19) -> 0
A20: 12 | B20: KU DEWANTA MENTAL JIWA HEALTH CARE | C20: 0 | D20: 0 | E20: 0 | F20: 0 | G20: 0 | H20: 0 | I20: =SUM(C20:H20) -> 0 | J20: 0 | K20: 0 | L20: 0 | M20: 0 | N20: 0 | O20: 0 | P20: =SUM(J20:O20) -> 0 | Q20: 0 | R20: 0 | S20: 0 | T20: 0 | U20: 0 | V20: 0 | W20: =SUM(Q20:V20) -> 0 | X20: 0 | Y20: 0 | Z20: 0 | AA20: 0 | AB20: 0 | AC20: 0 | AD20: =SUM(X20:AC20) -> 0
... A23: 15 | B23: RSUP Dr. BEN MBOI KUPANG | C23: 0 | D23: 0 | E23: 0 | F23: 0 | G23: 0 | H23: 0 | I23: =SUM(C23:H23) -> 0 | J23: 0 | K23: 0 | L23: 0 | M23: 0 | N23: 0 | O23: 0 | P23: =SUM(J23:O23) -> 0 | Q23: 0 | R23: 0 | S23: 0 | T23: 0 | U23: 0 | V23: 0 | W23: =SUM(Q23:V23) -> 0 | X23: 0 | Y23: 0 | Z23: 0 | AA23: 0 | AB23: 0 | AC23: 0 | AD23: =SUM(X23:AC23) -> 0
A24: TOTAL | C24: =SUM(C9:C23) -> 0 | D24: =SUM(D9:D23) -> 6 | E24: =SUM(E9:E23) -> 24 | F24: =SUM(F9:F23) -> 44 | G24: =SUM(G9:G23) -> 0 | H24: =SUM(H9:H23) -> 0 | I24: =SUM(C24:H24) -> 74 | J24: =SUM(J9:J23) -> 1 | K24: =SUM(K9:K23) -> 1 | L24: =SUM(L9:L23) -> 19 | M24: =SUM(M9:M23) -> 27 | N24: =SUM(N9:N23) -> 0 | O24: =SUM(O9:O23) -> 0 | P24: =SUM(J24:O24) -> 48 | Q24: =SUM(Q9:Q23) -> 1 | R24: =SUM(R9:R23) -> 2 | S24: =SUM(S9:S23) -> 25 | T24: =SUM(T9:T23) -> 29 | U24: =SUM(U9:U23) -> 0 | V24: =SUM(V9:V23) -> 0 | W24: =SUM(Q24:V24) -> 57 | X24: =SUM(X9:X23) -> 0 | Y24: =SUM(Y9:Y23) -> 4 | Z24: =SUM(Z9:Z23) -> 28 | AA24: =SUM(AA9:AA23) -> 36 | AB24: =SUM(AB9:AB23) -> 0 | AC24: =SUM(AC9:AC23) -> 0 | AD24: =SUM(X24:AC24) -> 68
A27: No. | B27: NAMA FASKES | C27: MEI | J27: JUNI | Q27: JULI | X27: AGUSTUS
C28: UMUM | E28: BPJS/KIS | G28: SKTM | I28: TOTAL | J28: UMUM | L28: BPJS/KIS | N28: SKTM | P28: TOTAL | Q28: UMUM | S28: BPJS/KIS | U28: SKTM | W28: TOTAL | X28: UMUM | Z28: BPJS/KIS | AB28: SKTM | AD28: TOTAL
C29: L | D29: P | E29: L | F29: P | G29: L | H29: P | J29: L | K29: P | L29: L | M29: P | N29: L | O29: P | Q29: L | R29: P | S29: L | T29: P | U29: L | V29: P | X29: L | Y29: P | Z29: L | AA29: P | AB29: L | AC29: P
A30: 1 | B30: RSUD KAB. ROTE NDAO | D30: 4 | E30: 12 | F30: 13 | I30: =SUM(C30:H30) -> 29 | K30: 1 | L30: 10 | M30: 37 | P30: =SUM(J30:O30) -> 48 | W30: =SUM(Q30:V30) -> 0 | AD30: =SUM(X30:AC30) -> 0
A31: 2 | B31: RSUD PROF DR WZ JOHANNES | F31: 1 | I31: =SUM(C31:H31) -> 1 | L31: 0 | M31: 3 | P31: =SUM(J31:O31) -> 3 | W31: =SUM(Q31:V31) -> 0 | AD31: =SUM(X31:AC31) -> 0
A32: 3 | B32: RS BHAYANGKARA KUPANG | I32: =SUM(C32:H32) -> 0 | P32: =SUM(J32:O32) -> 0 | W32: =SUM(Q32:V32) -> 0 | AD32: =SUM(X32:AC32) -> 0
A33: 4 | B33: RS KARTINI KUPANG | E33: 1 | F33: 5 | I33: =SUM(C33:H33) -> 6 | L33: 1 | M33: 3 | P33: =SUM(J33:O33) -> 4 | W33: =SUM(Q33:V33) -> 0 | AD33: =SUM(X33:AC33) -> 0
A34: 5 | B34: RS ST. CAROLUS BORROMEUS | I34: =SUM(C34:H34) -> 0 | L34: 1 | M34: 0 | P34: =SUM(J34:O34) -> 1 | W34: =SUM(Q34:V34) -> 0 | AD34: =SUM(X34:AC34) -> 0
A35: 6 | B35: RSU LEONA KUPANG | E35: 2 | F35: 2 | I35: =SUM(C35:H35) -> 4 | L35: 6 | M35: 6 | P35: =SUM(J35:O35) -> 12 | W35: =SUM(Q35:V35) -> 0 | AD35: =SUM(X35:AC35) -> 0
A36: 7 | B36: RSU SILOAM KUPANG | E36: 3 | F36: 1 | I36: =SUM(C36:H36) -> 4 | L36: 2 | M36: 1 | P36: =SUM(J36:O36) -> 3 | W36: =SUM(Q36:V36) -> 0 | AD36: =SUM(X36:AC36) -> 0
A37: 8 | B37: RUMAH SAKIT TK. III WIRASAKTI | I37: =SUM(C37:H37) -> 0 | P37: =SUM(J37:O37) -> 0 | W37: =SUM(Q37:V37) -> 0 | AD37: =SUM(X37:AC37) -> 0
A38: 9 | B38: RSJ NAIMATA | I38: =SUM(C38:H38) -> 0 | L38: 0 | M38: 0 | P38: =SUM(J38:O38) -> 0 | W38: =SUM(Q38:V38) -> 0 | AD38: =SUM(X38:AC38) -> 0
A39: 10 | B39: RS MAMAMI | I39: =SUM(C39:H39) -> 0 | L39: 0 | M39: 0 | P39: =SUM(J39:O39) -> 0 | W39: =SUM(Q39:V39) -> 0 | AD39: =SUM(X39:AC39) -> 0
A40: 11 | B40: RSUD S.K. LERIK | E40: 1 | I40: =SUM(C40:H40) -> 1 | L40: 2 | M40: 1 | P40: =SUM(J40:O40) -> 3 | W40: =SUM(Q40:V40) -> 0 | AD40: =SUM(X40:AC40) -> 0
A41: 12 | B41: KU DEWANTA MENTAL JIWA HEALTH CARE | I41: =SUM(C41:H41) -> 0 | L41: 0 | M41: 1 | P41: =SUM(J41:O41) -> 1 | W41: =SUM(Q41:V41) -> 0 | AD41: =SUM(X41:AC41) -> 0
A42: 13 | B42: RSIA DEDARI | F42: 2 | I42: =SUM(C42:H42) -> 2 | L42: 0 | M42: 1 | P42: =SUM(J42:O42) -> 1 | W42: =SUM(Q42:V42) -> 0 | AD42: =SUM(X42:AC42) -> 0
A43: 14 | B43: RSAL SAMUEL J MOEDA | I43: =SUM(C43:H43) -> 0 | L43: 0 | M43: 0 | P43: =SUM(J43:O43) -> 0 | W43: =SUM(Q43:V43) -> 0 | AD43: =SUM(X43:AC43) -> 0
A44: 15 | B44: RSUP Dr. BEN MBOI KUPANG | I44: =SUM(C44:H44) -> 0 | P44: =SUM(J44:O44) -> 0 | W44: =SUM(Q44:V44) -> 0 | AD44: =SUM(X44:AC44) -> 0
A45: TOTAL | C45: =SUM(C30:C44) -> 0 | D45: =SUM(D30:D44) -> 4 | E45: =SUM(E30:E44) -> 19 | F45: =SUM(F30:F44) -> 24 | G45: =SUM(G30:G44) -> 0 | H45: =SUM(H30:H44) -> 0 | I45: =SUM(C45:H45) -> 47 | J45: =SUM(J30:J44) -> 0 | K45: =SUM(K30:K44) -> 1 | L45: =SUM(L30:L44) -> 22 | M45: =SUM(M30:M44) -> 53 | N45: =SUM(N30:N44) -> 0 | O45: =SUM(O30:O44) -> 0 | P45: =SUM(J45:O45) -> 76 | Q45: =SUM(Q30:Q44) -> 0 | R45: =SUM(R30:R44) -> 0 | S45: =SUM(S30:S44) -> 0 | T45: =SUM(T30:T44) -> 0 | U45: =SUM(U30:U44) -> 0 | V45: =SUM(V30:V44) -> 0 | W45: =SUM(Q45:V45) -> 0 | X45: =SUM(X30:X44) -> 0 | Y45: =SUM(Y30:Y44) -> 0 | Z45: =SUM(Z30:Z44) -> 0 | AA45: =SUM(AA30:AA44) -> 0 | AB45: =SUM(AB30:AB44) -> 0 | AC45: =SUM(AC30:AC44) -> 0 | AD45: =SUM(X45:AC45) -> 0
A48: No. | B48: NAMA FASKES | C48: SEPTEMBER | J48: OKTOBER | Q48: NOVEMBER | X48: DESEMBER
...

Sheet DELHA
A2: LAPORAN RUJUKAN
A3: DI PUSKESMAS DELHA
A4: TAHUN 2026
A6: No. | B6: NAMA FASKES | C6: JANUARI | J6: FEBRUARI | Q6: MARET | X6: APRIL
C7: UMUM | E7: BPJS/KIS | G7: SKTM | I7: TOTAL | J7: UMUM | L7: BPJS/KIS | N7: SKTM | P7: TOTAL | Q7: UMUM | S7: BPJS/KIS | U7: SKTM | W7: TOTAL | X7: UMUM | Z7: BPJS/KIS | AB7: SKTM | AD7: TOTAL
C8: L | D8: P | E8: L | F8: P | G8: L | H8: P | J8: L | K8: P | L8: L | M8: P | N8: L | O8: P | Q8: L | R8: P | S8: L | T8: P | U8: L | V8: P | X8: L | Y8: P | Z8: L | AA8: P | AB8: L | AC8: P
A9: 1 | B9: RSUD KAB. ROTE NDAO | E9: 2 | F9: 1 | I9: =SUM(C9:H9) -> 3 | M9: 1 | P9: =SUM(J9:O9) -> 1 | Q9: 1 | R9: 1 | W9: =SUM(Q9:V9) -> 2 | AD9: =SUM(X9:AC9) -> 0
A10: 2 | B10: RSUD PROF DR WZ JOHANNES | I10: =SUM(C10:H10) -> 0 | P10: =SUM(J10:O10) -> 0 | W10: =SUM(Q10:V10) -> 0 | AA10: 2 | AD10: =SUM(X10:AC10) -> 2
A11: 3 | B11: RS BHAYANGKARA KUPANG | I11: =SUM(C11:H11) -> 0 | P11: =SUM(J11:O11) -> 0 | T11: 1 | W11: =SUM(Q11:V11) -> 1 | AD11: =SUM(X11:AC11) -> 0
A12: 4 | B12: RS KARTINI KUPANG | E12: 0 | F12: 1 | I12: =SUM(C12:H12) -> 1 | L12: 1 | M12: 5 | P12: =SUM(J12:O12) -> 6 | S12: 3 | T12: 1 | W12: =SUM(Q12:V12) -> 4 | AD12: =SUM(X12:AC12) -> 0
A13: 5 | B13: RS ST. CAROLUS BORROMEUS | I13: =SUM(C13:H13) -> 0 | P13: =SUM(J13:O13) -> 0 | W13: =SUM(Q13:V13) -> 0 | AD13: =SUM(X13:AC13) -> 0
A14: 6 | B14: RSU LEONA KUPANG | E14: 0 | F14: 3 | I14: =SUM(C14:H14) -> 3 | L14: 1 | M14: 2 | P14: =SUM(J14:O14) -> 3 | S14: 2 | T14: 2 | W14: =SUM(Q14:V14) -> 4 | Z14: 1 | AA14: 5 | AD14: =SUM(X14:AC14) -> 6
A15: 7 | B15: RSU SILOAM KUPANG | E15: 1 | F15: 0 | I15: =SUM(C15:H15) -> 1 | P15: =SUM(J15:O15) -> 0 | T15: 3 | W15: =SUM(Q15:V15) -> 3 | Z15: 2 | AD15: =SUM(X15:AC15) -> 2
A16: 8 | B16: RUMAH SAKIT TK. III WIRASAKTI | E16: 0 | F16: 1 | I16: =SUM(C16:H16) -> 1 | L16: 1 | M16: 1 | P16: =SUM(J16:O16) -> 2 | W16: =SUM(Q16:V16) -> 0 | AD16: =SUM(X16:AC16) -> 0
A17: 9 | B17: RSJ NAIMATA | I17: =SUM(C17:H17) -> 0 | P17: =SUM(J17:O17) -> 0 | W17: =SUM(Q17:V17) -> 0 | AD17: =SUM(X17:AC17) -> 0
A18: 10 | B18: RS MAMAMI | I18: =SUM(C18:H18) -> 0 | M18: 2 | P18: =SUM(J18:O18) -> 2 | W18: =SUM(Q18:V18) -> 0 | AD18: =SUM(X18:AC18) -> 0
A19: 11 | B19: RSUD S.K. LERIK | E19: 1 | F19: 0 | I19: =SUM(C19:H19) -> 1 | P19: =SUM(J19:O19) -> 0 | W19: =SUM(Q19:V19) -> 0 | AD19: =SUM(X19:AC19) -> 0
A20: 12 | B20: KU DEWANTA MENTAL JIWA HEALTH CARE | I20: =SUM(C20:H20) -> 0 | P20: =SUM(J20:O20) -> 0 | W20: =SUM(Q20:V20) -> 0 | AD20: =SUM(X20:AC20) -> 0
A21: 13 | B21: RSIA DEDARI | I21: =SUM(C21:H21) -> 0 | M21: 1 | P21: =SUM(J21:O21) -> 1 | T21: 4 | W21: =SUM(Q21:V21) -> 4 | AA21: 2 | AD21: =SUM(X21:AC21) -> 2
A22: 14 | B22: RSAL SAMUEL J MOEDA | I22: =SUM(C22:H22) -> 0 | P22: =SUM(J22:O22) -> 0 | T22: 1 | W22: =SUM(Q22:V22) -> 1 | AD22: =SUM(X22:AC22) -> 0
A23: 15 | B23: RSUP Dr. BEN MBOI KUPANG | I23: =SUM(C23:H23) -> 0 | P23: =SUM(J23:O23) -> 0 | S23: 1 | W23: =SUM(Q23:V23) -> 1 | AD23: =SUM(X23:AC23) -> 0
A24: TOTAL | C24: =SUM(C9:C23) -> 0 | D24: =SUM(D9:D23) -> 0 | E24: =SUM(E9:E23) -> 4 | F24: =SUM(F9:F23) -> 6 | G24: =SUM(G9:G23) -> 0 | H24: =SUM(H9:H23) -> 0 | I24: =SUM(C24:H24) -> 10 | J24: =SUM(J9:J23) -> 0 | K24: =SUM(K9:K23) -> 0 | L24: =SUM(L9:L23) -> 3 | M24: =SUM(M9:M23) -> 12 | N24: =SUM(N9:N23) -> 0 | O24: =SUM(O9:O23) -> 0 | P24: =SUM(J24:O24) -> 15 | Q24: =SUM(Q9:Q23) -> 1 | R24: =SUM(R9:R23) -> 1 | S24: =SUM(S9:S23) -> 6 | T24: =SUM(T9:T23) -> 12 | U24: =SUM(U9:U23) -> 0 | V24: =SUM(V9:V23) -> 0 | W24: =SUM(Q24:V24) -> 20 | X24: =SUM(X9:X23) -> 0 | Y24: =SUM(Y9:Y23) -> 0 | Z24: =SUM(Z9:Z23) -> 3 | AA24: =SUM(AA9:AA23) -> 9 | AB24: =SUM(AB9:AB23) -> 0 | AC24: =SUM(AC9:AC23) -> 0 | AD24: =SUM(X24:AC24) -> 12
A27: No. | B27: NAMA FASKES | C27: MEI | J27: JUNI | Q27: JULI | X27: AGUSTUS
C28: UMUM | E28: BPJS/KIS | G28: SKTM | I28: TOTAL | J28: UMUM | L28: BPJS/KIS | N28: SKTM | P28: TOTAL | Q28: UMUM | S28: BPJS/KIS | U28: SKTM | W28: TOTAL | X28: UMUM | Z28: BPJS/KIS | AB28: SKTM | AD28: TOTAL
C29: L | D29: P | E29: L | F29: P | G29: L | H29: P | J29: L | K29: P | L29: L | M29: P | N29: L | O29: P | Q29: L | R29: P | S29: L | T29: P | U29: L | V29: P | X29: L | Y29: P | Z29: L | AA29: P | AB29: L | AC29: P
A30: 1 | B30: RSUD KAB. ROTE NDAO | E30: 1 | I30: =SUM(C30:H30) -> 1 | P30: =SUM(J30:O30) -> 0 | W30: =SUM(Q30:V30) -> 0 | AD30: =SUM(X30:AC30) -> 0
A31: 2 | B31: RSUD PROF DR WZ JOHANNES | I31: =SUM(C31:H31) -> 0 | P31: =SUM(J31:O31) -> 0 | W31: =SUM(Q31:V31) -> 0 | AD31: =SUM(X31:AC31) -> 0
A32: 3 | B32: RS BHAYANGKARA KUPANG | I32: =SUM(C32:H32) -> 0 | P32: =SUM(J32:O32) -> 0 | W32: =SUM(Q32:V32) -> 0 | AD32: =SUM(X32:AC32) -> 0
A33: 4 | B33: RS KARTINI KUPANG | E33: 1 | I33: =SUM(C33:H33) -> 1 | P33: =SUM(J33:O33) -> 0 | W33: =SUM(Q33:V33) -> 0 | AD33: =SUM(X33:AC33) -> 0
A34: 5 | B34: RS ST. CAROLUS BORROMEUS | I34: =SUM(C34:H34) -> 0 | P34: =SUM(J34:O34) -> 0 | W34: =SUM(Q34:V34) -> 0 | AD34: =SUM(X34:AC34) -> 0
A35: 6 | B35: RSU LEONA KUPANG | E35: 2 | F35: 2 | I35: =SUM(C35:H35) -> 4 | P35: =SUM(J35:O35) -> 0 | W35: =SUM(Q35:V35) -> 0 | AD35: =SUM(X35:AC35) -> 0
A36: 7 | B36: RSU SILOAM KUPANG | E36: 3 | I36: =SUM(C36:H36) -> 3 | P36: =SUM(J36:O36) -> 0 | W36: =SUM(Q36:V36) -> 0 | AD36: =SUM(X36:AC36) -> 0
A37: 8 | B37: RUMAH SAKIT TK. III WIRASAKTI | I37: =SUM(C37:H37) -> 0 | P37: =SUM(J37:O37) -> 0 | W37: =SUM(Q37:V37) -> 0 | AD37: =SUM(X37:AC37) -> 0
A38: 9 | B38: RSJ NAIMATA | I38: =SUM(C38:H38) -> 0 | P38: =SUM(J38:O38) -> 0 | W38: =SUM(Q38:V38) -> 0 | AD38: =SUM(X38:AC38) -> 0
A39: 10 | B39: RS MAMAMI | I39: =SUM(C39:H39) -> 0 | P39: =SUM(J39:O39) -> 0 | W39: =SUM(Q39:V39) -> 0 | AD39: =SUM(X39:AC39) -> 0
A40: 11 | B40: RSUD S.K. LERIK | I40: =SUM(C40:H40) -> 0 | P40: =SUM(J40:O40) -> 0 | W40: =SUM(Q40:V40) -> 0 | AD40: =SUM(X40:AC40) -> 0
A41: 12 | B41: KU DEWANTA MENTAL JIWA HEALTH CARE | I41: =SUM(C41:H41) -> 0 | P41: =SUM(J41:O41) -> 0 | W41: =SUM(Q41:V41) -> 0 | AD41: =SUM(X41:AC41) -> 0
A42: 13 | B42: RSIA DEDARI | I42: =SUM(C42:H42) -> 0 | P42: =SUM(J42:O42) -> 0 | W42: =SUM(Q42:V42) -> 0 | AD42: =SUM(X42:AC42) -> 0
A43: 14 | B43: RSAL SAMUEL J MOEDA | I43: =SUM(C43:H43) -> 0 | P43: =SUM(J43:O43) -> 0 | W43: =SUM(Q43:V43) -> 0 | AD43: =SUM(X43:AC43) -> 0
A44: 15 | B44: RSUP Dr. BEN MBOI KUPANG | I44: =SUM(C44:H44) -> 0 | P44: =SUM(J44:O44) -> 0 | W44: =SUM(Q44:V44) -> 0 | AD44: =SUM(X44:AC44) -> 0
...

Sheet EAHUN
A2: LAPORAN RUJUKAN
A3: DI PUSKESMAS EAHUN
A4: TAHUN 2026
A6: No. | B6: NAMA FASKES | C6: JANUARI | J6: FEBRUARI | Q6: MARET | X6: APRIL
C7: UMUM | E7: BPJS/KIS | G7: SKTM | I7: TOTAL | J7: UMUM | L7: BPJS/KIS | N7: SKTM | P7: 1 | Q7: UMUM | S7: BPJS/KIS | U7: SKTM | W7: TOTAL | X7: UMUM | Z7: BPJS/KIS | AB7: SKTM | AD7: TOTAL
C8: L | D8: P | E8: L | F8: P | G8: L | H8: P | J8: L | K8: P | L8: L | M8: P | N8: L | O8: P | Q8: L | R8: P | S8: L | T8: P | U8: L | V8: P | X8: L | Y8: P | Z8: L | AA8: P | AB8: L | AC8: P
A9: 1 | B9: RSUD KAB. ROTE NDAO | C9: 1 | D9: 1 | E9: 1 | F9: 1 | I9: =SUM(C9:H9) -> 4 | J9: 2 | L9: 2 | M9: 1 | P9: =SUM(J9:O9) -> 5 | Q9: 2 | R9: 1 | S9: 1 | W9: =SUM(Q9:V9) -> 4 | X9: 1 | Y9: 2 | AA9: 1 | AD9: =SUM(X9:AC9) -> 4
A10: 2 | B10: RSUD PROF DR WZ JOHANNES | F10: 1 | I10: =SUM(C10:H10) -> 1 | M10: 2 | P10: =SUM(J10:O10) -> 2 | T10: 1 | W10: =SUM(Q10:V10) -> 1 | AA10: 1 | AD10: =SUM(X10:AC10) -> 1
A11: 3 | B11: RS BHAYANGKARA KUPANG | E11: 1 | F11: 1 | I11: =SUM(C11:H11) -> 2 | L11: 1 | M11: 3 | P11: =SUM(J11:O11) -> 4 | S11: 1 | T11: 1 | W11: =SUM(Q11:V11) -> 2 | AD11: =SUM(X11:AC11) -> 0
A12: 4 | B12: RS KARTINI KUPANG | E12: 2 | F12: 3 | I12: =SUM(C12:H12) -> 5 | L12: 2 | P12: =SUM(J12:O12) -> 2 | S12: 3 | T12: 3 | W12: =SUM(Q12:V12) -> 6 | Z12: 2 | AA12: 2 | AD12: =SUM(X12:AC12) -> 4
A13: 5 | B13: RS ST. CAROLUS BORROMEUS | I13: =SUM(C13:H13) -> 0 | P13: =SUM(J13:O13) -> 0 | W13: =SUM(Q13:V13) -> 0 | AD13: =SUM(X13:AC13) -> 0
A14: 6 | B14: RSU LEONA KUPANG | E14: 3 | F14: 5 | I14: =SUM(C14:H14) -> 8 | L14: 3 | M14: 4 | P14: =SUM(J14:O14) -> 7 | S14: 2 | T14: 3 | W14: =SUM(Q14:V14) -> 5 | Z14: 5 | AA14: 5 | AD14: =SUM(X14:AC14) -> 10
A15: 7 | B15: RSU SILOAM KUPANG | F15: 1 | I15: =SUM(C15:H15) -> 1 | P15: =SUM(J15:O15) -> 0 | T15: 1 | W15: =SUM(Q15:V15) -> 1 | Z15: 1 | AD15: =SUM(X15:AC15) -> 1
A16: 8 | B16: RUMAH SAKIT TK. III WIRASAKTI | E16: 1 | F16: 1 | I16: =SUM(C16:H16) -> 2 | M16: 3 | P16: =SUM(J16:O16) -> 3 | S16: 1 | T16: 1 | W16: =SUM(Q16:V16) -> 2 | Z16: 3 | AA16: 2 | AD16: =SUM(X16:AC16) -> 5
A17: 9 | B17: RSJ NAIMATA | I17: =SUM(C17:H17) -> 0 | P17: =SUM(J17:O17) -> 0 | W17: =SUM(Q17:V17) -> 0 | Z17: 1 | AD17: =SUM(X17:AC17) -> 1
A18: 10 | B18: RS MAMAMI | I18: =SUM(C18:H18) -> 0 | L18: 1 | M18: 1 | P18: =SUM(J18:O18) -> 2 | S18: 1 | W18: =SUM(Q18:V18) -> 1 | AA18: 1 | AD18: =SUM(X18:AC18) -> 1
A19: 11 | B19: RSUD S.K. LERIK | F19: 2 | I19: =SUM(C19:H19) -> 2 | M19: 1 | P19: =SUM(J19:O19) -> 1 | W19: =SUM(Q19:V19) -> 0 | AA19: 1 | AD19: =SUM(X19:AC19) -> 1
A20: 12 | B20: KU DEWANTA MENTAL JIWA HEALTH CARE | I20: =SUM(C20:H20) -> 0 | P20: =SUM(J20:O20) -> 0 | W20: =SUM(Q20:V20) -> 0 | AD20: =SUM(X20:AC20) -> 0
A21: 13 | B21: RSIA DEDARI | E21: 1 | F21: 3 | I21: =SUM(C21:H21) -> 4 | K21: 1 | M21: 4 | P21: =SUM(J21:O21) -> 5 | T21: 2 | W21: =SUM(Q21:V21) -> 2 | AA21: 2 | AD21: =SUM(X21:AC21) -> 2
A22: 14 | B22: RSAL SAMUEL J MOEDA | I22: =SUM(C22:H22) -> 0 | P22: =SUM(J22:O22) -> 0 | S22: 1 | W22: =SUM(Q22:V22) -> 1 | AD22: =SUM(X22:AC22) -> 0
A23: 15 | B23: RSUP Dr. BEN MBOI KUPANG | I23: =SUM(C23:H23) -> 0 | P23: =SUM(J23:O23) -> 0 | W23: =SUM(Q23:V23) -> 0 | Z23: 1 | AD23: =SUM(X23:AC23) -> 1
A24: TOTAL | C24: =SUM(C9:C23) -> 1 | D24: =SUM(D9:D23) -> 1 | E24: =SUM(E9:E23) -> 9 | F24: =SUM(F9:F23) -> 18 | G24: =SUM(G9:G23) -> 0 | H24: =SUM(H9:H23) -> 0 | I24: =SUM(C24:H24) -> 29 | J24: =SUM(J9:J23) -> 2 | K24: =SUM(K9:K23) -> 1 | L24: =SUM(L9:L23) -> 9 | M24: =SUM(M9:M23) -> 19 | N24: =SUM(N9:N23) -> 0 | O24: =SUM(O9:O23) -> 0 | P24: =SUM(J24:O24) -> 31 | Q24: =SUM(Q9:Q23) -> 2 | R24: =SUM(R9:R23) -> 1 | S24: =SUM(S9:S23) -> 10 | T24: =SUM(T9:T23) -> 12 | U24: =SUM(U9:U23) -> 0 | V24: =SUM(V9:V23) -> 0 | W24: =SUM(Q24:V24) -> 25 | X24: =SUM(X9:X23) -> 1 | Y24: =SUM(Y9:Y23) -> 2 | Z24: =SUM(Z9:Z23) -> 13 | AA24: =SUM(AA9:AA23) -> 15 | AB24: =SUM(AB9:AB23) -> 0 | AC24: =SUM(AC9:AC23) -> 0 | AD24: =SUM(X24:AC24) -> 31
A27: No. | B27: NAMA FASKES | C27: MEI | J27: JUNI | Q27: JULI | X27: AGUSTUS
C28: UMUM | E28: BPJS/KIS | G28: SKTM | I28: TOTAL | J28: UMUM | L28: BPJS/KIS | N28: SKTM | P28: TOTAL | Q28: UMUM | S28: BPJS/KIS | U28: SKTM | W28: TOTAL | X28: UMUM | Z28: BPJS/KIS | AB28: SKTM | AD28: TOTAL
C29: L | D29: P | E29: L | F29: P | G29: L | H29: P | J29: L | K29: P | L29: L | M29: P | N29: L | O29: P | Q29: L | R29: P | S29: L | T29: P | U29: L | V29: P | X29: L | Y29: P | Z29: L | AA29: P | AB29: L | AC29: P
A30: 1 | B30: RSUD KAB. ROTE NDAO | I30: =SUM(C30:H30) -> 0 | P30: =SUM(J30:O30) -> 0 | W30: =SUM(Q30:V30) -> 0 | AD30: =SUM(X30:AC30) -> 0
A31: 2 | B31: RSUD PROF DR WZ JOHANNES | I31: =SUM(C31:H31) -> 0 | P31: =SUM(J31:O31) -> 0 | W31: =SUM(Q31:V31) -> 0 | AD31: =SUM(X31:AC31) -> 0
A32: 3 | B32: RS BHAYANGKARA KUPANG | I32: =SUM(C32:H32) -> 0 | P32: =SUM(J32:O32) -> 0 | W32: =SUM(Q32:V32) -> 0 | AD32: =SUM(X32:AC32) -> 0
A33: 4 | B33: RS KARTINI KUPANG | I33: =SUM(C33:H33) -> 0 | P33: =SUM(J33:O33) -> 0 | W33: =SUM(Q33:V33) -> 0 | AD33: =SUM(X33:AC33) -> 0
A34: 5 | B34: RS ST. CAROLUS BORROMEUS | I34: =SUM(C34:H34) -> 0 | P34: =SUM(J34:O34) -> 0 | W34: =SUM(Q34:V34) -> 0 | AD34: =SUM(X34:AC34) -> 0
A35: 6 | B35: RSU LEONA KUPANG | I35: =SUM(C35:H35) -> 0 | P35: =SUM(J35:O35) -> 0 | W35: =SUM(Q35:V35) -> 0 | AD35: =SUM(X35:AC35) -> 0
A36: 7 | B36: RSU SILOAM KUPANG | I36: =SUM(C36:H36) -> 0 | P36: =SUM(J36:O36) -> 0 | W36: =SUM(Q36:V36) -> 0 | AD36: =SUM(X36:AC36) -> 0
A37: 8 | B37: RUMAH SAKIT TK. III WIRASAKTI | I37: =SUM(C37:H37) -> 0 | P37: =SUM(J37:O37) -> 0 | W37: =SUM(Q37:V37) -> 0 | AD37: =SUM(X37:AC37) -> 0
A38: 9 | B38: RSJ NAIMATA | I38: =SUM(C38:H38) -> 0 | P38: =SUM(J38:O38) -> 0 | W38: =SUM(Q38:V38) -> 0 | AD38: =SUM(X38:AC38) -> 0
A39: 10 | B39: RS MAMAMI | I39: =SUM(C39:H39) -> 0 | P39: =SUM(J39:O39) -> 0 | W39: =SUM(Q39:V39) -> 0 | AD39: =SUM(X39:AC39) -> 0
A40: 11 | B40: RSUD S.K. LERIK | I40: =SUM(C40:H40) -> 0 | P40: =SUM(J40:O40) -> 0 | W40: =SUM(Q40:V40) -> 0 | AD40: =SUM(X40:AC40) -> 0
A41: 12 | B41: KU DEWANTA MENTAL JIWA HEALTH CARE | I41: =SUM(C41:H41) -> 0 | P41: =SUM(J41:O41) -> 0 | W41: =SUM(Q41:V41) -> 0 | AD41: =SUM(X41:AC41) -> 0
... A44: 15 | B44: RSUP Dr. BEN MBOI KUPANG | I44: =SUM(C44:H44) -> 0 | P44: =SUM(J44:O44) -> 0 | W44: =SUM(Q44:V44) -> 0 | AD44: =SUM(X44:AC44) -> 0
A45: TOTAL | C45: =SUM(C30:C44) -> 0 | D45: =SUM(D30:D44) -> 0 | E45: =SUM(E30:E44) -> 0 | F45: =SUM(F30:F44) -> 0 | G45: =SUM(G30:G44) -> 0 | H45: =SUM(H30:H44) -> 0 | I45: =SUM(C45:H45) -> 0 | J45: =SUM(J30:J44) -> 0 | K45: =SUM(K30:K44) -> 0 | L45: =SUM(L30:L44) -> 0 | M45: =SUM(M30:M44) -> 0 | N45: =SUM(N30:N44) -> 0 | O45: =SUM(O30:O44) -> 0 | P45: =SUM(J45:O45) -> 0 | Q45: =SUM(Q30:Q44) -> 0 | R45: =SUM(R30:R44) -> 0 | S45: =SUM(S30:S44) -> 0 | T45: =SUM(T30:T44) -> 0 | U45: =SUM(U30:U44) -> 0 | V45: =SUM(V30:V44) -> 0 | W45: =SUM(Q45:V45) -> 0 | X45: =SUM(X30:X44) -> 0 | Y45: =SUM(Y30:Y44) -> 0 | Z45: =SUM(Z30:Z44) -> 0 | AA45: =SUM(AA30:AA44) -> 0 | AB45: =SUM(AB30:AB44) -> 0 | AC45: =SUM(AC30:AC44) -> 0 | AD45: =SUM(X45:AC45) -> 0
A48: No. | B48: NAMA FASKES | C48: SEPTEMBER | J48: OKTOBER | Q48: NOVEMBER | X48: DESEMBER
...

Sheet FEAPOPI
A2: LAPORAN RUJUKAN
A3: DI PUSKESMAS FEAPOPI
A4: TAHUN 2026
A6: No. | B6: NAMA FASKES | C6: JANUARI | J6: FEBRUARI | Q6: MARET | X6: APRIL
C7: UMUM | E7: BPJS/KIS | G7: SKTM | I7: TOTAL | J7: UMUM | L7: BPJS/KIS | N7: SKTM | P7: TOTAL | Q7: UMUM | S7: BPJS/KIS | U7: SKTM | W7: TOTAL | X7: UMUM | Z7: BPJS/KIS | AB7: SKTM | AD7: TOTAL
C8: L | D8: P | E8: L | F8: P | G8: L | H8: P | J8: L | K8: P | L8: L | M8: P | N8: L | O8: P | Q8: L | R8: P | S8: L | T8: P | U8: L | V8: P | X8: L | Y8: P | Z8: L | AA8: P | AB8: L | AC8: P
A9: 1 | B9: RSUD KAB. ROTE NDAO | I9: =SUM(C9:H9) -> 0 | P9: =SUM(J9:O9) -> 0 | W9: =SUM(Q9:V9) -> 0 | AD9: =SUM(X9:AC9) -> 0
A10: 2 | B10: RSUD PROF DR WZ JOHANNES | I10: =SUM(C10:H10) -> 0 | P10: =SUM(J10:O10) -> 0 | W10: =SUM(Q10:V10) -> 0 | AD10: =SUM(X10:AC10) -> 0
A11: 3 | B11: RS BHAYANGKARA KUPANG | I11: =SUM(C11:H11) -> 0 | P11: =SUM(J11:O11) -> 0 | W11: =SUM(Q11:V11) -> 0 | AD11: =SUM(X11:AC11) -> 0
A12: 4 | B12: RS KARTINI KUPANG | I12: =SUM(C12:H12) -> 0 | P12: =SUM(J12:O12) -> 0 | W12: =SUM(Q12:V12) -> 0 | AD12: =SUM(X12:AC12) -> 0
A13: 5 | B13: RS ST. CAROLUS BORROMEUS | I13: =SUM(C13:H13) -> 0 | P13: =SUM(J13:O13) -> 0 | W13: =SUM(Q13:V13) -> 0 | AD13: =SUM(X13:AC13) -> 0
A14: 6 | B14: RSU LEONA KUPANG | I14: =SUM(C14:H14) -> 0 | P14: =SUM(J14:O14) -> 0 | W14: =SUM(Q14:V14) -> 0 | AD14: =SUM(X14:AC14) -> 0
A15: 7 | B15: RSU SILOAM KUPANG | I15: =SUM(C15:H15) -> 0 | P15: =SUM(J15:O15) -> 0 | W15: =SUM(Q15:V15) -> 0 | AD15: =SUM(X15:AC15) -> 0
A16: 8 | B16: RUMAH SAKIT TK. III WIRASAKTI | I16: =SUM(C16:H16) -> 0 | P16: =SUM(J16:O16) -> 0 | W16: =SUM(Q16:V16) -> 0 | AD16: =SUM(X16:AC16) -> 0
A17: 9 | B17: RSJ NAIMATA | I17: =SUM(C17:H17) -> 0 | P17: =SUM(J17:O17) -> 0 | W17: =SUM(Q17:V17) -> 0 | AD17: =SUM(X17:AC17) -> 0
A18: 10 | B18: RS MAMAMI | I18: =SUM(C18:H18) -> 0 | P18: =SUM(J18:O18) -> 0 | W18: =SUM(Q18:V18) -> 0 | AD18: =SUM(X18:AC18) -> 0
A19: 11 | B19: RSUD S.K. LERIK | I19: =SUM(C19:H19) -> 0 | P19: =SUM(J19:O19) -> 0 | W19: =SUM(Q19:V19) -> 0 | AD19: =SUM(X19:AC19) -> 0
A20: 12 | B20: KU DEWANTA MENTAL JIWA HEALTH CARE | I20: =SUM(C20:H20) -> 0 | P20: =SUM(J20:O20) -> 0 | W20: =SUM(Q20:V20) -> 0 | AD20: =SUM(X20:AC20) -> 0
... A23: 15 | B23: RSUP Dr. BEN MBOI KUPANG | I23: =SUM(C23:H23) -> 0 | P23: =SUM(J23:O23) -> 0 | W23: =SUM(Q23:V23) -> 0 | AD23: =SUM(X23:AC23) -> 0
A24: TOTAL | C24: =SUM(C9:C23) -> 0 | D24: =SUM(D9:D23) -> 0 | E24: =SUM(E9:E23) -> 0 | F24: =SUM(F9:F23) -> 0 | G24: =SUM(G9:G23) -> 0 | H24: =SUM(H9:H23) -> 0 | I24: =SUM(C24:H24) -> 0 | J24: =SUM(J9:J23) -> 0 | K24: =SUM(K9:K23) -> 0 | L24: =SUM(L9:L23) -> 0 | M24: =SUM(M9:M23) -> 0 | N24: =SUM(N9:N23) -> 0 | O24: =SUM(O9:O23) -> 0 | P24: =SUM(J24:O24) -> 0 | Q24: =SUM(Q9:Q23) -> 0 | R24: =SUM(R9:R23) -> 0 | S24: =SUM(S9:S23) -> 0 | T24: =SUM(T9:T23) -> 0 | U24: =SUM(U9:U23) -> 0 | V24: =SUM(V9:V23) -> 0 | W24: =SUM(Q24:V24) -> 0 | X24: =SUM(X9:X23) -> 0 | Y24: =SUM(Y9:Y23) -> 0 | Z24: =SUM(Z9:Z23) -> 0 | AA24: =SUM(AA9:AA23) -> 0 | AB24: =SUM(AB9:AB23) -> 0 | AC24: =SUM(AC9:AC23) -> 0 | AD24: =SUM(X24:AC24) -> 0
A27: No. | B27: NAMA FASKES | C27: MEI | J27: JUNI | Q27: JULI | X27: AGUSTUS
C28: UMUM | E28: BPJS/KIS | G28: SKTM | I28: TOTAL | J28: UMUM | L28: BPJS/KIS | N28: SKTM | P28: TOTAL | Q28: UMUM | S28: BPJS/KIS | U28: SKTM | W28: TOTAL | X28: UMUM | Z28: BPJS/KIS | AB28: SKTM | AD28: TOTAL
C29: L | D29: P | E29: L | F29: P | G29: L | H29: P | J29: L | K29: P | L29: L | M29: P | N29: L | O29: P | Q29: L | R29: P | S29: L | T29: P | U29: L | V29: P | X29: L | Y29: P | Z29: L | AA29: P | AB29: L | AC29: P
A30: 1 | B30: RSUD KAB. ROTE NDAO | I30: =SUM(C30:H30) -> 0 | P30: =SUM(J30:O30) -> 0 | W30: =SUM(Q30:V30) -> 0 | AD30: =SUM(X30:AC30) -> 0
A31: 2 | B31: RSUD PROF DR WZ JOHANNES | I31: =SUM(C31:H31) -> 0 | P31: =SUM(J31:O31) -> 0 | W31: =SUM(Q31:V31) -> 0 | AD31: =SUM(X31:AC31) -> 0
A32: 3 | B32: RS BHAYANGKARA KUPANG | I32: =SUM(C32:H32) -> 0 | P32: =SUM(J32:O32) -> 0 | W32: =SUM(Q32:V32) -> 0 | AD32: =SUM(X32:AC32) -> 0
A33: 4 | B33: RS KARTINI KUPANG | I33: =SUM(C33:H33) -> 0 | P33: =SUM(J33:O33) -> 0 | W33: =SUM(Q33:V33) -> 0 | AD33: =SUM(X33:AC33) -> 0
A34: 5 | B34: RS ST. CAROLUS BORROMEUS | I34: =SUM(C34:H34) -> 0 | P34: =SUM(J34:O34) -> 0 | W34: =SUM(Q34:V34) -> 0 | AD34: =SUM(X34:AC34) -> 0
A35: 6 | B35: RSU LEONA KUPANG | I35: =SUM(C35:H35) -> 0 | P35: =SUM(J35:O35) -> 0 | W35: =SUM(Q35:V35) -> 0 | AD35: =SUM(X35:AC35) -> 0
A36: 7 | B36: RSU SILOAM KUPANG | I36: =SUM(C36:H36) -> 0 | P36: =SUM(J36:O36) -> 0 | W36: =SUM(Q36:V36) -> 0 | AD36: =SUM(X36:AC36) -> 0
A37: 8 | B37: RUMAH SAKIT TK. III WIRASAKTI | I37: =SUM(C37:H37) -> 0 | P37: =SUM(J37:O37) -> 0 | W37: =SUM(Q37:V37) -> 0 | AD37: =SUM(X37:AC37) -> 0
A38: 9 | B38: RSJ NAIMATA | I38: =SUM(C38:H38) -> 0 | P38: =SUM(J38:O38) -> 0 | W38: =SUM(Q38:V38) -> 0 | AD38: =SUM(X38:AC38) -> 0
A39: 10 | B39: RS MAMAMI | I39: =SUM(C39:H39) -> 0 | P39: =SUM(J39:O39) -> 0 | W39: =SUM(Q39:V39) -> 0 | AD39: =SUM(X39:AC39) -> 0
A40: 11 | B40: RSUD S.K. LERIK | I40: =SUM(C40:H40) -> 0 | P40: =SUM(J40:O40) -> 0 | W40: =SUM(Q40:V40) -> 0 | AD40: =SUM(X40:AC40) -> 0
A41: 12 | B41: KU DEWANTA MENTAL JIWA HEALTH CARE | I41: =SUM(C41:H41) -> 0 | P41: =SUM(J41:O41) -> 0 | W41: =SUM(Q41:V41) -> 0 | AD41: =SUM(X41:AC41) -> 0
... A44: 15 | B44: RSUP Dr. BEN MBOI KUPANG | I44: =SUM(C44:H44) -> 0 | P44: =SUM(J44:O44) -> 0 | W44: =SUM(Q44:V44) -> 0 | AD44: =SUM(X44:AC44) -> 0
A45: TOTAL | C45: =SUM(C30:C44) -> 0 | D45: =SUM(D30:D44) -> 0 | E45: =SUM(E30:E44) -> 0 | F45: =SUM(F30:F44) -> 0 | G45: =SUM(G30:G44) -> 0 | H45: =SUM(H30:H44) -> 0 | I45: =SUM(C45:H45) -> 0 | J45: =SUM(J30:J44) -> 0 | K45: =SUM(K30:K44) -> 0 | L45: =SUM(L30:L44) -> 0 | M45: =SUM(M30:M44) -> 0 | N45: =SUM(N30:N44) -> 0 | O45: =SUM(O30:O44) -> 0 | P45: =SUM(J45:O45) -> 0 | Q45: =SUM(Q30:Q44) -> 0 | R45: =SUM(R30:R44) -> 0 | S45: =SUM(S30:S44) -> 0 | T45: =SUM(T30:T44) -> 0 | U45: =SUM(U30:U44) -> 0 | V45: =SUM(V30:V44) -> 0 | W45: =SUM(Q45:V45) -> 0 | X45: =SUM(X30:X44) -> 0 | Y45: =SUM(Y30:Y44) -> 0 | Z45: =SUM(Z30:Z44) -> 0 | AA45: =SUM(AA30:AA44) -> 0 | AB45: =SUM(AB30:AB44) -> 0 | AC45: =SUM(AC30:AC44) -> 0 | AD45: =SUM(X45:AC45) -> 0
A48: No. | B48: NAMA FASKES | C48: SEPTEMBER | J48: OKTOBER | Q48: NOVEMBER | X48: DESEMBER
C49: UMUM | E49: BPJS/KIS | G49: SKTM | I49: TOTAL | J49: UMUM | L49: BPJS/KIS | N49: SKTM | P49: TOTAL | Q49: UMUM | S49: BPJS/KIS | U49: SKTM | W49: TOTAL | X49: UMUM | Z49: BPJS/KIS | AB49: SKTM | AD49: TOTAL
C50: L | D50: P | E50: L | F50: P | G50: L | H50: P | J50: L | K50: P | L50: L | M50: P | N50: L | O50: P | Q50: L | R50: P | S50: L | T50: P | U50: L | V50: P | X50: L | Y50: P | Z50: L | AA50: P | AB50: L | AC50: P
...

Sheet KORBAFO
A1: 3
A2: LAPORAN RUJUKAN
A3: DI PUSKESMAS KORBAFO
A4: TAHUN 2026
A6: No. | B6: NAMA FASKES | C6: JANUARI | J6: FEBRUARI | Q6: MARET | X6: APRIL
C7: UMUM | E7: BPJS/KIS | G7: SKTM | I7: TOTAL | J7: UMUM | L7: BPJS/KIS | N7: SKTM | P7: TOTAL | Q7: UMUM | S7: BPJS/KIS | U7: SKTM | W7: TOTAL | X7: UMUM | Z7: BPJS/KIS | AB7: SKTM | AD7: TOTAL
C8: L | D8: P | E8: L | F8: P | G8: L | H8: P | J8: L | K8: P | L8: L | M8: P | N8: L | O8: P | Q8: L | R8: P | S8: L | T8: P | U8: L | V8: P | X8: L | Y8: P | Z8: L | AA8: P | AB8: L | AC8: P
A9: 1 | B9: RSUD KAB. ROTE NDAO | C9: 2 | D9: 1 | E9: 5 | F9: 20 | I9: =SUM(C9:H9) -> 28 | L9: 4 | M9: 7 | O9: 1 | P9: =SUM(J9:O9) -> 12 | Q9: 2 | R9: 4 | S9: 5 | T9: 3 | U9: 1 | W9: =SUM(Q9:V9) -> 15 | Y9: 5 | Z9: 2 | AA9: 7 | AD9: =SUM(X9:AC9) -> 14
A10: 2 | B10: RSUD PROF DR WZ JOHANNES | I10: =SUM(C10:H10) -> 0 | P10: =SUM(J10:O10) -> 0 | W10: =SUM(Q10:V10) -> 0 | Z10: 1 | AA10: 1 | AD10: =SUM(X10:AC10) -> 2
A11: 3 | B11: RS BHAYANGKARA KUPANG | I11: =SUM(C11:H11) -> 0 | P11: =SUM(J11:O11) -> 0 | W11: =SUM(Q11:V11) -> 0 | Z11: 1 | AD11: =SUM(X11:AC11) -> 1
A12: 4 | B12: RS KARTINI KUPANG | I12: =SUM(C12:H12) -> 0 | L12: 2 | M12: 3 | P12: =SUM(J12:O12) -> 5 | S12: 2 | T12: 2 | W12: =SUM(Q12:V12) -> 4 | Z12: 2 | AA12: 2 | AD12: =SUM(X12:AC12) -> 4
A13: 5 | B13: RS ST. CAROLUS BORROMEUS | I13: =SUM(C13:H13) -> 0 | M13: 3 | P13: =SUM(J13:O13) -> 3 | S13: 1 | W13: =SUM(Q13:V13) -> 1 | AA13: 1 | AD13: =SUM(X13:AC13) -> 1
A14: 6 | B14: RSU LEONA KUPANG | E14: 1 | F14: 4 | I14: =SUM(C14:H14) -> 5 | L14: 1 | M14: 5 | P14: =SUM(J14:O14) -> 6 | S14: 1 | T14: 5 | W14: =SUM(Q14:V14) -> 6 | Z14: 1 | AA14: 6 | AD14: =SUM(X14:AC14) -> 7
A15: 7 | B15: RSU SILOAM KUPANG | E15: 1 | I15: =SUM(C15:H15) -> 1 | L15: 3 | M15: 1 | P15: =SUM(J15:O15) -> 4 | S15: 2 | T15: 3 | W15: =SUM(Q15:V15) -> 5 | AA15: 1 | AD15: =SUM(X15:AC15) -> 1
A16: 8 | B16: RUMAH SAKIT TK. III WIRASAKTI | I16: =SUM(C16:H16) -> 0 | L16: 1 | M16: 2 | P16: =SUM(J16:O16) -> 3 | W16: =SUM(Q16:V16) -> 0 | AA16: 1 | AD16: =SUM(X16:AC16) -> 1
A17: 9 | B17: RSJ NAIMATA | C17: 1 | I17: =SUM(C17:H17) -> 1 | P17: =SUM(J17:O17) -> 0 | W17: =SUM(Q17:V17) -> 0 | AD17: =SUM(X17:AC17) -> 0
A18: 10 | B18: RS MAMAMI | I18: =SUM(C18:H18) -> 0 | L18: 1 | P18: =SUM(J18:O18) -> 1 | W18: =SUM(Q18:V18) -> 0 | AD18: =SUM(X18:AC18) -> 0
A19: 11 | B19: RSUD S.K. LERIK | E19: 1 | I19: =SUM(C19:H19) -> 1 | P19: =SUM(J19:O19) -> 0 | W19: =SUM(Q19:V19) -> 0 | Z19: 1 | AD19: =SUM(X19:AC19) -> 1
A20: 12 | B20: KU DEWANTA MENTAL JIWA HEALTH CARE | E20: 1 | I20: =SUM(C20:H20) -> 1 | P20: =SUM(J20:O20) -> 0 | W20: =SUM(Q20:V20) -> 0 | Z20: 1 | AD20: =SUM(X20:AC20) -> 1
A21: 13 | B21: RSIA DEDARI | I21: =SUM(C21:H21) -> 0 | P21: =SUM(J21:O21) -> 0 | W21: =SUM(Q21:V21) -> 0 | AA21: 1 | AD21: =SUM(X21:AC21) -> 1
A22: 14 | B22: RSAL SAMUEL J MOEDA | I22: =SUM(C22:H22) -> 0 | P22: =SUM(J22:O22) -> 0 | W22: =SUM(Q22:V22) -> 0 | AD22: =SUM(X22:AC22) -> 0
A23: 15 | B23: RSUP Dr. BEN MBOI KUPANG | I23: =SUM(C23:H23) -> 0 | P23: =SUM(J23:O23) -> 0 | W23: =SUM(Q23:V23) -> 0 | AD23: =SUM(X23:AC23) -> 0
A24: TOTAL | C24: =SUM(C9:C23) -> 3 | D24: =SUM(D9:D23) -> 1 | E24: =SUM(E9:E23) -> 9 | F24: =SUM(F9:F23) -> 24 | G24: =SUM(G9:G23) -> 0 | H24: =SUM(H9:H23) -> 0 | I24: =SUM(C24:H24) -> 37 | J24: =SUM(J9:J23) -> 0 | K24: =SUM(K9:K23) -> 0 | L24: =SUM(L9:L23) -> 12 | M24: =SUM(M9:M23) -> 21 | N24: =SUM(N9:N23) -> 0 | O24: =SUM(O9:O23) -> 1 | P24: =SUM(J24:O24) -> 34 | Q24: =SUM(Q9:Q23) -> 2 | R24: =SUM(R9:R23) -> 4 | S24: =SUM(S9:S23) -> 11 | T24: =SUM(T9:T23) -> 13 | U24: =SUM(U9:U23) -> 1 | V24: =SUM(V9:V23) -> 0 | W24: =SUM(Q24:V24) -> 31 | X24: =SUM(X9:X23) -> 0 | Y24: =SUM(Y9:Y23) -> 5 | Z24: =SUM(Z9:Z23) -> 9 | AA24: =SUM(AA9:AA23) -> 20 | AB24: =SUM(AB9:AB23) -> 0 | AC24: =SUM(AC9:AC23) -> 0 | AD24: =SUM(X24:AC24) -> 34
A27: No. | B27: NAMA FASKES | C27: MEI | J27: JUNI | Q27: JULI | X27: AGUSTUS
C28: UMUM | E28: BPJS/KIS | G28: SKTM | I28: TOTAL | J28: UMUM | L28: BPJS/KIS | N28: SKTM | P28: TOTAL | Q28: UMUM | S28: BPJS/KIS | U28: SKTM | W28: TOTAL | X28: UMUM | Z28: BPJS/KIS | AB28: SKTM | AD28: TOTAL
C29: L | D29: P | E29: L | F29: P | G29: L | H29: P | J29: L | K29: P | L29: L | M29: P | N29: L | O29: P | Q29: L | R29: P | S29: L | T29: P | U29: L | V29: P | X29: L | Y29: P | Z29: L | AA29: P | AB29: L | AC29: P
A30: 1 | B30: RSUD KAB. ROTE NDAO | D30: 4 | E30: 7 | F30: 5 | H30: 1 | I30: =SUM(C30:H30) -> 17 | J30: 2 | K30: 4 | L30: 12 | M30: 14 | P30: =SUM(J30:O30) -> 32 | W30: =SUM(Q30:V30) -> 0 | AD30: =SUM(X30:AC30) -> 0
A31: 2 | B31: RSUD PROF DR WZ JOHANNES | E31: 1 | F31: 2 | I31: =SUM(C31:H31) -> 3 | M31: 1 | P31: =SUM(J31:O31) -> 1 | W31: =SUM(Q31:V31) -> 0 | AD31: =SUM(X31:AC31) -> 0
A32: 3 | B32: RS BHAYANGKARA KUPANG | I32: =SUM(C32:H32) -> 0 | P32: =SUM(J32:O32) -> 0 | W32: =SUM(Q32:V32) -> 0 | AD32: =SUM(X32:AC32) -> 0
A33: 4 | B33: RS KARTINI KUPANG | E33: 1 | F33: 1 | I33: =SUM(C33:H33) -> 2 | L33: 1 | M33: 1 | P33: =SUM(J33:O33) -> 2 | W33: =SUM(Q33:V33) -> 0 | AD33: =SUM(X33:AC33) -> 0
A34: 5 | B34: RS ST. CAROLUS BORROMEUS | I34: =SUM(C34:H34) -> 0 | P34: =SUM(J34:O34) -> 0 | W34: =SUM(Q34:V34) -> 0 | AD34: =SUM(X34:AC34) -> 0
A35: 6 | B35: RSU LEONA KUPANG | E35: 2 | F35: 5 | I35: =SUM(C35:H35) -> 7 | L35: 1 | M35: 2 | P35: =SUM(J35:O35) -> 3 | W35: =SUM(Q35:V35) -> 0 | AD35: =SUM(X35:AC35) -> 0
A36: 7 | B36: RSU SILOAM KUPANG | E36: 5 | F36: 1 | I36: =SUM(C36:H36) -> 6 | L36: 3 | M36: 2 | P36: =SUM(J36:O36) -> 5 | W36: =SUM(Q36:V36) -> 0 | AD36: =SUM(X36:AC36) -> 0
A37: 8 | B37: RUMAH SAKIT TK. III WIRASAKTI | I37: =SUM(C37:H37) -> 0 | P37: =SUM(J37:O37) -> 0 | W37: =SUM(Q37:V37) -> 0 | AD37: =SUM(X37:AC37) -> 0
A38: 9 | B38: RSJ NAIMATA | I38: =SUM(C38:H38) -> 0 | P38: =SUM(J38:O38) -> 0 | W38: =SUM(Q38:V38) -> 0 | AD38: =SUM(X38:AC38) -> 0
A39: 10 | B39: RS MAMAMI | E39: 1 | I39: =SUM(C39:H39) -> 1 | P39: =SUM(J39:O39) -> 0 | W39: =SUM(Q39:V39) -> 0 | AD39: =SUM(X39:AC39) -> 0
A40: 11 | B40: RSUD S.K. LERIK | I40: =SUM(C40:H40) -> 0 | M40: 1 | P40: =SUM(J40:O40) -> 1 | W40: =SUM(Q40:V40) -> 0 | AD40: =SUM(X40:AC40) -> 0
A41: 12 | B41: KU DEWANTA MENTAL JIWA HEALTH CARE | I41: =SUM(C41:H41) -> 0 | P41: =SUM(J41:O41) -> 0 | W41: =SUM(Q41:V41) -> 0 | AD41: =SUM(X41:AC41) -> 0
A42: 13 | B42: RSIA DEDARI | I42: =SUM(C42:H42) -> 0 | M42: 1 | P42: =SUM(J42:O42) -> 1 | W42: =SUM(Q42:V42) -> 0 | AD42: =SUM(X42:AC42) -> 0
A43: 14 | B43: RSAL SAMUEL J MOEDA | I43: =SUM(C43:H43) -> 0 | P43: =SUM(J43:O43) -> 0 | W43: =SUM(Q43:V43) -> 0 | AD43: =SUM(X43:AC43) -> 0
...

Sheet Sheet11

Sheet Copy of KORBAFO
A1: 3
A2: LAPORAN RUJUKAN
A3: DI PUSKESMAS KORBAFO
A4: TAHUN 2026
A6: No. | B6: NAMA FASKES | C6: JANUARI | J6: FEBRUARI | Q6: MARET | X6: APRIL
C7: UMUM | E7: BPJS/KIS | G7: SKTM | I7: TOTAL | J7: UMUM | L7: BPJS/KIS | N7: SKTM | P7: TOTAL | Q7: UMUM | S7: BPJS/KIS | U7: SKTM | W7: TOTAL | X7: UMUM | Z7: BPJS/KIS | AB7: SKTM | AD7: TOTAL
C8: L | D8: P | E8: L | F8: P | G8: L | H8: P | J8: L | K8: P | L8: L | M8: P | N8: L | O8: P | Q8: L | R8: P | S8: L | T8: P | U8: L | V8: P | X8: L | Y8: P | Z8: L | AA8: P | AB8: L | AC8: P
A9: 1 | B9: RSUD KAB. ROTE NDAO | C9: 2 | D9: 1 | E9: 5 | F9: 20 | I9: =SUM(C9:H9) -> 28 | L9: 4 | M9: 7 | O9: 1 | P9: =SUM(J9:O9) -> 12 | Q9: 2 | R9: 4 | S9: 5 | T9: 3 | U9: 1 | W9: =SUM(Q9:V9) -> 15 | Y9: 5 | Z9: 2 | AA9: 7 | AD9: =SUM(X9:AC9) -> 14
A10: 2 | B10: RSUD PROF DR WZ JOHANNES | I10: =SUM(C10:H10) -> 0 | P10: =SUM(J10:O10) -> 0 | W10: =SUM(Q10:V10) -> 0 | Z10: 1 | AA10: 1 | AD10: =SUM(X10:AC10) -> 2
A11: 3 | B11: RS BHAYANGKARA KUPANG | I11: =SUM(C11:H11) -> 0 | P11: =SUM(J11:O11) -> 0 | W11: =SUM(Q11:V11) -> 0 | Z11: 1 | AD11: =SUM(X11:AC11) -> 1
A12: 4 | B12: RS KARTINI KUPANG | I12: =SUM(C12:H12) -> 0 | L12: 2 | M12: 3 | P12: =SUM(J12:O12) -> 5 | S12: 2 | T12: 2 | W12: =SUM(Q12:V12) -> 4 | Z12: 2 | AA12: 2 | AD12: =SUM(X12:AC12) -> 4
A13: 5 | B13: RS ST. CAROLUS BORROMEUS | I13: =SUM(C13:H13) -> 0 | M13: 3 | P13: =SUM(J13:O13) -> 3 | S13: 1 | W13: =SUM(Q13:V13) -> 1 | AA13: 1 | AD13: =SUM(X13:AC13) -> 1
A14: 6 | B14: RSU LEONA KUPANG | E14: 1 | F14: 4 | I14: =SUM(C14:H14) -> 5 | L14: 1 | M14: 5 | P14: =SUM(J14:O14) -> 6 | S14: 1 | T14: 5 | W14: =SUM(Q14:V14) -> 6 | Z14: 1 | AA14: 6 | AD14: =SUM(X14:AC14) -> 7
A15: 7 | B15: RSU SILOAM KUPANG | E15: 1 | I15: =SUM(C15:H15) -> 1 | L15: 3 | M15: 1 | P15: =SUM(J15:O15) -> 4 | S15: 2 | T15: 3 | W15: =SUM(Q15:V15) -> 5 | AA15: 1 | AD15: =SUM(X15:AC15) -> 1
A16: 8 | B16: RUMAH SAKIT TK. III WIRASAKTI | I16: =SUM(C16:H16) -> 0 | L16: 1 | M16: 2 | P16: =SUM(J16:O16) -> 3 | W16: =SUM(Q16:V16) -> 0 | AA16: 1 | AD16: =SUM(X16:AC16) -> 1
A17: 9 | B17: RSJ NAIMATA | C17: 1 | I17: =SUM(C17:H17) -> 1 | P17: =SUM(J17:O17) -> 0 | W17: =SUM(Q17:V17) -> 0 | AD17: =SUM(X17:AC17) -> 0
A18: 10 | B18: RS MAMAMI | I18: =SUM(C18:H18) -> 0 | L18: 1 | P18: =SUM(J18:O18) -> 1 | W18: =SUM(Q18:V18) -> 0 | AD18: =SUM(X18:AC18) -> 0
A19: 11 | B19: RSUD S.K. LERIK | E19: 1 | I19: =SUM(C19:H19) -> 1 | P19: =SUM(J19:O19) -> 0 | W19: =SUM(Q19:V19) -> 0 | Z19: 1 | AD19: =SUM(X19:AC19) -> 1
A20: 12 | B20: KU DEWANTA MENTAL JIWA HEALTH CARE | E20: 1 | I20: =SUM(C20:H20) -> 1 | P20: =SUM(J20:O20) -> 0 | W20: =SUM(Q20:V20) -> 0 | Z20: 1 | AD20: =SUM(X20:AC20) -> 1
A21: 13 | B21: RSIA DEDARI | I21: =SUM(C21:H21) -> 0 | P21: =SUM(J21:O21) -> 0 | W21: =SUM(Q21:V21) -> 0 | AA21: 1 | AD21: =SUM(X21:AC21) -> 1
A22: 14 | B22: RSAL SAMUEL J MOEDA | I22: =SUM(C22:H22) -> 0 | P22: =SUM(J22:O22) -> 0 | W22: =SUM(Q22:V22) -> 0 | AD22: =SUM(X22:AC22) -> 0
A23: 15 | B23: RSUP Dr. BEN MBOI KUPANG | I23: =SUM(C23:H23) -> 0 | P23: =SUM(J23:O23) -> 0 | W23: =SUM(Q23:V23) -> 0 | AD23: =SUM(X23:AC23) -> 0
A24: TOTAL | C24: =SUM(C9:C23) -> 3 | D24: =SUM(D9:D23) -> 1 | E24: =SUM(E9:E23) -> 9 | F24: =SUM(F9:F23) -> 24 | G24: =SUM(G9:G23) -> 0 | H24: =SUM(H9:H23) -> 0 | I24: =SUM(C24:H24) -> 37 | J24: =SUM(J9:J23) -> 0 | K24: =SUM(K9:K23) -> 0 | L24: =SUM(L9:L23) -> 12 | M24: =SUM(M9:M23) -> 21 | N24: =SUM(N9:N23) -> 0 | O24: =SUM(O9:O23) -> 1 | P24: =SUM(J24:O24) -> 34 | Q24: =SUM(Q9:Q23) -> 2 | R24: =SUM(R9:R23) -> 4 | S24: =SUM(S9:S23) -> 11 | T24: =SUM(T9:T23) -> 13 | U24: =SUM(U9:U23) -> 1 | V24: =SUM(V9:V23) -> 0 | W24: =SUM(Q24:V24) -> 31 | X24: =SUM(X9:X23) -> 0 | Y24: =SUM(Y9:Y23) -> 5 | Z24: =SUM(Z9:Z23) -> 9 | AA24: =SUM(AA9:AA23) -> 20 | AB24: =SUM(AB9:AB23) -> 0 | AC24: =SUM(AC9:AC23) -> 0 | AD24: =SUM(X24:AC24) -> 34
A27: No. | B27: NAMA FASKES | C27: MEI | J27: JUNI | Q27: JULI | X27: AGUSTUS
C28: UMUM | E28: BPJS/KIS | G28: SKTM | I28: TOTAL | J28: UMUM | L28: BPJS/KIS | N28: SKTM | P28: TOTAL | Q28: UMUM | S28: BPJS/KIS | U28: SKTM | W28: TOTAL | X28: UMUM | Z28: BPJS/KIS | AB28: SKTM | AD28: TOTAL
C29: L | D29: P | E29: L | F29: P | G29: L | H29: P | J29: L | K29: P | L29: L | M29: P | N29: L | O29: P | Q29: L | R29: P | S29: L | T29: P | U29: L | V29: P | X29: L | Y29: P | Z29: L | AA29: P | AB29: L | AC29: P
A30: 1 | B30: RSUD KAB. ROTE NDAO | D30: 4 | E30: 7 | F30: 5 | H30: 1 | I30: =SUM(C30:H30) -> 17 | J30: 2 | K30: 4 | L30: 12 | M30: 14 | P30: =SUM(J30:O30) -> 32 | W30: =SUM(Q30:V30) -> 0 | AD30: =SUM(X30:AC30) -> 0
A31: 2 | B31: RSUD PROF DR WZ JOHANNES | E31: 1 | F31: 2 | I31: =SUM(C31:H31) -> 3 | M31: 1 | P31: =SUM(J31:O31) -> 1 | W31: =SUM(Q31:V31) -> 0 | AD31: =SUM(X31:AC31) -> 0
A32: 3 | B32: RS BHAYANGKARA KUPANG | I32: =SUM(C32:H32) -> 0 | P32: =SUM(J32:O32) -> 0 | W32: =SUM(Q32:V32) -> 0 | AD32: =SUM(X32:AC32) -> 0
A33: 4 | B33: RS KARTINI KUPANG | E33: 1 | F33: 1 | I33: =SUM(C33:H33) -> 2 | L33: 1 | M33: 1 | P33: =SUM(J33:O33) -> 2 | W33: =SUM(Q33:V33) -> 0 | AD33: =SUM(X33:AC33) -> 0
A34: 5 | B34: RS ST. CAROLUS BORROMEUS | I34: =SUM(C34:H34) -> 0 | P34: =SUM(J34:O34) -> 0 | W34: =SUM(Q34:V34) -> 0 | AD34: =SUM(X34:AC34) -> 0
A35: 6 | B35: RSU LEONA KUPANG | E35: 2 | F35: 5 | I35: =SUM(C35:H35) -> 7 | L35: 1 | M35: 2 | P35: =SUM(J35:O35) -> 3 | W35: =SUM(Q35:V35) -> 0 | AD35: =SUM(X35:AC35) -> 0
A36: 7 | B36: RSU SILOAM KUPANG | E36: 5 | F36: 1 | I36: =SUM(C36:H36) -> 6 | L36: 3 | M36: 2 | P36: =SUM(J36:O36) -> 5 | W36: =SUM(Q36:V36) -> 0 | AD36: =SUM(X36:AC36) -> 0
A37: 8 | B37: RUMAH SAKIT TK. III WIRASAKTI | I37: =SUM(C37:H37) -> 0 | P37: =SUM(J37:O37) -> 0 | W37: =SUM(Q37:V37) -> 0 | AD37: =SUM(X37:AC37) -> 0
A38: 9 | B38: RSJ NAIMATA | I38: =SUM(C38:H38) -> 0 | P38: =SUM(J38:O38) -> 0 | W38: =SUM(Q38:V38) -> 0 | AD38: =SUM(X38:AC38) -> 0
A39: 10 | B39: RS MAMAMI | E39: 1 | I39: =SUM(C39:H39) -> 1 | P39: =SUM(J39:O39) -> 0 | W39: =SUM(Q39:V39) -> 0 | AD39: =SUM(X39:AC39) -> 0
A40: 11 | B40: RSUD S.K. LERIK | I40: =SUM(C40:H40) -> 0 | M40: 1 | P40: =SUM(J40:O40) -> 1 | W40: =SUM(Q40:V40) -> 0 | AD40: =SUM(X40:AC40) -> 0
A41: 12 | B41: KU DEWANTA MENTAL JIWA HEALTH CARE | I41: =SUM(C41:H41) -> 0 | P41: =SUM(J41:O41) -> 0 | W41: =SUM(Q41:V41) -> 0 | AD41: =SUM(X41:AC41) -> 0
A42: 13 | B42: RSIA DEDARI | I42: =SUM(C42:H42) -> 0 | M42: 1 | P42: =SUM(J42:O42) -> 1 | W42: =SUM(Q42:V42) -> 0 | AD42: =SUM(X42:AC42) -> 0
A43: 14 | B43: RSAL SAMUEL J MOEDA | I43: =SUM(C43:H43) -> 0 | P43: =SUM(J43:O43) -> 0 | W43: =SUM(Q43:V43) -> 0 | AD43: =SUM(X43:AC43) -> 0
...

Sheet NDAO
A2: LAPORAN RUJUKAN
A3: DI PUSKESMAS NDAO
A4: TAHUN 2026
A6: No. | B6: NAMA FASKES | C6: JANUARI | J6: FEBRUARI | Q6: MARET | X6: APRIL
C7: UMUM | E7: BPJS/KIS | G7: SKTM | I7: TOTAL | J7: UMUM | L7: BPJS/KIS | N7: SKTM | P7: TOTAL | Q7: UMUM | S7: BPJS/KIS | U7: SKTM | W7: TOTAL | X7: UMUM | Z7: BPJS/KIS | AB7: SKTM | AD7: TOTAL
C8: L | D8: P | E8: L | F8: P | G8: L | H8: P | J8: L | K8: P | L8: L | M8: P | N8: L | O8: P | Q8: L | R8: P | S8: L | T8: P | U8: L | V8: P | X8: L | Y8: P | Z8: L | AA8: P | AB8: L | AC8: P
A9: 1 | B9: RSUD KAB. ROTE NDAO | I9: =SUM(C9:H9) -> 0 | P9: =SUM(J9:O9) -> 0 | W9: =SUM(Q9:V9) -> 0 | AD9: =SUM(X9:AC9) -> 0
A10: 2 | B10: RSUD PROF DR WZ JOHANNES | I10: =SUM(C10:H10) -> 0 | P10: =SUM(J10:O10) -> 0 | W10: =SUM(Q10:V10) -> 0 | AD10: =SUM(X10:AC10) -> 0
A11: 3 | B11: RS BHAYANGKARA KUPANG | I11: =SUM(C11:H11) -> 0 | P11: =SUM(J11:O11) -> 0 | W11: =SUM(Q11:V11) -> 0 | AD11: =SUM(X11:AC11) -> 0
A12: 4 | B12: RS KARTINI KUPANG | I12: =SUM(C12:H12) -> 0 | P12: =SUM(J12:O12) -> 0 | W12: =SUM(Q12:V12) -> 0 | AD12: =SUM(X12:AC12) -> 0
A13: 5 | B13: RS ST. CAROLUS BORROMEUS | I13: =SUM(C13:H13) -> 0 | P13: =SUM(J13:O13) -> 0 | W13: =SUM(Q13:V13) -> 0 | AD13: =SUM(X13:AC13) -> 0
A14: 6 | B14: RSU LEONA KUPANG | I14: =SUM(C14:H14) -> 0 | P14: =SUM(J14:O14) -> 0 | W14: =SUM(Q14:V14) -> 0 | AD14: =SUM(X14:AC14) -> 0
A15: 7 | B15: RSU SILOAM KUPANG | I15: =SUM(C15:H15) -> 0 | P15: =SUM(J15:O15) -> 0 | W15: =SUM(Q15:V15) -> 0 | AD15: =SUM(X15:AC15) -> 0
A16: 8 | B16: RUMAH SAKIT TK. III WIRASAKTI | I16: =SUM(C16:H16) -> 0 | P16: =SUM(J16:O16) -> 0 | W16: =SUM(Q16:V16) -> 0 | AD16: =SUM(X16:AC16) -> 0
A17: 9 | B17: RSJ NAIMATA | I17: =SUM(C17:H17) -> 0 | P17: =SUM(J17:O17) -> 0 | W17: =SUM(Q17:V17) -> 0 | AD17: =SUM(X17:AC17) -> 0
A18: 10 | B18: RS MAMAMI | I18: =SUM(C18:H18) -> 0 | P18: =SUM(J18:O18) -> 0 | W18: =SUM(Q18:V18) -> 0 | AD18: =SUM(X18:AC18) -> 0
A19: 11 | B19: RSUD S.K. LERIK | I19: =SUM(C19:H19) -> 0 | P19: =SUM(J19:O19) -> 0 | W19: =SUM(Q19:V19) -> 0 | AD19: =SUM(X19:AC19) -> 0
A20: 12 | B20: KU DEWANTA MENTAL JIWA HEALTH CARE | I20: =SUM(C20:H20) -> 0 | P20: =SUM(J20:O20) -> 0 | W20: =SUM(Q20:V20) -> 0 | AD20: =SUM(X20:AC20) -> 0
... A23: 15 | B23: RSUP Dr. BEN MBOI KUPANG | I23: =SUM(C23:H23) -> 0 | P23: =SUM(J23:O23) -> 0 | W23: =SUM(Q23:V23) -> 0 | AD23: =SUM(X23:AC23) -> 0
